Workbook

Sheet 사용방법
B2: 클레임 분석 시스템 사용방법
B4: 시트 구성
B5: 클레임목록 | C5: 클레임을 한 줄에 한 건씩 입력하는 시트입니다. (흰 칸 = 입력 / 회색 칸 = 자동계산, 건드리지 마세요) 최대 1,999건까지 입력할 수 있습니다.
B6: 분석보고서 | C6: 입력하면 자동으로 집계됩니다. 상단 노란 칸의 기준연도만 바꾸면 전년 대비가 자동으로 바뀝니다.
B7: 클레임조회 | C7: 기간·제공인력·품목류·분류·내용·키워드로 원하는 건만 골라 볼 수 있는 필터 시트입니다.
B8: 기준정보 | C8: 품목류·클레임분류·조치 항목을 관리합니다. 새 종류가 생기면 여기 노란 칸 맨 아래에 추가하세요.
B9: 자동목록 | C9: 계산용 시트입니다. 수정하지 마세요.
B10: 입력 방법
B11: ① 클레임 입력 | C11: 클레임목록의 A~J열에 입력합니다. 품목류·클레임분류·조치는 드롭다운에서 선택합니다. 날짜는 2026-03-15 형식입니다.
B12: ② 새 분류가 생기면 | C12: 기준정보 > 클레임분류 목록 맨 아래에 추가 → 클레임목록 드롭다운과 보고서에 바로 나타납니다. (분류 12개, 품목류 8개, 조치 4개까지 보고서에 표시)
B13: ③ 제공인력·내용 | C13: 드롭다운에 없는 이름·내용도 그냥 입력하면 됩니다. 자동으로 목록에 추가되고 보고서 TOP 순위에 반영됩니다. 오타가 있으면 다른 항목으로 집계되니 가능하면 드롭다운을 사용하세요.
B14: ④ 서비스시작일·조치 | C14: 입력하면 보고서 6번 "서비스 시작 후 경과일·조치별 현황"이 채워집니다. (선택 입력)
B15: ⑤ 데이터 필터 | C15: 방법 1) 클레임목록 1행의 ▼ 버튼(엑셀 기본 필터) 방법 2) 클레임조회 시트에서 조건 입력.
B16: 색상 안내
B17: 노란 칸 | C17: 직접 입력/수정하는 칸 (기준연도, 조회조건, 기준정보 목록)
B18: 회색 칸 | C18: 자동 계산 — 수정 금지
B19: 주의
B20: 보고서 확인 | C20: 보고서 상단 초록/빨간 문구가 "집계 누락"을 알려줍니다. 분류·품목류를 비우거나 기준정보에 없는 값을 쓰면 집계에서 빠집니다.
B21: 입력 예시 | C21: 클레임목록 2~3행에 입력 예시가 들어 있습니다. 실제 데이터를 입력하시거나 덮어써서 사용하세요.

Sheet 클레임목록
A1: 관리번호 | B1: 날짜 | C1: 제공인력 | D1: 품목류 | E1: 클레임분류 | F1: 내용 | G1: 점검결과 | H1: 이용자 | I1: 서비스시작일 | J1: 조치 | K1: 연도 | L1: 월 | M1: 시작후 경과일 | N1: 경과구간 | O1: 조회순번 | P1: 인력순번 | Q1: 내용순번
A2: 240624 | B2: 46036 | C2: 유은영 | D2: 산모신생아 | E2: 전문성 | F2: 조기퇴근 | G2: 말이 많으심. 성향 안맞아 | H2: 26-03 윤푸름 | K2: =IF(ISNUMBER(B2),YEAR(B2),"") -> 2026 | L2: =IF(ISNUMBER(B2),MONTH(B2),"") -> 1 | M2: =IF(AND(ISNUMBER(B2),ISNUMBER(I2)),B2-I2+1,"") | N2: =IF(B2="","",IF(M2="","시작일 미입력",IF(M2<1,"시작일 이전(확인)",IF(M2=1,"1일째",IF(M2=2,"2일째",IF(M2=3,"3일째",IF(M2<=7,"일주일 이내",IF(M2<=14,"이주일 이내","15일 이후")))))))) -> 시작일 미입력 | O2: =IF(AND(COUNTA($A2:$J2)>0,OR(클레임조회!$C$4="",AND(ISNUMBER($B2),$B2>=클레임조회!$C$4)),OR(클레임조회!$C$5="",AND(ISNUMBER($B2),$B2<=클레임조회!$C$5)),OR(클레임조회!$C$6="",$C2=클레임조회!$C$6),OR(클레임조회!$C$7="",$D2=클레임조회!$C$7),OR(클레임조회!$C$8="",$E2=클레임조회!$C$8),OR(클레임조회!$C$9="",$F2=클레임조회!$C$9),OR(클레임조회!$C$10="",ISNUMBER(SEARCH(클레임조회!$C$10,$C2&" "&$F2&" "&$G2&" "&$H2)))),COUNT(O$1:O1)+1,"") -> 1 | P2: =IF(AND(TRIM(C2)<>"",COUNTIF(C$2:C2,C2)=1),MAX(P$1:P1)+1,"") -> 1 | Q2: =IF(AND(TRIM(F2)<>"",COUNTIF(F$2:F2,F2)=1),MAX(Q$1:Q1)+1,"") -> 1
A3: 102004 | B3: 46037 | D3: 영유아 | E3: 성실성 | F3: 휴대폰사용 | H3: 26-42 변영애 | K3: =IF(ISNUMBER(B3),YEAR(B3),"") -> 2026 | L3: =IF(ISNUMBER(B3),MONTH(B3),"") -> 1 | M3: =IF(AND(ISNUMBER(B3),ISNUMBER(I3)),B3-I3+1,"") | N3: =IF(B3="","",IF(M3="","시작일 미입력",IF(M3<1,"시작일 이전(확인)",IF(M3=1,"1일째",IF(M3=2,"2일째",IF(M3=3,"3일째",IF(M3<=7,"일주일 이내",IF(M3<=14,"이주일 이내","15일 이후")))))))) -> 시작일 미입력 | O3: =IF(AND(COUNTA($A3:$J3)>0,OR(클레임조회!$C$4="",AND(ISNUMBER($B3),$B3>=클레임조회!$C$4)),OR(클레임조회!$C$5="",AND(ISNUMBER($B3),$B3<=클레임조회!$C$5)),OR(클레임조회!$C$6="",$C3=클레임조회!$C$6),OR(클레임조회!$C$7="",$D3=클레임조회!$C$7),OR(클레임조회!$C$8="",$E3=클레임조회!$C$8),OR(클레임조회!$C$9="",$F3=클레임조회!$C$9),OR(클레임조회!$C$10="",ISNUMBER(SEARCH(클레임조회!$C$10,$C3&" "&$F3&" "&$G3&" "&$H3)))),COUNT(O$1:O2)+1,"") -> 2 | P3: =IF(AND(TRIM(C3)<>"",COUNTIF(C$2:C3,C3)=1),MAX(P$1:P2)+1,"") | Q3: =IF(AND(TRIM(F3)<>"",COUNTIF(F$2:F3,F3)=1),MAX(Q$1:Q2)+1,"") -> 2
K4: =IF(ISNUMBER(B4),YEAR(B4),"") | L4: =IF(ISNUMBER(B4),MONTH(B4),"") | M4: =IF(AND(ISNUMBER(B4),ISNUMBER(I4)),B4-I4+1,"") | N4: =IF(B4="","",IF(M4="","시작일 미입력",IF(M4<1,"시작일 이전(확인)",IF(M4=1,"1일째",IF(M4=2,"2일째",IF(M4=3,"3일째",IF(M4<=7,"일주일 이내",IF(M4<=14,"이주일 이내","15일 이후")))))))) | O4: =IF(AND(COUNTA($A4:$J4)>0,OR(클레임조회!$C$4="",AND(ISNUMBER($B4),$B4>=클레임조회!$C$4)),OR(클레임조회!$C$5="",AND(ISNUMBER($B4),$B4<=클레임조회!$C$5)),OR(클레임조회!$C$6="",$C4=클레임조회!$C$6),OR(클레임조회!$C$7="",$D4=클레임조회!$C$7),OR(클레임조회!$C$8="",$E4=클레임조회!$C$8),OR(클레임조회!$C$9="",$F4=클레임조회!$C$9),OR(클레임조회!$C$10="",ISNUMBER(SEARCH(클레임조회!$C$10,$C4&" "&$F4&" "&$G4&" "&$H4)))),COUNT(O$1:O3)+1,"") | P4: =IF(AND(TRIM(C4)<>"",COUNTIF(C$2:C4,C4)=1),MAX(P$1:P3)+1,"") | Q4: =IF(AND(TRIM(F4)<>"",COUNTIF(F$2:F4,F4)=1),MAX(Q$1:Q3)+1,"")
K5: =IF(ISNUMBER(B5),YEAR(B5),"") | L5: =IF(ISNUMBER(B5),MONTH(B5),"") | M5: =IF(AND(ISNUMBER(B5),ISNUMBER(I5)),B5-I5+1,"") | N5: =IF(B5="","",IF(M5="","시작일 미입력",IF(M5<1,"시작일 이전(확인)",IF(M5=1,"1일째",IF(M5=2,"2일째",IF(M5=3,"3일째",IF(M5<=7,"일주일 이내",IF(M5<=14,"이주일 이내","15일 이후")))))))) | O5: =IF(AND(COUNTA($A5:$J5)>0,OR(클레임조회!$C$4="",AND(ISNUMBER($B5),$B5>=클레임조회!$C$4)),OR(클레임조회!$C$5="",AND(ISNUMBER($B5),$B5<=클레임조회!$C$5)),OR(클레임조회!$C$6="",$C5=클레임조회!$C$6),OR(클레임조회!$C$7="",$D5=클레임조회!$C$7),OR(클레임조회!$C$8="",$E5=클레임조회!$C$8),OR(클레임조회!$C$9="",$F5=클레임조회!$C$9),OR(클레임조회!$C$10="",ISNUMBER(SEARCH(클레임조회!$C$10,$C5&" "&$F5&" "&$G5&" "&$H5)))),COUNT(O$1:O4)+1,"") | P5: =IF(AND(TRIM(C5)<>"",COUNTIF(C$2:C5,C5)=1),MAX(P$1:P4)+1,"") | Q5: =IF(AND(TRIM(F5)<>"",COUNTIF(F$2:F5,F5)=1),MAX(Q$1:Q4)+1,"")
K6: =IF(ISNUMBER(B6),YEAR(B6),"") | L6: =IF(ISNUMBER(B6),MONTH(B6),"") | M6: =IF(AND(ISNUMBER(B6),ISNUMBER(I6)),B6-I6+1,"") | N6: =IF(B6="","",IF(M6="","시작일 미입력",IF(M6<1,"시작일 이전(확인)",IF(M6=1,"1일째",IF(M6=2,"2일째",IF(M6=3,"3일째",IF(M6<=7,"일주일 이내",IF(M6<=14,"이주일 이내","15일 이후")))))))) | O6: =IF(AND(COUNTA($A6:$J6)>0,OR(클레임조회!$C$4="",AND(ISNUMBER($B6),$B6>=클레임조회!$C$4)),OR(클레임조회!$C$5="",AND(ISNUMBER($B6),$B6<=클레임조회!$C$5)),OR(클레임조회!$C$6="",$C6=클레임조회!$C$6),OR(클레임조회!$C$7="",$D6=클레임조회!$C$7),OR(클레임조회!$C$8="",$E6=클레임조회!$C$8),OR(클레임조회!$C$9="",$F6=클레임조회!$C$9),OR(클레임조회!$C$10="",ISNUMBER(SEARCH(클레임조회!$C$10,$C6&" "&$F6&" "&$G6&" "&$H6)))),COUNT(O$1:O5)+1,"") | P6: =IF(AND(TRIM(C6)<>"",COUNTIF(C$2:C6,C6)=1),MAX(P$1:P5)+1,"") | Q6: =IF(AND(TRIM(F6)<>"",COUNTIF(F$2:F6,F6)=1),MAX(Q$1:Q5)+1,"")
K7: =IF(ISNUMBER(B7),YEAR(B7),"") | L7: =IF(ISNUMBER(B7),MONTH(B7),"") | M7: =IF(AND(ISNUMBER(B7),ISNUMBER(I7)),B7-I7+1,"") | N7: =IF(B7="","",IF(M7="","시작일 미입력",IF(M7<1,"시작일 이전(확인)",IF(M7=1,"1일째",IF(M7=2,"2일째",IF(M7=3,"3일째",IF(M7<=7,"일주일 이내",IF(M7<=14,"이주일 이내","15일 이후")))))))) | O7: =IF(AND(COUNTA($A7:$J7)>0,OR(클레임조회!$C$4="",AND(ISNUMBER($B7),$B7>=클레임조회!$C$4)),OR(클레임조회!$C$5="",AND(ISNUMBER($B7),$B7<=클레임조회!$C$5)),OR(클레임조회!$C$6="",$C7=클레임조회!$C$6),OR(클레임조회!$C$7="",$D7=클레임조회!$C$7),OR(클레임조회!$C$8="",$E7=클레임조회!$C$8),OR(클레임조회!$C$9="",$F7=클레임조회!$C$9),OR(클레임조회!$C$10="",ISNUMBER(SEARCH(클레임조회!$C$10,$C7&" "&$F7&" "&$G7&" "&$H7)))),COUNT(O$1:O6)+1,"") | P7: =IF(AND(TRIM(C7)<>"",COUNTIF(C$2:C7,C7)=1),MAX(P$1:P6)+1,"") | Q7: =IF(AND(TRIM(F7)<>"",COUNTIF(F$2:F7,F7)=1),MAX(Q$1:Q6)+1,"")
K8: =IF(ISNUMBER(B8),YEAR(B8),"") | L8: =IF(ISNUMBER(B8),MONTH(B8),"") | M8: =IF(AND(ISNUMBER(B8),ISNUMBER(I8)),B8-I8+1,"") | N8: =IF(B8="","",IF(M8="","시작일 미입력",IF(M8<1,"시작일 이전(확인)",IF(M8=1,"1일째",IF(M8=2,"2일째",IF(M8=3,"3일째",IF(M8<=7,"일주일 이내",IF(M8<=14,"이주일 이내","15일 이후")))))))) | O8: =IF(AND(COUNTA($A8:$J8)>0,OR(클레임조회!$C$4="",AND(ISNUMBER($B8),$B8>=클레임조회!$C$4)),OR(클레임조회!$C$5="",AND(ISNUMBER($B8),$B8<=클레임조회!$C$5)),OR(클레임조회!$C$6="",$C8=클레임조회!$C$6),OR(클레임조회!$C$7="",$D8=클레임조회!$C$7),OR(클레임조회!$C$8="",$E8=클레임조회!$C$8),OR(클레임조회!$C$9="",$F8=클레임조회!$C$9),OR(클레임조회!$C$10="",ISNUMBER(SEARCH(클레임조회!$C$10,$C8&" "&$F8&" "&$G8&" "&$H8)))),COUNT(O$1:O7)+1,"") | P8: =IF(AND(TRIM(C8)<>"",COUNTIF(C$2:C8,C8)=1),MAX(P$1:P7)+1,"") | Q8: =IF(AND(TRIM(F8)<>"",COUNTIF(F$2:F8,F8)=1),MAX(Q$1:Q7)+1,"")
K9: =IF(ISNUMBER(B9),YEAR(B9),"") | L9: =IF(ISNUMBER(B9),MONTH(B9),"") | M9: =IF(AND(ISNUMBER(B9),ISNUMBER(I9)),B9-I9+1,"") | N9: =IF(B9="","",IF(M9="","시작일 미입력",IF(M9<1,"시작일 이전(확인)",IF(M9=1,"1일째",IF(M9=2,"2일째",IF(M9=3,"3일째",IF(M9<=7,"일주일 이내",IF(M9<=14,"이주일 이내","15일 이후")))))))) | O9: =IF(AND(COUNTA($A9:$J9)>0,OR(클레임조회!$C$4="",AND(ISNUMBER($B9),$B9>=클레임조회!$C$4)),OR(클레임조회!$C$5="",AND(ISNUMBER($B9),$B9<=클레임조회!$C$5)),OR(클레임조회!$C$6="",$C9=클레임조회!$C$6),OR(클레임조회!$C$7="",$D9=클레임조회!$C$7),OR(클레임조회!$C$8="",$E9=클레임조회!$C$8),OR(클레임조회!$C$9="",$F9=클레임조회!$C$9),OR(클레임조회!$C$10="",ISNUMBER(SEARCH(클레임조회!$C$10,$C9&" "&$F9&" "&$G9&" "&$H9)))),COUNT(O$1:O8)+1,"") | P9: =IF(AND(TRIM(C9)<>"",COUNTIF(C$2:C9,C9)=1),MAX(P$1:P8)+1,"") | Q9: =IF(AND(TRIM(F9)<>"",COUNTIF(F$2:F9,F9)=1),MAX(Q$1:Q8)+1,"")
K10: =IF(ISNUMBER(B10),YEAR(B10),"") | L10: =IF(ISNUMBER(B10),MONTH(B10),"") | M10: =IF(AND(ISNUMBER(B10),ISNUMBER(I10)),B10-I10+1,"") | N10: =IF(B10="","",IF(M10="","시작일 미입력",IF(M10<1,"시작일 이전(확인)",IF(M10=1,"1일째",IF(M10=2,"2일째",IF(M10=3,"3일째",IF(M10<=7,"일주일 이내",IF(M10<=14,"이주일 이내","15일 이후")))))))) | O10: =IF(AND(COUNTA($A10:$J10)>0,OR(클레임조회!$C$4="",AND(ISNUMBER($B10),$B10>=클레임조회!$C$4)),OR(클레임조회!$C$5="",AND(ISNUMBER($B10),$B10<=클레임조회!$C$5)),OR(클레임조회!$C$6="",$C10=클레임조회!$C$6),OR(클레임조회!$C$7="",$D10=클레임조회!$C$7),OR(클레임조회!$C$8="",$E10=클레임조회!$C$8),OR(클레임조회!$C$9="",$F10=클레임조회!$C$9),OR(클레임조회!$C$10="",ISNUMBER(SEARCH(클레임조회!$C$10,$C10&" "&$F10&" "&$G10&" "&$H10)))),COUNT(O$1:O9)+1,"") | P10: =IF(AND(TRIM(C10)<>"",COUNTIF(C$2:C10,C10)=1),MAX(P$1:P9)+1,"") | Q10: =IF(AND(TRIM(F10)<>"",COUNTIF(F$2:F10,F10)=1),MAX(Q$1:Q9)+1,"")
K11: =IF(ISNUMBER(B11),YEAR(B11),"") | L11: =IF(ISNUMBER(B11),MONTH(B11),"") | M11: =IF(AND(ISNUMBER(B11),ISNUMBER(I11)),B11-I11+1,"") | N11: =IF(B11="","",IF(M11="","시작일 미입력",IF(M11<1,"시작일 이전(확인)",IF(M11=1,"1일째",IF(M11=2,"2일째",IF(M11=3,"3일째",IF(M11<=7,"일주일 이내",IF(M11<=14,"이주일 이내","15일 이후")))))))) | O11: =IF(AND(COUNTA($A11:$J11)>0,OR(클레임조회!$C$4="",AND(ISNUMBER($B11),$B11>=클레임조회!$C$4)),OR(클레임조회!$C$5="",AND(ISNUMBER($B11),$B11<=클레임조회!$C$5)),OR(클레임조회!$C$6="",$C11=클레임조회!$C$6),OR(클레임조회!$C$7="",$D11=클레임조회!$C$7),OR(클레임조회!$C$8="",$E11=클레임조회!$C$8),OR(클레임조회!$C$9="",$F11=클레임조회!$C$9),OR(클레임조회!$C$10="",ISNUMBER(SEARCH(클레임조회!$C$10,$C11&" "&$F11&" "&$G11&" "&$H11)))),COUNT(O$1:O10)+1,"") | P11: =IF(AND(TRIM(C11)<>"",COUNTIF(C$2:C11,C11)=1),MAX(P$1:P10)+1,"") | Q11: =IF(AND(TRIM(F11)<>"",COUNTIF(F$2:F11,F11)=1),MAX(Q$1:Q10)+1,"")
K12: =IF(ISNUMBER(B12),YEAR(B12),"") | L12: =IF(ISNUMBER(B12),MONTH(B12),"") | M12: =IF(AND(ISNUMBER(B12),ISNUMBER(I12)),B12-I12+1,"") | N12: =IF(B12="","",IF(M12="","시작일 미입력",IF(M12<1,"시작일 이전(확인)",IF(M12=1,"1일째",IF(M12=2,"2일째",IF(M12=3,"3일째",IF(M12<=7,"일주일 이내",IF(M12<=14,"이주일 이내","15일 이후")))))))) | O12: =IF(AND(COUNTA($A12:$J12)>0,OR(클레임조회!$C$4="",AND(ISNUMBER($B12),$B12>=클레임조회!$C$4)),OR(클레임조회!$C$5="",AND(ISNUMBER($B12),$B12<=클레임조회!$C$5)),OR(클레임조회!$C$6="",$C12=클레임조회!$C$6),OR(클레임조회!$C$7="",$D12=클레임조회!$C$7),OR(클레임조회!$C$8="",$E12=클레임조회!$C$8),OR(클레임조회!$C$9="",$F12=클레임조회!$C$9),OR(클레임조회!$C$10="",ISNUMBER(SEARCH(클레임조회!$C$10,$C12&" "&$F12&" "&$G12&" "&$H12)))),COUNT(O$1:O11)+1,"") | P12: =IF(AND(TRIM(C12)<>"",COUNTIF(C$2:C12,C12)=1),MAX(P$1:P11)+1,"") | Q12: =IF(AND(TRIM(F12)<>"",COUNTIF(F$2:F12,F12)=1),MAX(Q$1:Q11)+1,"")
K13: =IF(ISNUMBER(B13),YEAR(B13),"") | L13: =IF(ISNUMBER(B13),MONTH(B13),"") | M13: =IF(AND(ISNUMBER(B13),ISNUMBER(I13)),B13-I13+1,"") | N13: =IF(B13="","",IF(M13="","시작일 미입력",IF(M13<1,"시작일 이전(확인)",IF(M13=1,"1일째",IF(M13=2,"2일째",IF(M13=3,"3일째",IF(M13<=7,"일주일 이내",IF(M13<=14,"이주일 이내","15일 이후")))))))) | O13: =IF(AND(COUNTA($A13:$J13)>0,OR(클레임조회!$C$4="",AND(ISNUMBER($B13),$B13>=클레임조회!$C$4)),OR(클레임조회!$C$5="",AND(ISNUMBER($B13),$B13<=클레임조회!$C$5)),OR(클레임조회!$C$6="",$C13=클레임조회!$C$6),OR(클레임조회!$C$7="",$D13=클레임조회!$C$7),OR(클레임조회!$C$8="",$E13=클레임조회!$C$8),OR(클레임조회!$C$9="",$F13=클레임조회!$C$9),OR(클레임조회!$C$10="",ISNUMBER(SEARCH(클레임조회!$C$10,$C13&" "&$F13&" "&$G13&" "&$H13)))),COUNT(O$1:O12)+1,"") | P13: =IF(AND(TRIM(C13)<>"",COUNTIF(C$2:C13,C13)=1),MAX(P$1:P12)+1,"") | Q13: =IF(AND(TRIM(F13)<>"",COUNTIF(F$2:F13,F13)=1),MAX(Q$1:Q12)+1,"")
K14: =IF(ISNUMBER(B14),YEAR(B14),"") | L14: =IF(ISNUMBER(B14),MONTH(B14),"") | M14: =IF(AND(ISNUMBER(B14),ISNUMBER(I14)),B14-I14+1,"") | N14: =IF(B14="","",IF(M14="","시작일 미입력",IF(M14<1,"시작일 이전(확인)",IF(M14=1,"1일째",IF(M14=2,"2일째",IF(M14=3,"3일째",IF(M14<=7,"일주일 이내",IF(M14<=14,"이주일 이내","15일 이후")))))))) | O14: =IF(AND(COUNTA($A14:$J14)>0,OR(클레임조회!$C$4="",AND(ISNUMBER($B14),$B14>=클레임조회!$C$4)),OR(클레임조회!$C$5="",AND(ISNUMBER($B14),$B14<=클레임조회!$C$5)),OR(클레임조회!$C$6="",$C14=클레임조회!$C$6),OR(클레임조회!$C$7="",$D14=클레임조회!$C$7),OR(클레임조회!$C$8="",$E14=클레임조회!$C$8),OR(클레임조회!$C$9="",$F14=클레임조회!$C$9),OR(클레임조회!$C$10="",ISNUMBER(SEARCH(클레임조회!$C$10,$C14&" "&$F14&" "&$G14&" "&$H14)))),COUNT(O$1:O13)+1,"") | P14: =IF(AND(TRIM(C14)<>"",COUNTIF(C$2:C14,C14)=1),MAX(P$1:P13)+1,"") | Q14: =IF(AND(TRIM(F14)<>"",COUNTIF(F$2:F14,F14)=1),MAX(Q$1:Q13)+1,"")
K15: =IF(ISNUMBER(B15),YEAR(B15),"") | L15: =IF(ISNUMBER(B15),MONTH(B15),"") | M15: =IF(AND(ISNUMBER(B15),ISNUMBER(I15)),B15-I15+1,"") | N15: =IF(B15="","",IF(M15="","시작일 미입력",IF(M15<1,"시작일 이전(확인)",IF(M15=1,"1일째",IF(M15=2,"2일째",IF(M15=3,"3일째",IF(M15<=7,"일주일 이내",IF(M15<=14,"이주일 이내","15일 이후")))))))) | O15: =IF(AND(COUNTA($A15:$J15)>0,OR(클레임조회!$C$4="",AND(ISNUMBER($B15),$B15>=클레임조회!$C$4)),OR(클레임조회!$C$5="",AND(ISNUMBER($B15),$B15<=클레임조회!$C$5)),OR(클레임조회!$C$6="",$C15=클레임조회!$C$6),OR(클레임조회!$C$7="",$D15=클레임조회!$C$7),OR(클레임조회!$C$8="",$E15=클레임조회!$C$8),OR(클레임조회!$C$9="",$F15=클레임조회!$C$9),OR(클레임조회!$C$10="",ISNUMBER(SEARCH(클레임조회!$C$10,$C15&" "&$F15&" "&$G15&" "&$H15)))),COUNT(O$1:O14)+1,"") | P15: =IF(AND(TRIM(C15)<>"",COUNTIF(C$2:C15,C15)=1),MAX(P$1:P14)+1,"") | Q15: =IF(AND(TRIM(F15)<>"",COUNTIF(F$2:F15,F15)=1),MAX(Q$1:Q14)+1,"")
... K2000: =IF(ISNUMBER(B2000),YEAR(B2000),"") | L2000: =IF(ISNUMBER(B2000),MONTH(B2000),"") | M2000: =IF(AND(ISNUMBER(B2000),ISNUMBER(I2000)),B2000-I2000+1,"") | N2000: =IF(B2000="","",IF(M2000="","시작일 미입력",IF(M2000<1,"시작일 이전(확인)",IF(M2000=1,"1일째",IF(M2000=2,"2일째",IF(M2000=3,"3일째",IF(M2000<=7,"일주일 이내",IF(M2000<=14,"이주일 이내","15일 이후")))))))) | O2000: =IF(AND(COUNTA($A2000:$J2000)>0,OR(클레임조회!$C$4="",AND(ISNUMBER($B2000),$B2000>=클레임조회!$C$4)),OR(클레임조회!$C$5="",AND(ISNUMBER($B2000),$B2000<=클레임조회!$C$5)),OR(클레임조회!$C$6="",$C2000=클레임조회!$C$6),OR(클레임조회!$C$7="",$D2000=클레임조회!$C$7),OR(클레임조회!$C$8="",$E2000=클레임조회!$C$8),OR(클레임조회!$C$9="",$F2000=클레임조회!$C$9),OR(클레임조회!$C$10="",ISNUMBER(SEARCH(클레임조회!$C$10,$C2000&" "&$F2000&" "&$G2000&" "&$H2000)))),COUNT(O$1:O1999)+1,"") | P2000: =IF(AND(TRIM(C2000)<>"",COUNTIF(C$2:C2000,C2000)=1),MAX(P$1:P1999)+1,"") | Q2000: =IF(AND(TRIM(F2000)<>"",COUNTIF(F$2:F2000,F2000)=1),MAX(Q$1:Q1999)+1,"")

Sheet 분석보고서
B2: 클레임 접수 현황 분석 보고서
B3: 기준연도 | C3: 2026 | D3: 비교연도 | E3: =C3-1 -> 2025 | F3: ← 노란 칸의 연도를 바꾸면 보고서 전체가 그 연도 기준으로 바뀝니다.
B5: 올해 총 건수 | D5: 전년 총 건수 | F5: 전년 대비 증감률 | H5: 최다 클레임분류 | J5: 최다 제공인력 | L5: 재발 제공인력(2건↑)
B6: =COUNTIF(데이터_연도,기준연도) -> 2 | D6: =COUNTIF(데이터_연도,비교연도) -> 0 | F6: =IF(D6=0,"-",(B6-D6)/D6) -> - | H6: =IF(MAX(D10:D21)=0,"-",INDEX(B10:B21,MATCH(MAX(D10:D21),D10:D21,0))) -> 전문성 | J6: =IF(C42="","-",C42) -> 유은영 | L6: =COUNTIF(자동목록!B4:B203,">=2") -> 0
B7: =IF(AND(B6=SUM(D10:D21),B6=C65),"✔ 기준연도 모든 클레임이 분류·품목류에 집계되었습니다.","⚠ 집계 누락: 분류 "&(B6-SUM(D10:D21))&"건 / 품목류 "&(B6-C65)&"건 — 분류·품목류 미입력이거나 기준정보에 없는 항목입니다.") -> ✔ 기준연도 모든 클레임이 분류·품목류에 집계되었습니다.
B8: 1. 전년 대비 클레임 접수 건수 (클레임분류별)
B9: 구분 | C9: =비교연도&"년" -> 2025년 | D9: =기준연도&"년" -> 2026년 | E9: 증감건수 | F9: 증감률
B10: =IF(기준정보!B4="","",기준정보!B4) -> 전문성 | C10: =IF($B10="","",COUNTIFS(데이터_분류,$B10,데이터_연도,비교연도)) -> 0 | D10: =IF($B10="","",COUNTIFS(데이터_분류,$B10,데이터_연도,기준연도)) -> 1 | E10: =IF($B10="","",D10-C10) -> 1 | F10: =IF($B10="","",IF(C10=0,IF(D10=0,"-","신규"),E10/C10)) -> 신규
B11: =IF(기준정보!B5="","",기준정보!B5) -> 성실성 | C11: =IF($B11="","",COUNTIFS(데이터_분류,$B11,데이터_연도,비교연도)) -> 0 | D11: =IF($B11="","",COUNTIFS(데이터_분류,$B11,데이터_연도,기준연도)) -> 1 | E11: =IF($B11="","",D11-C11) -> 1 | F11: =IF($B11="","",IF(C11=0,IF(D11=0,"-","신규"),E11/C11)) -> 신규
B12: =IF(기준정보!B6="","",기준정보!B6) -> 책임감 | C12: =IF($B12="","",COUNTIFS(데이터_분류,$B12,데이터_연도,비교연도)) -> 0 | D12: =IF($B12="","",COUNTIFS(데이터_분류,$B12,데이터_연도,기준연도)) -> 0 | E12: =IF($B12="","",D12-C12) -> 0 | F12: =IF($B12="","",IF(C12=0,IF(D12=0,"-","신규"),E12/C12)) -> -
B13: =IF(기준정보!B7="","",기준정보!B7) -> 청결성 | C13: =IF($B13="","",COUNTIFS(데이터_분류,$B13,데이터_연도,비교연도)) -> 0 | D13: =IF($B13="","",COUNTIFS(데이터_분류,$B13,데이터_연도,기준연도)) -> 0 | E13: =IF($B13="","",D13-C13) -> 0 | F13: =IF($B13="","",IF(C13=0,IF(D13=0,"-","신규"),E13/C13)) -> -
B14: =IF(기준정보!B8="","",기준정보!B8) -> 배려·존중 | C14: =IF($B14="","",COUNTIFS(데이터_분류,$B14,데이터_연도,비교연도)) -> 0 | D14: =IF($B14="","",COUNTIFS(데이터_분류,$B14,데이터_연도,기준연도)) -> 0 | E14: =IF($B14="","",D14-C14) -> 0 | F14: =IF($B14="","",IF(C14=0,IF(D14=0,"-","신규"),E14/C14)) -> -
B15: =IF(기준정보!B9="","",기준정보!B9) -> 기타 | C15: =IF($B15="","",COUNTIFS(데이터_분류,$B15,데이터_연도,비교연도)) -> 0 | D15: =IF($B15="","",COUNTIFS(데이터_분류,$B15,데이터_연도,기준연도)) -> 0 | E15: =IF($B15="","",D15-C15) -> 0 | F15: =IF($B15="","",IF(C15=0,IF(D15=0,"-","신규"),E15/C15)) -> -
B16: =IF(기준정보!B10="","",기준정보!B10) | C16: =IF($B16="","",COUNTIFS(데이터_분류,$B16,데이터_연도,비교연도)) | D16: =IF($B16="","",COUNTIFS(데이터_분류,$B16,데이터_연도,기준연도)) | E16: =IF($B16="","",D16-C16) | F16: =IF($B16="","",IF(C16=0,IF(D16=0,"-","신규"),E16/C16))
B17: =IF(기준정보!B11="","",기준정보!B11) | C17: =IF($B17="","",COUNTIFS(데이터_분류,$B17,데이터_연도,비교연도)) | D17: =IF($B17="","",COUNTIFS(데이터_분류,$B17,데이터_연도,기준연도)) | E17: =IF($B17="","",D17-C17) | F17: =IF($B17="","",IF(C17=0,IF(D17=0,"-","신규"),E17/C17))
B18: =IF(기준정보!B12="","",기준정보!B12) | C18: =IF($B18="","",COUNTIFS(데이터_분류,$B18,데이터_연도,비교연도)) | D18: =IF($B18="","",COUNTIFS(데이터_분류,$B18,데이터_연도,기준연도)) | E18: =IF($B18="","",D18-C18) | F18: =IF($B18="","",IF(C18=0,IF(D18=0,"-","신규"),E18/C18))
B19: =IF(기준정보!B13="","",기준정보!B13) | C19: =IF($B19="","",COUNTIFS(데이터_분류,$B19,데이터_연도,비교연도)) | D19: =IF($B19="","",COUNTIFS(데이터_분류,$B19,데이터_연도,기준연도)) | E19: =IF($B19="","",D19-C19) | F19: =IF($B19="","",IF(C19=0,IF(D19=0,"-","신규"),E19/C19))
B20: =IF(기준정보!B14="","",기준정보!B14) | C20: =IF($B20="","",COUNTIFS(데이터_분류,$B20,데이터_연도,비교연도)) | D20: =IF($B20="","",COUNTIFS(데이터_분류,$B20,데이터_연도,기준연도)) | E20: =IF($B20="","",D20-C20) | F20: =IF($B20="","",IF(C20=0,IF(D20=0,"-","신규"),E20/C20))
B21: =IF(기준정보!B15="","",기준정보!B15) | C21: =IF($B21="","",COUNTIFS(데이터_분류,$B21,데이터_연도,비교연도)) | D21: =IF($B21="","",COUNTIFS(데이터_분류,$B21,데이터_연도,기준연도)) | E21: =IF($B21="","",D21-C21) | F21: =IF($B21="","",IF(C21=0,IF(D21=0,"-","신규"),E21/C21))
B22: 합계 | C22: =SUM(C10:C21) -> 0 | D22: =SUM(D10:D21) -> 2 | E22: =D22-C22 -> 2 | F22: =IF(C22=0,IF(D22=0,"-","신규"),E22/C22) -> 신규
B24: 2. 월별 클레임 추이
B25: 월 | C25: =비교연도&"년" -> 2025년 | D25: =기준연도&"년" -> 2026년 | E25: 증감건수
B26: 1 | C26: =COUNTIFS(데이터_월,$B26,데이터_연도,비교연도) -> 0 | D26: =COUNTIFS(데이터_월,$B26,데이터_연도,기준연도) -> 2 | E26: =D26-C26 -> 2
B27: 2 | C27: =COUNTIFS(데이터_월,$B27,데이터_연도,비교연도) -> 0 | D27: =COUNTIFS(데이터_월,$B27,데이터_연도,기준연도) -> 0 | E27: =D27-C27 -> 0
B28: 3 | C28: =COUNTIFS(데이터_월,$B28,데이터_연도,비교연도) -> 0 | D28: =COUNTIFS(데이터_월,$B28,데이터_연도,기준연도) -> 0 | E28: =D28-C28 -> 0
B29: 4 | C29: =COUNTIFS(데이터_월,$B29,데이터_연도,비교연도) -> 0 | D29: =COUNTIFS(데이터_월,$B29,데이터_연도,기준연도) -> 0 | E29: =D29-C29 -> 0
B30: 5 | C30: =COUNTIFS(데이터_월,$B30,데이터_연도,비교연도) -> 0 | D30: =COUNTIFS(데이터_월,$B30,데이터_연도,기준연도) -> 0 | E30: =D30-C30 -> 0
B31: 6 | C31: =COUNTIFS(데이터_월,$B31,데이터_연도,비교연도) -> 0 | D31: =COUNTIFS(데이터_월,$B31,데이터_연도,기준연도) -> 0 | E31: =D31-C31 -> 0
B32: 7 | C32: =COUNTIFS(데이터_월,$B32,데이터_연도,비교연도) -> 0 | D32: =COUNTIFS(데이터_월,$B32,데이터_연도,기준연도) -> 0 | E32: =D32-C32 -> 0
B33: 8 | C33: =COUNTIFS(데이터_월,$B33,데이터_연도,비교연도) -> 0 | D33: =COUNTIFS(데이터_월,$B33,데이터_연도,기준연도) -> 0 | E33: =D33-C33 -> 0
B34: 9 | C34: =COUNTIFS(데이터_월,$B34,데이터_연도,비교연도) -> 0 | D34: =COUNTIFS(데이터_월,$B34,데이터_연도,기준연도) -> 0 | E34: =D34-C34 -> 0
B35: 10 | C35: =COUNTIFS(데이터_월,$B35,데이터_연도,비교연도) -> 0 | D35: =COUNTIFS(데이터_월,$B35,데이터_연도,기준연도) -> 0 | E35: =D35-C35 -> 0
B36: 11 | C36: =COUNTIFS(데이터_월,$B36,데이터_연도,비교연도) -> 0 | D36: =COUNTIFS(데이터_월,$B36,데이터_연도,기준연도) -> 0 | E36: =D36-C36 -> 0
B37: 12 | C37: =COUNTIFS(데이터_월,$B37,데이터_연도,비교연도) -> 0 | D37: =COUNTIFS(데이터_월,$B37,데이터_연도,기준연도) -> 0 | E37: =D37-C37 -> 0
B38: 합계 | C38: =SUM(C26:C37) -> 0 | D38: =SUM(D26:D37) -> 2 | E38: =D38-C38 -> 2
B40: 3. 제공인력별 클레임 발생 건수 (기준연도 상위 10명 × 품목류)
B41: 순위 | C41: 제공인력 | D41: =IF(기준정보!A4="","",기준정보!A4) -> 산모신생아 | E41: =IF(기준정보!A5="","",기준정보!A5) -> 영유아 | F41: =IF(기준정보!A6="","",기준정보!A6) -> 가사서비스 | G41: =IF(기준정보!A7="","",기준정보!A7) -> 정리수납 | H41: =IF(기준정보!A8="","",기준정보!A8) -> 이유식전문가 | I41: =IF(기준정보!A9="","",기준정보!A9) | J41: =IF(기준정보!A10="","",기준정보!A10) | K41: =IF(기준정보!A11="","",기준정보!A11) | L41: 합계 | M41: 비율(%)
B42: 1 | C42: =IF(ISNUMBER(LARGE(자동목록!$C$4:$C$203,1)),IF(LARGE(자동목록!$C$4:$C$203,1)>0,INDEX(자동목록!$A$4:$A$203,MATCH(LARGE(자동목록!$C$4:$C$203,1),자동목록!$C$4:$C$203,0)),""),"") -> 유은영 | D42: =IF(OR($C42="",D$41=""),"",COUNTIFS(데이터_제공인력,$C42,데이터_품목류,D$41,데이터_연도,기준연도)) -> 1 | E42: =IF(OR($C42="",E$41=""),"",COUNTIFS(데이터_제공인력,$C42,데이터_품목류,E$41,데이터_연도,기준연도)) -> 0 | F42: =IF(OR($C42="",F$41=""),"",COUNTIFS(데이터_제공인력,$C42,데이터_품목류,F$41,데이터_연도,기준연도)) -> 0 | G42: =IF(OR($C42="",G$41=""),"",COUNTIFS(데이터_제공인력,$C42,데이터_품목류,G$41,데이터_연도,기준연도)) -> 0 | H42: =IF(OR($C42="",H$41=""),"",COUNTIFS(데이터_제공인력,$C42,데이터_품목류,H$41,데이터_연도,기준연도)) -> 0 | I42: =IF(OR($C42="",I$41=""),"",COUNTIFS(데이터_제공인력,$C42,데이터_품목류,I$41,데이터_연도,기준연도)) | J42: =IF(OR($C42="",J$41=""),"",COUNTIFS(데이터_제공인력,$C42,데이터_품목류,J$41,데이터_연도,기준연도)) | K42: =IF(OR($C42="",K$41=""),"",COUNTIFS(데이터_제공인력,$C42,데이터_품목류,K$41,데이터_연도,기준연도)) | L42: =IF($C42="","",COUNTIFS(데이터_제공인력,$C42,데이터_연도,기준연도)) -> 1 | M42: =IF($C42="","",IF($B$6=0,0,L42/$B$6)) -> 0.5
B43: 2 | C43: =IF(ISNUMBER(LARGE(자동목록!$C$4:$C$203,2)),IF(LARGE(자동목록!$C$4:$C$203,2)>0,INDEX(자동목록!$A$4:$A$203,MATCH(LARGE(자동목록!$C$4:$C$203,2),자동목록!$C$4:$C$203,0)),""),"") | D43: =IF(OR($C43="",D$41=""),"",COUNTIFS(데이터_제공인력,$C43,데이터_품목류,D$41,데이터_연도,기준연도)) | E43: =IF(OR($C43="",E$41=""),"",COUNTIFS(데이터_제공인력,$C43,데이터_품목류,E$41,데이터_연도,기준연도)) | F43: =IF(OR($C43="",F$41=""),"",COUNTIFS(데이터_제공인력,$C43,데이터_품목류,F$41,데이터_연도,기준연도)) | G43: =IF(OR($C43="",G$41=""),"",COUNTIFS(데이터_제공인력,$C43,데이터_품목류,G$41,데이터_연도,기준연도)) | H43: =IF(OR($C43="",H$41=""),"",COUNTIFS(데이터_제공인력,$C43,데이터_품목류,H$41,데이터_연도,기준연도)) | I43: =IF(OR($C43="",I$41=""),"",COUNTIFS(데이터_제공인력,$C43,데이터_품목류,I$41,데이터_연도,기준연도)) | J43: =IF(OR($C43="",J$41=""),"",COUNTIFS(데이터_제공인력,$C43,데이터_품목류,J$41,데이터_연도,기준연도)) | K43: =IF(OR($C43="",K$41=""),"",COUNTIFS(데이터_제공인력,$C43,데이터_품목류,K$41,데이터_연도,기준연도)) | L43: =IF($C43="","",COUNTIFS(데이터_제공인력,$C43,데이터_연도,기준연도)) | M43: =IF($C43="","",IF($B$6=0,0,L43/$B$6))
B44: 3 | C44: =IF(ISNUMBER(LARGE(자동목록!$C$4:$C$203,3)),IF(LARGE(자동목록!$C$4:$C$203,3)>0,INDEX(자동목록!$A$4:$A$203,MATCH(LARGE(자동목록!$C$4:$C$203,3),자동목록!$C$4:$C$203,0)),""),"") | D44: =IF(OR($C44="",D$41=""),"",COUNTIFS(데이터_제공인력,$C44,데이터_품목류,D$41,데이터_연도,기준연도)) | E44: =IF(OR($C44="",E$41=""),"",COUNTIFS(데이터_제공인력,$C44,데이터_품목류,E$41,데이터_연도,기준연도)) | F44: =IF(OR($C44="",F$41=""),"",COUNTIFS(데이터_제공인력,$C44,데이터_품목류,F$41,데이터_연도,기준연도)) | G44: =IF(OR($C44="",G$41=""),"",COUNTIFS(데이터_제공인력,$C44,데이터_품목류,G$41,데이터_연도,기준연도)) | H44: =IF(OR($C44="",H$41=""),"",COUNTIFS(데이터_제공인력,$C44,데이터_품목류,H$41,데이터_연도,기준연도)) | I44: =IF(OR($C44="",I$41=""),"",COUNTIFS(데이터_제공인력,$C44,데이터_품목류,I$41,데이터_연도,기준연도)) | J44: =IF(OR($C44="",J$41=""),"",COUNTIFS(데이터_제공인력,$C44,데이터_품목류,J$41,데이터_연도,기준연도)) | K44: =IF(OR($C44="",K$41=""),"",COUNTIFS(데이터_제공인력,$C44,데이터_품목류,K$41,데이터_연도,기준연도)) | L44: =IF($C44="","",COUNTIFS(데이터_제공인력,$C44,데이터_연도,기준연도)) | M44: =IF($C44="","",IF($B$6=0,0,L44/$B$6))
...

Sheet 클레임조회
B2: 클레임 조회 (데이터 필터)
B3: 조건을 고르거나 입력하면 아래에 일치하는 클레임만 나타납니다. 비워 두면 전체이며, 조건을 지우면(Delete) 해제됩니다.
B4: 시작일 | F4: 날짜 예: 2026-03-01
B5: 종료일
B6: 제공인력 | F6: 목록에 없어도 직접 입력 가능
B7: 품목류
B8: 클레임분류
B9: 내용
B10: 키워드 | F10: 제공인력·내용·점검결과·이용자 안에서 검색
B11: 일치 건수 | C11: =COUNT(클레임목록!$O$2:$O$2000) -> 2 | E11: =IF(C11>100,"⚠ 100건까지만 표시됩니다. 조건을 좁혀 주세요.","")
B13: 번호 | C13: 관리번호 | D13: 날짜 | E13: 제공인력 | F13: 품목류 | G13: 클레임분류 | H13: 내용 | I13: 점검결과 | J13: 이용자 | K13: 서비스시작일 | L13: 조치
B14: =IF(1<=$C$11,1,"") -> 1 | C14: =IF($B14="","",IF(INDEX(클레임목록!$A$2:$A$2000,MATCH($B14,클레임목록!$O$2:$O$2000,0))="","",INDEX(클레임목록!$A$2:$A$2000,MATCH($B14,클레임목록!$O$2:$O$2000,0)))) -> 240624 | D14: =IF($B14="","",IF(INDEX(클레임목록!$B$2:$B$2000,MATCH($B14,클레임목록!$O$2:$O$2000,0))="","",INDEX(클레임목록!$B$2:$B$2000,MATCH($B14,클레임목록!$O$2:$O$2000,0)))) -> 46036 | E14: =IF($B14="","",IF(INDEX(클레임목록!$C$2:$C$2000,MATCH($B14,클레임목록!$O$2:$O$2000,0))="","",INDEX(클레임목록!$C$2:$C$2000,MATCH($B14,클레임목록!$O$2:$O$2000,0)))) -> 유은영 | F14: =IF($B14="","",IF(INDEX(클레임목록!$D$2:$D$2000,MATCH($B14,클레임목록!$O$2:$O$2000,0))="","",INDEX(클레임목록!$D$2:$D$2000,MATCH($B14,클레임목록!$O$2:$O$2000,0)))) -> 산모신생아 | G14: =IF($B14="","",IF(INDEX(클레임목록!$E$2:$E$2000,MATCH($B14,클레임목록!$O$2:$O$2000,0))="","",INDEX(클레임목록!$E$2:$E$2000,MATCH($B14,클레임목록!$O$2:$O$2000,0)))) -> 전문성 | H14: =IF($B14="","",IF(INDEX(클레임목록!$F$2:$F$2000,MATCH($B14,클레임목록!$O$2:$O$2000,0))="","",INDEX(클레임목록!$F$2:$F$2000,MATCH($B14,클레임목록!$O$2:$O$2000,0)))) -> 조기퇴근 | I14: =IF($B14="","",IF(INDEX(클레임목록!$G$2:$G$2000,MATCH($B14,클레임목록!$O$2:$O$2000,0))="","",INDEX(클레임목록!$G$2:$G$2000,MATCH($B14,클레임목록!$O$2:$O$2000,0)))) -> 말이 많으심. 성향 안맞아 | J14: =IF($B14="","",IF(INDEX(클레임목록!$H$2:$H$2000,MATCH($B14,클레임목록!$O$2:$O$2000,0))="","",INDEX(클레임목록!$H$2:$H$2000,MATCH($B14,클레임목록!$O$2:$O$2000,0)))) -> 26-03 윤푸름 | K14: =IF($B14="","",IF(INDEX(클레임목록!$I$2:$I$2000,MATCH($B14,클레임목록!$O$2:$O$2000,0))="","",INDEX(클레임목록!$I$2:$I$2000,MATCH($B14,클레임목록!$O$2:$O$2000,0)))) | L14: =IF($B14="","",IF(INDEX(클레임목록!$J$2:$J$2000,MATCH($B14,클레임목록!$O$2:$O$2000,0))="","",INDEX(클레임목록!$J$2:$J$2000,MATCH($B14,클레임목록!$O$2:$O$2000,0))))
B15: =IF(2<=$C$11,2,"") -> 2 | C15: =IF($B15="","",IF(INDEX(클레임목록!$A$2:$A$2000,MATCH($B15,클레임목록!$O$2:$O$2000,0))="","",INDEX(클레임목록!$A$2:$A$2000,MATCH($B15,클레임목록!$O$2:$O$2000,0)))) -> 102004 | D15: =IF($B15="","",IF(INDEX(클레임목록!$B$2:$B$2000,MATCH($B15,클레임목록!$O$2:$O$2000,0))="","",INDEX(클레임목록!$B$2:$B$2000,MATCH($B15,클레임목록!$O$2:$O$2000,0)))) -> 46037 | E15: =IF($B15="","",IF(INDEX(클레임목록!$C$2:$C$2000,MATCH($B15,클레임목록!$O$2:$O$2000,0))="","",INDEX(클레임목록!$C$2:$C$2000,MATCH($B15,클레임목록!$O$2:$O$2000,0)))) | F15: =IF($B15="","",IF(INDEX(클레임목록!$D$2:$D$2000,MATCH($B15,클레임목록!$O$2:$O$2000,0))="","",INDEX(클레임목록!$D$2:$D$2000,MATCH($B15,클레임목록!$O$2:$O$2000,0)))) -> 영유아 | G15: =IF($B15="","",IF(INDEX(클레임목록!$E$2:$E$2000,MATCH($B15,클레임목록!$O$2:$O$2000,0))="","",INDEX(클레임목록!$E$2:$E$2000,MATCH($B15,클레임목록!$O$2:$O$2000,0)))) -> 성실성 | H15: =IF($B15="","",IF(INDEX(클레임목록!$F$2:$F$2000,MATCH($B15,클레임목록!$O$2:$O$2000,0))="","",INDEX(클레임목록!$F$2:$F$2000,MATCH($B15,클레임목록!$O$2:$O$2000,0)))) -> 휴대폰사용 | I15: =IF($B15="","",IF(INDEX(클레임목록!$G$2:$G$2000,MATCH($B15,클레임목록!$O$2:$O$2000,0))="","",INDEX(클레임목록!$G$2:$G$2000,MATCH($B15,클레임목록!$O$2:$O$2000,0)))) | J15: =IF($B15="","",IF(INDEX(클레임목록!$H$2:$H$2000,MATCH($B15,클레임목록!$O$2:$O$2000,0))="","",INDEX(클레임목록!$H$2:$H$2000,MATCH($B15,클레임목록!$O$2:$O$2000,0)))) -> 26-42 변영애 | K15: =IF($B15="","",IF(INDEX(클레임목록!$I$2:$I$2000,MATCH($B15,클레임목록!$O$2:$O$2000,0))="","",INDEX(클레임목록!$I$2:$I$2000,MATCH($B15,클레임목록!$O$2:$O$2000,0)))) | L15: =IF($B15="","",IF(INDEX(클레임목록!$J$2:$J$2000,MATCH($B15,클레임목록!$O$2:$O$2000,0))="","",INDEX(클레임목록!$J$2:$J$2000,MATCH($B15,클레임목록!$O$2:$O$2000,0))))
B16: =IF(3<=$C$11,3,"") | C16: =IF($B16="","",IF(INDEX(클레임목록!$A$2:$A$2000,MATCH($B16,클레임목록!$O$2:$O$2000,0))="","",INDEX(클레임목록!$A$2:$A$2000,MATCH($B16,클레임목록!$O$2:$O$2000,0)))) | D16: =IF($B16="","",IF(INDEX(클레임목록!$B$2:$B$2000,MATCH($B16,클레임목록!$O$2:$O$2000,0))="","",INDEX(클레임목록!$B$2:$B$2000,MATCH($B16,클레임목록!$O$2:$O$2000,0)))) | E16: =IF($B16="","",IF(INDEX(클레임목록!$C$2:$C$2000,MATCH($B16,클레임목록!$O$2:$O$2000,0))="","",INDEX(클레임목록!$C$2:$C$2000,MATCH($B16,클레임목록!$O$2:$O$2000,0)))) | F16: =IF($B16="","",IF(INDEX(클레임목록!$D$2:$D$2000,MATCH($B16,클레임목록!$O$2:$O$2000,0))="","",INDEX(클레임목록!$D$2:$D$2000,MATCH($B16,클레임목록!$O$2:$O$2000,0)))) | G16: =IF($B16="","",IF(INDEX(클레임목록!$E$2:$E$2000,MATCH($B16,클레임목록!$O$2:$O$2000,0))="","",INDEX(클레임목록!$E$2:$E$2000,MATCH($B16,클레임목록!$O$2:$O$2000,0)))) | H16: =IF($B16="","",IF(INDEX(클레임목록!$F$2:$F$2000,MATCH($B16,클레임목록!$O$2:$O$2000,0))="","",INDEX(클레임목록!$F$2:$F$2000,MATCH($B16,클레임목록!$O$2:$O$2000,0)))) | I16: =IF($B16="","",IF(INDEX(클레임목록!$G$2:$G$2000,MATCH($B16,클레임목록!$O$2:$O$2000,0))="","",INDEX(클레임목록!$G$2:$G$2000,MATCH($B16,클레임목록!$O$2:$O$2000,0)))) | J16: =IF($B16="","",IF(INDEX(클레임목록!$H$2:$H$2000,MATCH($B16,클레임목록!$O$2:$O$2000,0))="","",INDEX(클레임목록!$H$2:$H$2000,MATCH($B16,클레임목록!$O$2:$O$2000,0)))) | K16: =IF($B16="","",IF(INDEX(클레임목록!$I$2:$I$2000,MATCH($B16,클레임목록!$O$2:$O$2000,0))="","",INDEX(클레임목록!$I$2:$I$2000,MATCH($B16,클레임목록!$O$2:$O$2000,0)))) | L16: =IF($B16="","",IF(INDEX(클레임목록!$J$2:$J$2000,MATCH($B16,클레임목록!$O$2:$O$2000,0))="","",INDEX(클레임목록!$J$2:$J$2000,MATCH($B16,클레임목록!$O$2:$O$2000,0))))
B17: =IF(4<=$C$11,4,"") | C17: =IF($B17="","",IF(INDEX(클레임목록!$A$2:$A$2000,MATCH($B17,클레임목록!$O$2:$O$2000,0))="","",INDEX(클레임목록!$A$2:$A$2000,MATCH($B17,클레임목록!$O$2:$O$2000,0)))) | D17: =IF($B17="","",IF(INDEX(클레임목록!$B$2:$B$2000,MATCH($B17,클레임목록!$O$2:$O$2000,0))="","",INDEX(클레임목록!$B$2:$B$2000,MATCH($B17,클레임목록!$O$2:$O$2000,0)))) | E17: =IF($B17="","",IF(INDEX(클레임목록!$C$2:$C$2000,MATCH($B17,클레임목록!$O$2:$O$2000,0))="","",INDEX(클레임목록!$C$2:$C$2000,MATCH($B17,클레임목록!$O$2:$O$2000,0)))) | F17: =IF($B17="","",IF(INDEX(클레임목록!$D$2:$D$2000,MATCH($B17,클레임목록!$O$2:$O$2000,0))="","",INDEX(클레임목록!$D$2:$D$2000,MATCH($B17,클레임목록!$O$2:$O$2000,0)))) | G17: =IF($B17="","",IF(INDEX(클레임목록!$E$2:$E$2000,MATCH($B17,클레임목록!$O$2:$O$2000,0))="","",INDEX(클레임목록!$E$2:$E$2000,MATCH($B17,클레임목록!$O$2:$O$2000,0)))) | H17: =IF($B17="","",IF(INDEX(클레임목록!$F$2:$F$2000,MATCH($B17,클레임목록!$O$2:$O$2000,0))="","",INDEX(클레임목록!$F$2:$F$2000,MATCH($B17,클레임목록!$O$2:$O$2000,0)))) | I17: =IF($B17="","",IF(INDEX(클레임목록!$G$2:$G$2000,MATCH($B17,클레임목록!$O$2:$O$2000,0))="","",INDEX(클레임목록!$G$2:$G$2000,MATCH($B17,클레임목록!$O$2:$O$2000,0)))) | J17: =IF($B17="","",IF(INDEX(클레임목록!$H$2:$H$2000,MATCH($B17,클레임목록!$O$2:$O$2000,0))="","",INDEX(클레임목록!$H$2:$H$2000,MATCH($B17,클레임목록!$O$2:$O$2000,0)))) | K17: =IF($B17="","",IF(INDEX(클레임목록!$I$2:$I$2000,MATCH($B17,클레임목록!$O$2:$O$2000,0))="","",INDEX(클레임목록!$I$2:$I$2000,MATCH($B17,클레임목록!$O$2:$O$2000,0)))) | L17: =IF($B17="","",IF(INDEX(클레임목록!$J$2:$J$2000,MATCH($B17,클레임목록!$O$2:$O$2000,0))="","",INDEX(클레임목록!$J$2:$J$2000,MATCH($B17,클레임목록!$O$2:$O$2000,0))))
B18: =IF(5<=$C$11,5,"") | C18: =IF($B18="","",IF(INDEX(클레임목록!$A$2:$A$2000,MATCH($B18,클레임목록!$O$2:$O$2000,0))="","",INDEX(클레임목록!$A$2:$A$2000,MATCH($B18,클레임목록!$O$2:$O$2000,0)))) | D18: =IF($B18="","",IF(INDEX(클레임목록!$B$2:$B$2000,MATCH($B18,클레임목록!$O$2:$O$2000,0))="","",INDEX(클레임목록!$B$2:$B$2000,MATCH($B18,클레임목록!$O$2:$O$2000,0)))) | E18: =IF($B18="","",IF(INDEX(클레임목록!$C$2:$C$2000,MATCH($B18,클레임목록!$O$2:$O$2000,0))="","",INDEX(클레임목록!$C$2:$C$2000,MATCH($B18,클레임목록!$O$2:$O$2000,0)))) | F18: =IF($B18="","",IF(INDEX(클레임목록!$D$2:$D$2000,MATCH($B18,클레임목록!$O$2:$O$2000,0))="","",INDEX(클레임목록!$D$2:$D$2000,MATCH($B18,클레임목록!$O$2:$O$2000,0)))) | G18: =IF($B18="","",IF(INDEX(클레임목록!$E$2:$E$2000,MATCH($B18,클레임목록!$O$2:$O$2000,0))="","",INDEX(클레임목록!$E$2:$E$2000,MATCH($B18,클레임목록!$O$2:$O$2000,0)))) | H18: =IF($B18="","",IF(INDEX(클레임목록!$F$2:$F$2000,MATCH($B18,클레임목록!$O$2:$O$2000,0))="","",INDEX(클레임목록!$F$2:$F$2000,MATCH($B18,클레임목록!$O$2:$O$2000,0)))) | I18: =IF($B18="","",IF(INDEX(클레임목록!$G$2:$G$2000,MATCH($B18,클레임목록!$O$2:$O$2000,0))="","",INDEX(클레임목록!$G$2:$G$2000,MATCH($B18,클레임목록!$O$2:$O$2000,0)))) | J18: =IF($B18="","",IF(INDEX(클레임목록!$H$2:$H$2000,MATCH($B18,클레임목록!$O$2:$O$2000,0))="","",INDEX(클레임목록!$H$2:$H$2000,MATCH($B18,클레임목록!$O$2:$O$2000,0)))) | K18: =IF($B18="","",IF(INDEX(클레임목록!$I$2:$I$2000,MATCH($B18,클레임목록!$O$2:$O$2000,0))="","",INDEX(클레임목록!$I$2:$I$2000,MATCH($B18,클레임목록!$O$2:$O$2000,0)))) | L18: =IF($B18="","",IF(INDEX(클레임목록!$J$2:$J$2000,MATCH($B18,클레임목록!$O$2:$O$2000,0))="","",INDEX(클레임목록!$J$2:$J$2000,MATCH($B18,클레임목록!$O$2:$O$2000,0))))
B19: =IF(6<=$C$11,6,"") | C19: =IF($B19="","",IF(INDEX(클레임목록!$A$2:$A$2000,MATCH($B19,클레임목록!$O$2:$O$2000,0))="","",INDEX(클레임목록!$A$2:$A$2000,MATCH($B19,클레임목록!$O$2:$O$2000,0)))) | D19: =IF($B19="","",IF(INDEX(클레임목록!$B$2:$B$2000,MATCH($B19,클레임목록!$O$2:$O$2000,0))="","",INDEX(클레임목록!$B$2:$B$2000,MATCH($B19,클레임목록!$O$2:$O$2000,0)))) | E19: =IF($B19="","",IF(INDEX(클레임목록!$C$2:$C$2000,MATCH($B19,클레임목록!$O$2:$O$2000,0))="","",INDEX(클레임목록!$C$2:$C$2000,MATCH($B19,클레임목록!$O$2:$O$2000,0)))) | F19: =IF($B19="","",IF(INDEX(클레임목록!$D$2:$D$2000,MATCH($B19,클레임목록!$O$2:$O$2000,0))="","",INDEX(클레임목록!$D$2:$D$2000,MATCH($B19,클레임목록!$O$2:$O$2000,0)))) | G19: =IF($B19="","",IF(INDEX(클레임목록!$E$2:$E$2000,MATCH($B19,클레임목록!$O$2:$O$2000,0))="","",INDEX(클레임목록!$E$2:$E$2000,MATCH($B19,클레임목록!$O$2:$O$2000,0)))) | H19: =IF($B19="","",IF(INDEX(클레임목록!$F$2:$F$2000,MATCH($B19,클레임목록!$O$2:$O$2000,0))="","",INDEX(클레임목록!$F$2:$F$2000,MATCH($B19,클레임목록!$O$2:$O$2000,0)))) | I19: =IF($B19="","",IF(INDEX(클레임목록!$G$2:$G$2000,MATCH($B19,클레임목록!$O$2:$O$2000,0))="","",INDEX(클레임목록!$G$2:$G$2000,MATCH($B19,클레임목록!$O$2:$O$2000,0)))) | J19: =IF($B19="","",IF(INDEX(클레임목록!$H$2:$H$2000,MATCH($B19,클레임목록!$O$2:$O$2000,0))="","",INDEX(클레임목록!$H$2:$H$2000,MATCH($B19,클레임목록!$O$2:$O$2000,0)))) | K19: =IF($B19="","",IF(INDEX(클레임목록!$I$2:$I$2000,MATCH($B19,클레임목록!$O$2:$O$2000,0))="","",INDEX(클레임목록!$I$2:$I$2000,MATCH($B19,클레임목록!$O$2:$O$2000,0)))) | L19: =IF($B19="","",IF(INDEX(클레임목록!$J$2:$J$2000,MATCH($B19,클레임목록!$O$2:$O$2000,0))="","",INDEX(클레임목록!$J$2:$J$2000,MATCH($B19,클레임목록!$O$2:$O$2000,0))))
B20: =IF(7<=$C$11,7,"") | C20: =IF($B20="","",IF(INDEX(클레임목록!$A$2:$A$2000,MATCH($B20,클레임목록!$O$2:$O$2000,0))="","",INDEX(클레임목록!$A$2:$A$2000,MATCH($B20,클레임목록!$O$2:$O$2000,0)))) | D20: =IF($B20="","",IF(INDEX(클레임목록!$B$2:$B$2000,MATCH($B20,클레임목록!$O$2:$O$2000,0))="","",INDEX(클레임목록!$B$2:$B$2000,MATCH($B20,클레임목록!$O$2:$O$2000,0)))) | E20: =IF($B20="","",IF(INDEX(클레임목록!$C$2:$C$2000,MATCH($B20,클레임목록!$O$2:$O$2000,0))="","",INDEX(클레임목록!$C$2:$C$2000,MATCH($B20,클레임목록!$O$2:$O$2000,0)))) | F20: =IF($B20="","",IF(INDEX(클레임목록!$D$2:$D$2000,MATCH($B20,클레임목록!$O$2:$O$2000,0))="","",INDEX(클레임목록!$D$2:$D$2000,MATCH($B20,클레임목록!$O$2:$O$2000,0)))) | G20: =IF($B20="","",IF(INDEX(클레임목록!$E$2:$E$2000,MATCH($B20,클레임목록!$O$2:$O$2000,0))="","",INDEX(클레임목록!$E$2:$E$2000,MATCH($B20,클레임목록!$O$2:$O$2000,0)))) | H20: =IF($B20="","",IF(INDEX(클레임목록!$F$2:$F$2000,MATCH($B20,클레임목록!$O$2:$O$2000,0))="","",INDEX(클레임목록!$F$2:$F$2000,MATCH($B20,클레임목록!$O$2:$O$2000,0)))) | I20: =IF($B20="","",IF(INDEX(클레임목록!$G$2:$G$2000,MATCH($B20,클레임목록!$O$2:$O$2000,0))="","",INDEX(클레임목록!$G$2:$G$2000,MATCH($B20,클레임목록!$O$2:$O$2000,0)))) | J20: =IF($B20="","",IF(INDEX(클레임목록!$H$2:$H$2000,MATCH($B20,클레임목록!$O$2:$O$2000,0))="","",INDEX(클레임목록!$H$2:$H$2000,MATCH($B20,클레임목록!$O$2:$O$2000,0)))) | K20: =IF($B20="","",IF(INDEX(클레임목록!$I$2:$I$2000,MATCH($B20,클레임목록!$O$2:$O$2000,0))="","",INDEX(클레임목록!$I$2:$I$2000,MATCH($B20,클레임목록!$O$2:$O$2000,0)))) | L20: =IF($B20="","",IF(INDEX(클레임목록!$J$2:$J$2000,MATCH($B20,클레임목록!$O$2:$O$2000,0))="","",INDEX(클레임목록!$J$2:$J$2000,MATCH($B20,클레임목록!$O$2:$O$2000,0))))
B21: =IF(8<=$C$11,8,"") | C21: =IF($B21="","",IF(INDEX(클레임목록!$A$2:$A$2000,MATCH($B21,클레임목록!$O$2:$O$2000,0))="","",INDEX(클레임목록!$A$2:$A$2000,MATCH($B21,클레임목록!$O$2:$O$2000,0)))) | D21: =IF($B21="","",IF(INDEX(클레임목록!$B$2:$B$2000,MATCH($B21,클레임목록!$O$2:$O$2000,0))="","",INDEX(클레임목록!$B$2:$B$2000,MATCH($B21,클레임목록!$O$2:$O$2000,0)))) | E21: =IF($B21="","",IF(INDEX(클레임목록!$C$2:$C$2000,MATCH($B21,클레임목록!$O$2:$O$2000,0))="","",INDEX(클레임목록!$C$2:$C$2000,MATCH($B21,클레임목록!$O$2:$O$2000,0)))) | F21: =IF($B21="","",IF(INDEX(클레임목록!$D$2:$D$2000,MATCH($B21,클레임목록!$O$2:$O$2000,0))="","",INDEX(클레임목록!$D$2:$D$2000,MATCH($B21,클레임목록!$O$2:$O$2000,0)))) | G21: =IF($B21="","",IF(INDEX(클레임목록!$E$2:$E$2000,MATCH($B21,클레임목록!$O$2:$O$2000,0))="","",INDEX(클레임목록!$E$2:$E$2000,MATCH($B21,클레임목록!$O$2:$O$2000,0)))) | H21: =IF($B21="","",IF(INDEX(클레임목록!$F$2:$F$2000,MATCH($B21,클레임목록!$O$2:$O$2000,0))="","",INDEX(클레임목록!$F$2:$F$2000,MATCH($B21,클레임목록!$O$2:$O$2000,0)))) | I21: =IF($B21="","",IF(INDEX(클레임목록!$G$2:$G$2000,MATCH($B21,클레임목록!$O$2:$O$2000,0))="","",INDEX(클레임목록!$G$2:$G$2000,MATCH($B21,클레임목록!$O$2:$O$2000,0)))) | J21: =IF($B21="","",IF(INDEX(클레임목록!$H$2:$H$2000,MATCH($B21,클레임목록!$O$2:$O$2000,0))="","",INDEX(클레임목록!$H$2:$H$2000,MATCH($B21,클레임목록!$O$2:$O$2000,0)))) | K21: =IF($B21="","",IF(INDEX(클레임목록!$I$2:$I$2000,MATCH($B21,클레임목록!$O$2:$O$2000,0))="","",INDEX(클레임목록!$I$2:$I$2000,MATCH($B21,클레임목록!$O$2:$O$2000,0)))) | L21: =IF($B21="","",IF(INDEX(클레임목록!$J$2:$J$2000,MATCH($B21,클레임목록!$O$2:$O$2000,0))="","",INDEX(클레임목록!$J$2:$J$2000,MATCH($B21,클레임목록!$O$2:$O$2000,0))))
B22: =IF(9<=$C$11,9,"") | C22: =IF($B22="","",IF(INDEX(클레임목록!$A$2:$A$2000,MATCH($B22,클레임목록!$O$2:$O$2000,0))="","",INDEX(클레임목록!$A$2:$A$2000,MATCH($B22,클레임목록!$O$2:$O$2000,0)))) | D22: =IF($B22="","",IF(INDEX(클레임목록!$B$2:$B$2000,MATCH($B22,클레임목록!$O$2:$O$2000,0))="","",INDEX(클레임목록!$B$2:$B$2000,MATCH($B22,클레임목록!$O$2:$O$2000,0)))) | E22: =IF($B22="","",IF(INDEX(클레임목록!$C$2:$C$2000,MATCH($B22,클레임목록!$O$2:$O$2000,0))="","",INDEX(클레임목록!$C$2:$C$2000,MATCH($B22,클레임목록!$O$2:$O$2000,0)))) | F22: =IF($B22="","",IF(INDEX(클레임목록!$D$2:$D$2000,MATCH($B22,클레임목록!$O$2:$O$2000,0))="","",INDEX(클레임목록!$D$2:$D$2000,MATCH($B22,클레임목록!$O$2:$O$2000,0)))) | G22: =IF($B22="","",IF(INDEX(클레임목록!$E$2:$E$2000,MATCH($B22,클레임목록!$O$2:$O$2000,0))="","",INDEX(클레임목록!$E$2:$E$2000,MATCH($B22,클레임목록!$O$2:$O$2000,0)))) | H22: =IF($B22="","",IF(INDEX(클레임목록!$F$2:$F$2000,MATCH($B22,클레임목록!$O$2:$O$2000,0))="","",INDEX(클레임목록!$F$2:$F$2000,MATCH($B22,클레임목록!$O$2:$O$2000,0)))) | I22: =IF($B22="","",IF(INDEX(클레임목록!$G$2:$G$2000,MATCH($B22,클레임목록!$O$2:$O$2000,0))="","",INDEX(클레임목록!$G$2:$G$2000,MATCH($B22,클레임목록!$O$2:$O$2000,0)))) | J22: =IF($B22="","",IF(INDEX(클레임목록!$H$2:$H$2000,MATCH($B22,클레임목록!$O$2:$O$2000,0))="","",INDEX(클레임목록!$H$2:$H$2000,MATCH($B22,클레임목록!$O$2:$O$2000,0)))) | K22: =IF($B22="","",IF(INDEX(클레임목록!$I$2:$I$2000,MATCH($B22,클레임목록!$O$2:$O$2000,0))="","",INDEX(클레임목록!$I$2:$I$2000,MATCH($B22,클레임목록!$O$2:$O$2000,0)))) | L22: =IF($B22="","",IF(INDEX(클레임목록!$J$2:$J$2000,MATCH($B22,클레임목록!$O$2:$O$2000,0))="","",INDEX(클레임목록!$J$2:$J$2000,MATCH($B22,클레임목록!$O$2:$O$2000,0))))
B23: =IF(10<=$C$11,10,"") | C23: =IF($B23="","",IF(INDEX(클레임목록!$A$2:$A$2000,MATCH($B23,클레임목록!$O$2:$O$2000,0))="","",INDEX(클레임목록!$A$2:$A$2000,MATCH($B23,클레임목록!$O$2:$O$2000,0)))) | D23: =IF($B23="","",IF(INDEX(클레임목록!$B$2:$B$2000,MATCH($B23,클레임목록!$O$2:$O$2000,0))="","",INDEX(클레임목록!$B$2:$B$2000,MATCH($B23,클레임목록!$O$2:$O$2000,0)))) | E23: =IF($B23="","",IF(INDEX(클레임목록!$C$2:$C$2000,MATCH($B23,클레임목록!$O$2:$O$2000,0))="","",INDEX(클레임목록!$C$2:$C$2000,MATCH($B23,클레임목록!$O$2:$O$2000,0)))) | F23: =IF($B23="","",IF(INDEX(클레임목록!$D$2:$D$2000,MATCH($B23,클레임목록!$O$2:$O$2000,0))="","",INDEX(클레임목록!$D$2:$D$2000,MATCH($B23,클레임목록!$O$2:$O$2000,0)))) | G23: =IF($B23="","",IF(INDEX(클레임목록!$E$2:$E$2000,MATCH($B23,클레임목록!$O$2:$O$2000,0))="","",INDEX(클레임목록!$E$2:$E$2000,MATCH($B23,클레임목록!$O$2:$O$2000,0)))) | H23: =IF($B23="","",IF(INDEX(클레임목록!$F$2:$F$2000,MATCH($B23,클레임목록!$O$2:$O$2000,0))="","",INDEX(클레임목록!$F$2:$F$2000,MATCH($B23,클레임목록!$O$2:$O$2000,0)))) | I23: =IF($B23="","",IF(INDEX(클레임목록!$G$2:$G$2000,MATCH($B23,클레임목록!$O$2:$O$2000,0))="","",INDEX(클레임목록!$G$2:$G$2000,MATCH($B23,클레임목록!$O$2:$O$2000,0)))) | J23: =IF($B23="","",IF(INDEX(클레임목록!$H$2:$H$2000,MATCH($B23,클레임목록!$O$2:$O$2000,0))="","",INDEX(클레임목록!$H$2:$H$2000,MATCH($B23,클레임목록!$O$2:$O$2000,0)))) | K23: =IF($B23="","",IF(INDEX(클레임목록!$I$2:$I$2000,MATCH($B23,클레임목록!$O$2:$O$2000,0))="","",INDEX(클레임목록!$I$2:$I$2000,MATCH($B23,클레임목록!$O$2:$O$2000,0)))) | L23: =IF($B23="","",IF(INDEX(클레임목록!$J$2:$J$2000,MATCH($B23,클레임목록!$O$2:$O$2000,0))="","",INDEX(클레임목록!$J$2:$J$2000,MATCH($B23,클레임목록!$O$2:$O$2000,0))))
B24: =IF(11<=$C$11,11,"") | C24: =IF($B24="","",IF(INDEX(클레임목록!$A$2:$A$2000,MATCH($B24,클레임목록!$O$2:$O$2000,0))="","",INDEX(클레임목록!$A$2:$A$2000,MATCH($B24,클레임목록!$O$2:$O$2000,0)))) | D24: =IF($B24="","",IF(INDEX(클레임목록!$B$2:$B$2000,MATCH($B24,클레임목록!$O$2:$O$2000,0))="","",INDEX(클레임목록!$B$2:$B$2000,MATCH($B24,클레임목록!$O$2:$O$2000,0)))) | E24: =IF($B24="","",IF(INDEX(클레임목록!$C$2:$C$2000,MATCH($B24,클레임목록!$O$2:$O$2000,0))="","",INDEX(클레임목록!$C$2:$C$2000,MATCH($B24,클레임목록!$O$2:$O$2000,0)))) | F24: =IF($B24="","",IF(INDEX(클레임목록!$D$2:$D$2000,MATCH($B24,클레임목록!$O$2:$O$2000,0))="","",INDEX(클레임목록!$D$2:$D$2000,MATCH($B24,클레임목록!$O$2:$O$2000,0)))) | G24: =IF($B24="","",IF(INDEX(클레임목록!$E$2:$E$2000,MATCH($B24,클레임목록!$O$2:$O$2000,0))="","",INDEX(클레임목록!$E$2:$E$2000,MATCH($B24,클레임목록!$O$2:$O$2000,0)))) | H24: =IF($B24="","",IF(INDEX(클레임목록!$F$2:$F$2000,MATCH($B24,클레임목록!$O$2:$O$2000,0))="","",INDEX(클레임목록!$F$2:$F$2000,MATCH($B24,클레임목록!$O$2:$O$2000,0)))) | I24: =IF($B24="","",IF(INDEX(클레임목록!$G$2:$G$2000,MATCH($B24,클레임목록!$O$2:$O$2000,0))="","",INDEX(클레임목록!$G$2:$G$2000,MATCH($B24,클레임목록!$O$2:$O$2000,0)))) | J24: =IF($B24="","",IF(INDEX(클레임목록!$H$2:$H$2000,MATCH($B24,클레임목록!$O$2:$O$2000,0))="","",INDEX(클레임목록!$H$2:$H$2000,MATCH($B24,클레임목록!$O$2:$O$2000,0)))) | K24: =IF($B24="","",IF(INDEX(클레임목록!$I$2:$I$2000,MATCH($B24,클레임목록!$O$2:$O$2000,0))="","",INDEX(클레임목록!$I$2:$I$2000,MATCH($B24,클레임목록!$O$2:$O$2000,0)))) | L24: =IF($B24="","",IF(INDEX(클레임목록!$J$2:$J$2000,MATCH($B24,클레임목록!$O$2:$O$2000,0))="","",INDEX(클레임목록!$J$2:$J$2000,MATCH($B24,클레임목록!$O$2:$O$2000,0))))
B25: =IF(12<=$C$11,12,"") | C25: =IF($B25="","",IF(INDEX(클레임목록!$A$2:$A$2000,MATCH($B25,클레임목록!$O$2:$O$2000,0))="","",INDEX(클레임목록!$A$2:$A$2000,MATCH($B25,클레임목록!$O$2:$O$2000,0)))) | D25: =IF($B25="","",IF(INDEX(클레임목록!$B$2:$B$2000,MATCH($B25,클레임목록!$O$2:$O$2000,0))="","",INDEX(클레임목록!$B$2:$B$2000,MATCH($B25,클레임목록!$O$2:$O$2000,0)))) | E25: =IF($B25="","",IF(INDEX(클레임목록!$C$2:$C$2000,MATCH($B25,클레임목록!$O$2:$O$2000,0))="","",INDEX(클레임목록!$C$2:$C$2000,MATCH($B25,클레임목록!$O$2:$O$2000,0)))) | F25: =IF($B25="","",IF(INDEX(클레임목록!$D$2:$D$2000,MATCH($B25,클레임목록!$O$2:$O$2000,0))="","",INDEX(클레임목록!$D$2:$D$2000,MATCH($B25,클레임목록!$O$2:$O$2000,0)))) | G25: =IF($B25="","",IF(INDEX(클레임목록!$E$2:$E$2000,MATCH($B25,클레임목록!$O$2:$O$2000,0))="","",INDEX(클레임목록!$E$2:$E$2000,MATCH($B25,클레임목록!$O$2:$O$2000,0)))) | H25: =IF($B25="","",IF(INDEX(클레임목록!$F$2:$F$2000,MATCH($B25,클레임목록!$O$2:$O$2000,0))="","",INDEX(클레임목록!$F$2:$F$2000,MATCH($B25,클레임목록!$O$2:$O$2000,0)))) | I25: =IF($B25="","",IF(INDEX(클레임목록!$G$2:$G$2000,MATCH($B25,클레임목록!$O$2:$O$2000,0))="","",INDEX(클레임목록!$G$2:$G$2000,MATCH($B25,클레임목록!$O$2:$O$2000,0)))) | J25: =IF($B25="","",IF(INDEX(클레임목록!$H$2:$H$2000,MATCH($B25,클레임목록!$O$2:$O$2000,0))="","",INDEX(클레임목록!$H$2:$H$2000,MATCH($B25,클레임목록!$O$2:$O$2000,0)))) | K25: =IF($B25="","",IF(INDEX(클레임목록!$I$2:$I$2000,MATCH($B25,클레임목록!$O$2:$O$2000,0))="","",INDEX(클레임목록!$I$2:$I$2000,MATCH($B25,클레임목록!$O$2:$O$2000,0)))) | L25: =IF($B25="","",IF(INDEX(클레임목록!$J$2:$J$2000,MATCH($B25,클레임목록!$O$2:$O$2000,0))="","",INDEX(클레임목록!$J$2:$J$2000,MATCH($B25,클레임목록!$O$2:$O$2000,0))))
B26: =IF(13<=$C$11,13,"") | C26: =IF($B26="","",IF(INDEX(클레임목록!$A$2:$A$2000,MATCH($B26,클레임목록!$O$2:$O$2000,0))="","",INDEX(클레임목록!$A$2:$A$2000,MATCH($B26,클레임목록!$O$2:$O$2000,0)))) | D26: =IF($B26="","",IF(INDEX(클레임목록!$B$2:$B$2000,MATCH($B26,클레임목록!$O$2:$O$2000,0))="","",INDEX(클레임목록!$B$2:$B$2000,MATCH($B26,클레임목록!$O$2:$O$2000,0)))) | E26: =IF($B26="","",IF(INDEX(클레임목록!$C$2:$C$2000,MATCH($B26,클레임목록!$O$2:$O$2000,0))="","",INDEX(클레임목록!$C$2:$C$2000,MATCH($B26,클레임목록!$O$2:$O$2000,0)))) | F26: =IF($B26="","",IF(INDEX(클레임목록!$D$2:$D$2000,MATCH($B26,클레임목록!$O$2:$O$2000,0))="","",INDEX(클레임목록!$D$2:$D$2000,MATCH($B26,클레임목록!$O$2:$O$2000,0)))) | G26: =IF($B26="","",IF(INDEX(클레임목록!$E$2:$E$2000,MATCH($B26,클레임목록!$O$2:$O$2000,0))="","",INDEX(클레임목록!$E$2:$E$2000,MATCH($B26,클레임목록!$O$2:$O$2000,0)))) | H26: =IF($B26="","",IF(INDEX(클레임목록!$F$2:$F$2000,MATCH($B26,클레임목록!$O$2:$O$2000,0))="","",INDEX(클레임목록!$F$2:$F$2000,MATCH($B26,클레임목록!$O$2:$O$2000,0)))) | I26: =IF($B26="","",IF(INDEX(클레임목록!$G$2:$G$2000,MATCH($B26,클레임목록!$O$2:$O$2000,0))="","",INDEX(클레임목록!$G$2:$G$2000,MATCH($B26,클레임목록!$O$2:$O$2000,0)))) | J26: =IF($B26="","",IF(INDEX(클레임목록!$H$2:$H$2000,MATCH($B26,클레임목록!$O$2:$O$2000,0))="","",INDEX(클레임목록!$H$2:$H$2000,MATCH($B26,클레임목록!$O$2:$O$2000,0)))) | K26: =IF($B26="","",IF(INDEX(클레임목록!$I$2:$I$2000,MATCH($B26,클레임목록!$O$2:$O$2000,0))="","",INDEX(클레임목록!$I$2:$I$2000,MATCH($B26,클레임목록!$O$2:$O$2000,0)))) | L26: =IF($B26="","",IF(INDEX(클레임목록!$J$2:$J$2000,MATCH($B26,클레임목록!$O$2:$O$2000,0))="","",INDEX(클레임목록!$J$2:$J$2000,MATCH($B26,클레임목록!$O$2:$O$2000,0))))
B27: =IF(14<=$C$11,14,"") | C27: =IF($B27="","",IF(INDEX(클레임목록!$A$2:$A$2000,MATCH($B27,클레임목록!$O$2:$O$2000,0))="","",INDEX(클레임목록!$A$2:$A$2000,MATCH($B27,클레임목록!$O$2:$O$2000,0)))) | D27: =IF($B27="","",IF(INDEX(클레임목록!$B$2:$B$2000,MATCH($B27,클레임목록!$O$2:$O$2000,0))="","",INDEX(클레임목록!$B$2:$B$2000,MATCH($B27,클레임목록!$O$2:$O$2000,0)))) | E27: =IF($B27="","",IF(INDEX(클레임목록!$C$2:$C$2000,MATCH($B27,클레임목록!$O$2:$O$2000,0))="","",INDEX(클레임목록!$C$2:$C$2000,MATCH($B27,클레임목록!$O$2:$O$2000,0)))) | F27: =IF($B27="","",IF(INDEX(클레임목록!$D$2:$D$2000,MATCH($B27,클레임목록!$O$2:$O$2000,0))="","",INDEX(클레임목록!$D$2:$D$2000,MATCH($B27,클레임목록!$O$2:$O$2000,0)))) | G27: =IF($B27="","",IF(INDEX(클레임목록!$E$2:$E$2000,MATCH($B27,클레임목록!$O$2:$O$2000,0))="","",INDEX(클레임목록!$E$2:$E$2000,MATCH($B27,클레임목록!$O$2:$O$2000,0)))) | H27: =IF($B27="","",IF(INDEX(클레임목록!$F$2:$F$2000,MATCH($B27,클레임목록!$O$2:$O$2000,0))="","",INDEX(클레임목록!$F$2:$F$2000,MATCH($B27,클레임목록!$O$2:$O$2000,0)))) | I27: =IF($B27="","",IF(INDEX(클레임목록!$G$2:$G$2000,MATCH($B27,클레임목록!$O$2:$O$2000,0))="","",INDEX(클레임목록!$G$2:$G$2000,MATCH($B27,클레임목록!$O$2:$O$2000,0)))) | J27: =IF($B27="","",IF(INDEX(클레임목록!$H$2:$H$2000,MATCH($B27,클레임목록!$O$2:$O$2000,0))="","",INDEX(클레임목록!$H$2:$H$2000,MATCH($B27,클레임목록!$O$2:$O$2000,0)))) | K27: =IF($B27="","",IF(INDEX(클레임목록!$I$2:$I$2000,MATCH($B27,클레임목록!$O$2:$O$2000,0))="","",INDEX(클레임목록!$I$2:$I$2000,MATCH($B27,클레임목록!$O$2:$O$2000,0)))) | L27: =IF($B27="","",IF(INDEX(클레임목록!$J$2:$J$2000,MATCH($B27,클레임목록!$O$2:$O$2000,0))="","",INDEX(클레임목록!$J$2:$J$2000,MATCH($B27,클레임목록!$O$2:$O$2000,0))))
B28: =IF(15<=$C$11,15,"") | C28: =IF($B28="","",IF(INDEX(클레임목록!$A$2:$A$2000,MATCH($B28,클레임목록!$O$2:$O$2000,0))="","",INDEX(클레임목록!$A$2:$A$2000,MATCH($B28,클레임목록!$O$2:$O$2000,0)))) | D28: =IF($B28="","",IF(INDEX(클레임목록!$B$2:$B$2000,MATCH($B28,클레임목록!$O$2:$O$2000,0))="","",INDEX(클레임목록!$B$2:$B$2000,MATCH($B28,클레임목록!$O$2:$O$2000,0)))) | E28: =IF($B28="","",IF(INDEX(클레임목록!$C$2:$C$2000,MATCH($B28,클레임목록!$O$2:$O$2000,0))="","",INDEX(클레임목록!$C$2:$C$2000,MATCH($B28,클레임목록!$O$2:$O$2000,0)))) | F28: =IF($B28="","",IF(INDEX(클레임목록!$D$2:$D$2000,MATCH($B28,클레임목록!$O$2:$O$2000,0))="","",INDEX(클레임목록!$D$2:$D$2000,MATCH($B28,클레임목록!$O$2:$O$2000,0)))) | G28: =IF($B28="","",IF(INDEX(클레임목록!$E$2:$E$2000,MATCH($B28,클레임목록!$O$2:$O$2000,0))="","",INDEX(클레임목록!$E$2:$E$2000,MATCH($B28,클레임목록!$O$2:$O$2000,0)))) | H28: =IF($B28="","",IF(INDEX(클레임목록!$F$2:$F$2000,MATCH($B28,클레임목록!$O$2:$O$2000,0))="","",INDEX(클레임목록!$F$2:$F$2000,MATCH($B28,클레임목록!$O$2:$O$2000,0)))) | I28: =IF($B28="","",IF(INDEX(클레임목록!$G$2:$G$2000,MATCH($B28,클레임목록!$O$2:$O$2000,0))="","",INDEX(클레임목록!$G$2:$G$2000,MATCH($B28,클레임목록!$O$2:$O$2000,0)))) | J28: =IF($B28="","",IF(INDEX(클레임목록!$H$2:$H$2000,MATCH($B28,클레임목록!$O$2:$O$2000,0))="","",INDEX(클레임목록!$H$2:$H$2000,MATCH($B28,클레임목록!$O$2:$O$2000,0)))) | K28: =IF($B28="","",IF(INDEX(클레임목록!$I$2:$I$2000,MATCH($B28,클레임목록!$O$2:$O$2000,0))="","",INDEX(클레임목록!$I$2:$I$2000,MATCH($B28,클레임목록!$O$2:$O$2000,0)))) | L28: =IF($B28="","",IF(INDEX(클레임목록!$J$2:$J$2000,MATCH($B28,클레임목록!$O$2:$O$2000,0))="","",INDEX(클레임목록!$J$2:$J$2000,MATCH($B28,클레임목록!$O$2:$O$2000,0))))
B29: =IF(16<=$C$11,16,"") | C29: =IF($B29="","",IF(INDEX(클레임목록!$A$2:$A$2000,MATCH($B29,클레임목록!$O$2:$O$2000,0))="","",INDEX(클레임목록!$A$2:$A$2000,MATCH($B29,클레임목록!$O$2:$O$2000,0)))) | D29: =IF($B29="","",IF(INDEX(클레임목록!$B$2:$B$2000,MATCH($B29,클레임목록!$O$2:$O$2000,0))="","",INDEX(클레임목록!$B$2:$B$2000,MATCH($B29,클레임목록!$O$2:$O$2000,0)))) | E29: =IF($B29="","",IF(INDEX(클레임목록!$C$2:$C$2000,MATCH($B29,클레임목록!$O$2:$O$2000,0))="","",INDEX(클레임목록!$C$2:$C$2000,MATCH($B29,클레임목록!$O$2:$O$2000,0)))) | F29: =IF($B29="","",IF(INDEX(클레임목록!$D$2:$D$2000,MATCH($B29,클레임목록!$O$2:$O$2000,0))="","",INDEX(클레임목록!$D$2:$D$2000,MATCH($B29,클레임목록!$O$2:$O$2000,0)))) | G29: =IF($B29="","",IF(INDEX(클레임목록!$E$2:$E$2000,MATCH($B29,클레임목록!$O$2:$O$2000,0))="","",INDEX(클레임목록!$E$2:$E$2000,MATCH($B29,클레임목록!$O$2:$O$2000,0)))) | H29: =IF($B29="","",IF(INDEX(클레임목록!$F$2:$F$2000,MATCH($B29,클레임목록!$O$2:$O$2000,0))="","",INDEX(클레임목록!$F$2:$F$2000,MATCH($B29,클레임목록!$O$2:$O$2000,0)))) | I29: =IF($B29="","",IF(INDEX(클레임목록!$G$2:$G$2000,MATCH($B29,클레임목록!$O$2:$O$2000,0))="","",INDEX(클레임목록!$G$2:$G$2000,MATCH($B29,클레임목록!$O$2:$O$2000,0)))) | J29: =IF($B29="","",IF(INDEX(클레임목록!$H$2:$H$2000,MATCH($B29,클레임목록!$O$2:$O$2000,0))="","",INDEX(클레임목록!$H$2:$H$2000,MATCH($B29,클레임목록!$O$2:$O$2000,0)))) | K29: =IF($B29="","",IF(INDEX(클레임목록!$I$2:$I$2000,MATCH($B29,클레임목록!$O$2:$O$2000,0))="","",INDEX(클레임목록!$I$2:$I$2000,MATCH($B29,클레임목록!$O$2:$O$2000,0)))) | L29: =IF($B29="","",IF(INDEX(클레임목록!$J$2:$J$2000,MATCH($B29,클레임목록!$O$2:$O$2000,0))="","",INDEX(클레임목록!$J$2:$J$2000,MATCH($B29,클레임목록!$O$2:$O$2000,0))))
B30: =IF(17<=$C$11,17,"") | C30: =IF($B30="","",IF(INDEX(클레임목록!$A$2:$A$2000,MATCH($B30,클레임목록!$O$2:$O$2000,0))="","",INDEX(클레임목록!$A$2:$A$2000,MATCH($B30,클레임목록!$O$2:$O$2000,0)))) | D30: =IF($B30="","",IF(INDEX(클레임목록!$B$2:$B$2000,MATCH($B30,클레임목록!$O$2:$O$2000,0))="","",INDEX(클레임목록!$B$2:$B$2000,MATCH($B30,클레임목록!$O$2:$O$2000,0)))) | E30: =IF($B30="","",IF(INDEX(클레임목록!$C$2:$C$2000,MATCH($B30,클레임목록!$O$2:$O$2000,0))="","",INDEX(클레임목록!$C$2:$C$2000,MATCH($B30,클레임목록!$O$2:$O$2000,0)))) | F30: =IF($B30="","",IF(INDEX(클레임목록!$D$2:$D$2000,MATCH($B30,클레임목록!$O$2:$O$2000,0))="","",INDEX(클레임목록!$D$2:$D$2000,MATCH($B30,클레임목록!$O$2:$O$2000,0)))) | G30: =IF($B30="","",IF(INDEX(클레임목록!$E$2:$E$2000,MATCH($B30,클레임목록!$O$2:$O$2000,0))="","",INDEX(클레임목록!$E$2:$E$2000,MATCH($B30,클레임목록!$O$2:$O$2000,0)))) | H30: =IF($B30="","",IF(INDEX(클레임목록!$F$2:$F$2000,MATCH($B30,클레임목록!$O$2:$O$2000,0))="","",INDEX(클레임목록!$F$2:$F$2000,MATCH($B30,클레임목록!$O$2:$O$2000,0)))) | I30: =IF($B30="","",IF(INDEX(클레임목록!$G$2:$G$2000,MATCH($B30,클레임목록!$O$2:$O$2000,0))="","",INDEX(클레임목록!$G$2:$G$2000,MATCH($B30,클레임목록!$O$2:$O$2000,0)))) | J30: =IF($B30="","",IF(INDEX(클레임목록!$H$2:$H$2000,MATCH($B30,클레임목록!$O$2:$O$2000,0))="","",INDEX(클레임목록!$H$2:$H$2000,MATCH($B30,클레임목록!$O$2:$O$2000,0)))) | K30: =IF($B30="","",IF(INDEX(클레임목록!$I$2:$I$2000,MATCH($B30,클레임목록!$O$2:$O$2000,0))="","",INDEX(클레임목록!$I$2:$I$2000,MATCH($B30,클레임목록!$O$2:$O$2000,0)))) | L30: =IF($B30="","",IF(INDEX(클레임목록!$J$2:$J$2000,MATCH($B30,클레임목록!$O$2:$O$2000,0))="","",INDEX(클레임목록!$J$2:$J$2000,MATCH($B30,클레임목록!$O$2:$O$2000,0))))
B31: =IF(18<=$C$11,18,"") | C31: =IF($B31="","",IF(INDEX(클레임목록!$A$2:$A$2000,MATCH($B31,클레임목록!$O$2:$O$2000,0))="","",INDEX(클레임목록!$A$2:$A$2000,MATCH($B31,클레임목록!$O$2:$O$2000,0)))) | D31: =IF($B31="","",IF(INDEX(클레임목록!$B$2:$B$2000,MATCH($B31,클레임목록!$O$2:$O$2000,0))="","",INDEX(클레임목록!$B$2:$B$2000,MATCH($B31,클레임목록!$O$2:$O$2000,0)))) | E31: =IF($B31="","",IF(INDEX(클레임목록!$C$2:$C$2000,MATCH($B31,클레임목록!$O$2:$O$2000,0))="","",INDEX(클레임목록!$C$2:$C$2000,MATCH($B31,클레임목록!$O$2:$O$2000,0)))) | F31: =IF($B31="","",IF(INDEX(클레임목록!$D$2:$D$2000,MATCH($B31,클레임목록!$O$2:$O$2000,0))="","",INDEX(클레임목록!$D$2:$D$2000,MATCH($B31,클레임목록!$O$2:$O$2000,0)))) | G31: =IF($B31="","",IF(INDEX(클레임목록!$E$2:$E$2000,MATCH($B31,클레임목록!$O$2:$O$2000,0))="","",INDEX(클레임목록!$E$2:$E$2000,MATCH($B31,클레임목록!$O$2:$O$2000,0)))) | H31: =IF($B31="","",IF(INDEX(클레임목록!$F$2:$F$2000,MATCH($B31,클레임목록!$O$2:$O$2000,0))="","",INDEX(클레임목록!$F$2:$F$2000,MATCH($B31,클레임목록!$O$2:$O$2000,0)))) | I31: =IF($B31="","",IF(INDEX(클레임목록!$G$2:$G$2000,MATCH($B31,클레임목록!$O$2:$O$2000,0))="","",INDEX(클레임목록!$G$2:$G$2000,MATCH($B31,클레임목록!$O$2:$O$2000,0)))) | J31: =IF($B31="","",IF(INDEX(클레임목록!$H$2:$H$2000,MATCH($B31,클레임목록!$O$2:$O$2000,0))="","",INDEX(클레임목록!$H$2:$H$2000,MATCH($B31,클레임목록!$O$2:$O$2000,0)))) | K31: =IF($B31="","",IF(INDEX(클레임목록!$I$2:$I$2000,MATCH($B31,클레임목록!$O$2:$O$2000,0))="","",INDEX(클레임목록!$I$2:$I$2000,MATCH($B31,클레임목록!$O$2:$O$2000,0)))) | L31: =IF($B31="","",IF(INDEX(클레임목록!$J$2:$J$2000,MATCH($B31,클레임목록!$O$2:$O$2000,0))="","",INDEX(클레임목록!$J$2:$J$2000,MATCH($B31,클레임목록!$O$2:$O$2000,0))))
B32: =IF(19<=$C$11,19,"") | C32: =IF($B32="","",IF(INDEX(클레임목록!$A$2:$A$2000,MATCH($B32,클레임목록!$O$2:$O$2000,0))="","",INDEX(클레임목록!$A$2:$A$2000,MATCH($B32,클레임목록!$O$2:$O$2000,0)))) | D32: =IF($B32="","",IF(INDEX(클레임목록!$B$2:$B$2000,MATCH($B32,클레임목록!$O$2:$O$2000,0))="","",INDEX(클레임목록!$B$2:$B$2000,MATCH($B32,클레임목록!$O$2:$O$2000,0)))) | E32: =IF($B32="","",IF(INDEX(클레임목록!$C$2:$C$2000,MATCH($B32,클레임목록!$O$2:$O$2000,0))="","",INDEX(클레임목록!$C$2:$C$2000,MATCH($B32,클레임목록!$O$2:$O$2000,0)))) | F32: =IF($B32="","",IF(INDEX(클레임목록!$D$2:$D$2000,MATCH($B32,클레임목록!$O$2:$O$2000,0))="","",INDEX(클레임목록!$D$2:$D$2000,MATCH($B32,클레임목록!$O$2:$O$2000,0)))) | G32: =IF($B32="","",IF(INDEX(클레임목록!$E$2:$E$2000,MATCH($B32,클레임목록!$O$2:$O$2000,0))="","",INDEX(클레임목록!$E$2:$E$2000,MATCH($B32,클레임목록!$O$2:$O$2000,0)))) | H32: =IF($B32="","",IF(INDEX(클레임목록!$F$2:$F$2000,MATCH($B32,클레임목록!$O$2:$O$2000,0))="","",INDEX(클레임목록!$F$2:$F$2000,MATCH($B32,클레임목록!$O$2:$O$2000,0)))) | I32: =IF($B32="","",IF(INDEX(클레임목록!$G$2:$G$2000,MATCH($B32,클레임목록!$O$2:$O$2000,0))="","",INDEX(클레임목록!$G$2:$G$2000,MATCH($B32,클레임목록!$O$2:$O$2000,0)))) | J32: =IF($B32="","",IF(INDEX(클레임목록!$H$2:$H$2000,MATCH($B32,클레임목록!$O$2:$O$2000,0))="","",INDEX(클레임목록!$H$2:$H$2000,MATCH($B32,클레임목록!$O$2:$O$2000,0)))) | K32: =IF($B32="","",IF(INDEX(클레임목록!$I$2:$I$2000,MATCH($B32,클레임목록!$O$2:$O$2000,0))="","",INDEX(클레임목록!$I$2:$I$2000,MATCH($B32,클레임목록!$O$2:$O$2000,0)))) | L32: =IF($B32="","",IF(INDEX(클레임목록!$J$2:$J$2000,MATCH($B32,클레임목록!$O$2:$O$2000,0))="","",INDEX(클레임목록!$J$2:$J$2000,MATCH($B32,클레임목록!$O$2:$O$2000,0))))
B33: =IF(20<=$C$11,20,"") | C33: =IF($B33="","",IF(INDEX(클레임목록!$A$2:$A$2000,MATCH($B33,클레임목록!$O$2:$O$2000,0))="","",INDEX(클레임목록!$A$2:$A$2000,MATCH($B33,클레임목록!$O$2:$O$2000,0)))) | D33: =IF($B33="","",IF(INDEX(클레임목록!$B$2:$B$2000,MATCH($B33,클레임목록!$O$2:$O$2000,0))="","",INDEX(클레임목록!$B$2:$B$2000,MATCH($B33,클레임목록!$O$2:$O$2000,0)))) | E33: =IF($B33="","",IF(INDEX(클레임목록!$C$2:$C$2000,MATCH($B33,클레임목록!$O$2:$O$2000,0))="","",INDEX(클레임목록!$C$2:$C$2000,MATCH($B33,클레임목록!$O$2:$O$2000,0)))) | F33: =IF($B33="","",IF(INDEX(클레임목록!$D$2:$D$2000,MATCH($B33,클레임목록!$O$2:$O$2000,0))="","",INDEX(클레임목록!$D$2:$D$2000,MATCH($B33,클레임목록!$O$2:$O$2000,0)))) | G33: =IF($B33="","",IF(INDEX(클레임목록!$E$2:$E$2000,MATCH($B33,클레임목록!$O$2:$O$2000,0))="","",INDEX(클레임목록!$E$2:$E$2000,MATCH($B33,클레임목록!$O$2:$O$2000,0)))) | H33: =IF($B33="","",IF(INDEX(클레임목록!$F$2:$F$2000,MATCH($B33,클레임목록!$O$2:$O$2000,0))="","",INDEX(클레임목록!$F$2:$F$2000,MATCH($B33,클레임목록!$O$2:$O$2000,0)))) | I33: =IF($B33="","",IF(INDEX(클레임목록!$G$2:$G$2000,MATCH($B33,클레임목록!$O$2:$O$2000,0))="","",INDEX(클레임목록!$G$2:$G$2000,MATCH($B33,클레임목록!$O$2:$O$2000,0)))) | J33: =IF($B33="","",IF(INDEX(클레임목록!$H$2:$H$2000,MATCH($B33,클레임목록!$O$2:$O$2000,0))="","",INDEX(클레임목록!$H$2:$H$2000,MATCH($B33,클레임목록!$O$2:$O$2000,0)))) | K33: =IF($B33="","",IF(INDEX(클레임목록!$I$2:$I$2000,MATCH($B33,클레임목록!$O$2:$O$2000,0))="","",INDEX(클레임목록!$I$2:$I$2000,MATCH($B33,클레임목록!$O$2:$O$2000,0)))) | L33: =IF($B33="","",IF(INDEX(클레임목록!$J$2:$J$2000,MATCH($B33,클레임목록!$O$2:$O$2000,0))="","",INDEX(클레임목록!$J$2:$J$2000,MATCH($B33,클레임목록!$O$2:$O$2000,0))))
B34: =IF(21<=$C$11,21,"") | C34: =IF($B34="","",IF(INDEX(클레임목록!$A$2:$A$2000,MATCH($B34,클레임목록!$O$2:$O$2000,0))="","",INDEX(클레임목록!$A$2:$A$2000,MATCH($B34,클레임목록!$O$2:$O$2000,0)))) | D34: =IF($B34="","",IF(INDEX(클레임목록!$B$2:$B$2000,MATCH($B34,클레임목록!$O$2:$O$2000,0))="","",INDEX(클레임목록!$B$2:$B$2000,MATCH($B34,클레임목록!$O$2:$O$2000,0)))) | E34: =IF($B34="","",IF(INDEX(클레임목록!$C$2:$C$2000,MATCH($B34,클레임목록!$O$2:$O$2000,0))="","",INDEX(클레임목록!$C$2:$C$2000,MATCH($B34,클레임목록!$O$2:$O$2000,0)))) | F34: =IF($B34="","",IF(INDEX(클레임목록!$D$2:$D$2000,MATCH($B34,클레임목록!$O$2:$O$2000,0))="","",INDEX(클레임목록!$D$2:$D$2000,MATCH($B34,클레임목록!$O$2:$O$2000,0)))) | G34: =IF($B34="","",IF(INDEX(클레임목록!$E$2:$E$2000,MATCH($B34,클레임목록!$O$2:$O$2000,0))="","",INDEX(클레임목록!$E$2:$E$2000,MATCH($B34,클레임목록!$O$2:$O$2000,0)))) | H34: =IF($B34="","",IF(INDEX(클레임목록!$F$2:$F$2000,MATCH($B34,클레임목록!$O$2:$O$2000,0))="","",INDEX(클레임목록!$F$2:$F$2000,MATCH($B34,클레임목록!$O$2:$O$2000,0)))) | I34: =IF($B34="","",IF(INDEX(클레임목록!$G$2:$G$2000,MATCH($B34,클레임목록!$O$2:$O$2000,0))="","",INDEX(클레임목록!$G$2:$G$2000,MATCH($B34,클레임목록!$O$2:$O$2000,0)))) | J34: =IF($B34="","",IF(INDEX(클레임목록!$H$2:$H$2000,MATCH($B34,클레임목록!$O$2:$O$2000,0))="","",INDEX(클레임목록!$H$2:$H$2000,MATCH($B34,클레임목록!$O$2:$O$2000,0)))) | K34: =IF($B34="","",IF(INDEX(클레임목록!$I$2:$I$2000,MATCH($B34,클레임목록!$O$2:$O$2000,0))="","",INDEX(클레임목록!$I$2:$I$2000,MATCH($B34,클레임목록!$O$2:$O$2000,0)))) | L34: =IF($B34="","",IF(INDEX(클레임목록!$J$2:$J$2000,MATCH($B34,클레임목록!$O$2:$O$2000,0))="","",INDEX(클레임목록!$J$2:$J$2000,MATCH($B34,클레임목록!$O$2:$O$2000,0))))
B35: =IF(22<=$C$11,22,"") | C35: =IF($B35="","",IF(INDEX(클레임목록!$A$2:$A$2000,MATCH($B35,클레임목록!$O$2:$O$2000,0))="","",INDEX(클레임목록!$A$2:$A$2000,MATCH($B35,클레임목록!$O$2:$O$2000,0)))) | D35: =IF($B35="","",IF(INDEX(클레임목록!$B$2:$B$2000,MATCH($B35,클레임목록!$O$2:$O$2000,0))="","",INDEX(클레임목록!$B$2:$B$2000,MATCH($B35,클레임목록!$O$2:$O$2000,0)))) | E35: =IF($B35="","",IF(INDEX(클레임목록!$C$2:$C$2000,MATCH($B35,클레임목록!$O$2:$O$2000,0))="","",INDEX(클레임목록!$C$2:$C$2000,MATCH($B35,클레임목록!$O$2:$O$2000,0)))) | F35: =IF($B35="","",IF(INDEX(클레임목록!$D$2:$D$2000,MATCH($B35,클레임목록!$O$2:$O$2000,0))="","",INDEX(클레임목록!$D$2:$D$2000,MATCH($B35,클레임목록!$O$2:$O$2000,0)))) | G35: =IF($B35="","",IF(INDEX(클레임목록!$E$2:$E$2000,MATCH($B35,클레임목록!$O$2:$O$2000,0))="","",INDEX(클레임목록!$E$2:$E$2000,MATCH($B35,클레임목록!$O$2:$O$2000,0)))) | H35: =IF($B35="","",IF(INDEX(클레임목록!$F$2:$F$2000,MATCH($B35,클레임목록!$O$2:$O$2000,0))="","",INDEX(클레임목록!$F$2:$F$2000,MATCH($B35,클레임목록!$O$2:$O$2000,0)))) | I35: =IF($B35="","",IF(INDEX(클레임목록!$G$2:$G$2000,MATCH($B35,클레임목록!$O$2:$O$2000,0))="","",INDEX(클레임목록!$G$2:$G$2000,MATCH($B35,클레임목록!$O$2:$O$2000,0)))) | J35: =IF($B35="","",IF(INDEX(클레임목록!$H$2:$H$2000,MATCH($B35,클레임목록!$O$2:$O$2000,0))="","",INDEX(클레임목록!$H$2:$H$2000,MATCH($B35,클레임목록!$O$2:$O$2000,0)))) | K35: =IF($B35="","",IF(INDEX(클레임목록!$I$2:$I$2000,MATCH($B35,클레임목록!$O$2:$O$2000,0))="","",INDEX(클레임목록!$I$2:$I$2000,MATCH($B35,클레임목록!$O$2:$O$2000,0)))) | L35: =IF($B35="","",IF(INDEX(클레임목록!$J$2:$J$2000,MATCH($B35,클레임목록!$O$2:$O$2000,0))="","",INDEX(클레임목록!$J$2:$J$2000,MATCH($B35,클레임목록!$O$2:$O$2000,0))))
B36: =IF(23<=$C$11,23,"") | C36: =IF($B36="","",IF(INDEX(클레임목록!$A$2:$A$2000,MATCH($B36,클레임목록!$O$2:$O$2000,0))="","",INDEX(클레임목록!$A$2:$A$2000,MATCH($B36,클레임목록!$O$2:$O$2000,0)))) | D36: =IF($B36="","",IF(INDEX(클레임목록!$B$2:$B$2000,MATCH($B36,클레임목록!$O$2:$O$2000,0))="","",INDEX(클레임목록!$B$2:$B$2000,MATCH($B36,클레임목록!$O$2:$O$2000,0)))) | E36: =IF($B36="","",IF(INDEX(클레임목록!$C$2:$C$2000,MATCH($B36,클레임목록!$O$2:$O$2000,0))="","",INDEX(클레임목록!$C$2:$C$2000,MATCH($B36,클레임목록!$O$2:$O$2000,0)))) | F36: =IF($B36="","",IF(INDEX(클레임목록!$D$2:$D$2000,MATCH($B36,클레임목록!$O$2:$O$2000,0))="","",INDEX(클레임목록!$D$2:$D$2000,MATCH($B36,클레임목록!$O$2:$O$2000,0)))) | G36: =IF($B36="","",IF(INDEX(클레임목록!$E$2:$E$2000,MATCH($B36,클레임목록!$O$2:$O$2000,0))="","",INDEX(클레임목록!$E$2:$E$2000,MATCH($B36,클레임목록!$O$2:$O$2000,0)))) | H36: =IF($B36="","",IF(INDEX(클레임목록!$F$2:$F$2000,MATCH($B36,클레임목록!$O$2:$O$2000,0))="","",INDEX(클레임목록!$F$2:$F$2000,MATCH($B36,클레임목록!$O$2:$O$2000,0)))) | I36: =IF($B36="","",IF(INDEX(클레임목록!$G$2:$G$2000,MATCH($B36,클레임목록!$O$2:$O$2000,0))="","",INDEX(클레임목록!$G$2:$G$2000,MATCH($B36,클레임목록!$O$2:$O$2000,0)))) | J36: =IF($B36="","",IF(INDEX(클레임목록!$H$2:$H$2000,MATCH($B36,클레임목록!$O$2:$O$2000,0))="","",INDEX(클레임목록!$H$2:$H$2000,MATCH($B36,클레임목록!$O$2:$O$2000,0)))) | K36: =IF($B36="","",IF(INDEX(클레임목록!$I$2:$I$2000,MATCH($B36,클레임목록!$O$2:$O$2000,0))="","",INDEX(클레임목록!$I$2:$I$2000,MATCH($B36,클레임목록!$O$2:$O$2000,0)))) | L36: =IF($B36="","",IF(INDEX(클레임목록!$J$2:$J$2000,MATCH($B36,클레임목록!$O$2:$O$2000,0))="","",INDEX(클레임목록!$J$2:$J$2000,MATCH($B36,클레임목록!$O$2:$O$2000,0))))
