Workbook

Sheet 요약
A1: 따사로운 회계부 — 요약
A2: 사업자가 둘이므로 회계부도 둘입니다. 이 시트는 두 사업자의 숫자를 나란히 보여줄 뿐, 입력은 각 사업자의 ① 거래입력에서만 합니다. 여기 숫자는 손으로 고치지 마십시오.
A4: 구분 | B4: 따사로운 통합서비스 | C4: 따사로운 평생교육원 | D4: 두 사업자 합계 (참고) | G4: 이 파일의 구조
A5: 이번 달 수입 | B5: ='통합 ① 거래입력'!B4 -> 5120000 | C5: ='교육원 ① 거래입력'!B4 -> 1260000 | D5: =B5+C5 -> 6380000 | G5: ■ 파란 탭 = 따사로운 통합서비스 (바우처통장 · 경비통장 · 카드)
A6: 이번 달 지출 | B6: ='통합 ① 거래입력'!B5 -> 4278000 | C6: ='교육원 ① 거래입력'!B5 -> 872400 | D6: =B6+C6 -> 5150400 | G6: ■ 주황 탭 = 따사로운 평생교육원 (교육원통장 하나)
A7: 이번 달 차액 | B7: ='통합 ① 거래입력'!B6 -> 842000 | C7: ='교육원 ① 거래입력'!B6 -> 387600 | D7: =B7+C7 -> 1229600 | G7: 각 사업자마다 ① 거래입력 → ② 월별결산 → ③ 통장·카드 → ④ 설정, 4장씩입니다.
A8: 누적 수입 | B8: ='통합 ① 거래입력'!B7 -> 5120000 | C8: ='교육원 ① 거래입력'!B7 -> 1260000 | D8: =B8+C8 -> 6380000
A9: 누적 지출 | B9: ='통합 ① 거래입력'!B8 -> 4278000 | C9: ='교육원 ① 거래입력'!B8 -> 872400 | D9: =B9+C9 -> 5150400 | G9: 지켜야 할 규칙 하나
A10: 누적 차액 | B10: =B8-B9 -> 842000 | C10: =C8-C9 -> 387600 | D10: =D8-D9 -> 1229600 | G10: 돈이 어느 사업자 통장·카드에서 오갔는지가 기준입니다. 통합서비스 통장이면 통합 시트, 교육원통장이면 교육원 시트. 「공통」은 없습니다.
A11: 손볼 줄 (점검) | B11: ='통합 ① 거래입력'!E4 -> 0 | C11: ='교육원 ① 거래입력'!E4 -> 0 | D11: =B11+C11 -> 0 | G11: 함께 쓰는 비용(임차료·공과금 등)은 실제로 낸 사업자가 지출로 적고, 상대가 분담분을 보내면 「타사업자 정산수입 / 정산지출」로 양쪽에 적습니다.
A12: 증빙 없음 | B12: ='통합 ① 거래입력'!E5 -> 0 | C12: ='교육원 ① 거래입력'!E5 -> 1 | D12: =B12+C12 -> 1 | G12: 사업자 사이 송금은 반드시 증빙(계산서 또는 이체확인증)을 남기십시오. 세무사에게 넘길 때 두 사업자를 따로 뽑을 수 있습니다.
A13: ※ 이번 달 = 오늘 날짜의 달. 수입·지출은 「계좌대체」를 뺀 손익 기준. 「타사업자 정산」은 한쪽 수입·한쪽 지출이라 합계 열에서는 서로 지워집니다.
A15: 통장·카드 잔액
A16: 사업자 | B16: 결제수단 | C16: 구분 | D16: 현재 잔액 / 카드 사용액
A17: =IF('통합 ③ 통장·카드'!$A5="","","통합") -> 통합 | B17: =IF('통합 ③ 통장·카드'!$A5="","",'통합 ③ 통장·카드'!$A5) -> 바우처통장 | C17: =IF('통합 ③ 통장·카드'!$A5="","",'통합 ③ 통장·카드'!$B5) -> 통장 | D17: =IF('통합 ③ 통장·카드'!$A5="","",'통합 ③ 통장·카드'!$G5) -> 1820000
A18: =IF('통합 ③ 통장·카드'!$A6="","","통합") -> 통합 | B18: =IF('통합 ③ 통장·카드'!$A6="","",'통합 ③ 통장·카드'!$A6) -> 경비통장 | C18: =IF('통합 ③ 통장·카드'!$A6="","",'통합 ③ 통장·카드'!$B6) -> 통장 | D18: =IF('통합 ③ 통장·카드'!$A6="","",'통합 ③ 통장·카드'!$G6) -> 190000
A19: =IF('통합 ③ 통장·카드'!$A7="","","통합") -> 통합 | B19: =IF('통합 ③ 통장·카드'!$A7="","",'통합 ③ 통장·카드'!$A7) -> 삼성카드 | C19: =IF('통합 ③ 통장·카드'!$A7="","",'통합 ③ 통장·카드'!$B7) -> 카드 | D19: =IF('통합 ③ 통장·카드'!$A7="","",'통합 ③ 통장·카드'!$G7) -> 850000
A20: =IF('통합 ③ 통장·카드'!$A8="","","통합") -> 통합 | B20: =IF('통합 ③ 통장·카드'!$A8="","",'통합 ③ 통장·카드'!$A8) -> BC카드 | C20: =IF('통합 ③ 통장·카드'!$A8="","",'통합 ③ 통장·카드'!$B8) -> 카드 | D20: =IF('통합 ③ 통장·카드'!$A8="","",'통합 ③ 통장·카드'!$G8) -> 318000
A21: =IF('통합 ③ 통장·카드'!$A9="","","통합") -> 통합 | B21: =IF('통합 ③ 통장·카드'!$A9="","",'통합 ③ 통장·카드'!$A9) -> 현금 | C21: =IF('통합 ③ 통장·카드'!$A9="","",'통합 ③ 통장·카드'!$B9) -> 현금 | D21: =IF('통합 ③ 통장·카드'!$A9="","",'통합 ③ 통장·카드'!$G9) -> 0
A22: =IF('통합 ③ 통장·카드'!$A10="","","통합") | B22: =IF('통합 ③ 통장·카드'!$A10="","",'통합 ③ 통장·카드'!$A10) | C22: =IF('통합 ③ 통장·카드'!$A10="","",'통합 ③ 통장·카드'!$B10) | D22: =IF('통합 ③ 통장·카드'!$A10="","",'통합 ③ 통장·카드'!$G10)
A23: =IF('통합 ③ 통장·카드'!$A11="","","통합") | B23: =IF('통합 ③ 통장·카드'!$A11="","",'통합 ③ 통장·카드'!$A11) | C23: =IF('통합 ③ 통장·카드'!$A11="","",'통합 ③ 통장·카드'!$B11) | D23: =IF('통합 ③ 통장·카드'!$A11="","",'통합 ③ 통장·카드'!$G11)
B24: 통합 통장 합계 | D24: ='통합 ③ 통장·카드'!$G$12 -> 2010000
A25: =IF('교육원 ③ 통장·카드'!$A5="","","교육원") -> 교육원 | B25: =IF('교육원 ③ 통장·카드'!$A5="","",'교육원 ③ 통장·카드'!$A5) -> 교육원통장 | C25: =IF('교육원 ③ 통장·카드'!$A5="","",'교육원 ③ 통장·카드'!$B5) -> 통장 | D25: =IF('교육원 ③ 통장·카드'!$A5="","",'교육원 ③ 통장·카드'!$G5) -> 350000
A26: =IF('교육원 ③ 통장·카드'!$A6="","","교육원") -> 교육원 | B26: =IF('교육원 ③ 통장·카드'!$A6="","",'교육원 ③ 통장·카드'!$A6) -> 현금 | C26: =IF('교육원 ③ 통장·카드'!$A6="","",'교육원 ③ 통장·카드'!$B6) -> 현금 | D26: =IF('교육원 ③ 통장·카드'!$A6="","",'교육원 ③ 통장·카드'!$G6) -> 37600
A27: =IF('교육원 ③ 통장·카드'!$A7="","","교육원") | B27: =IF('교육원 ③ 통장·카드'!$A7="","",'교육원 ③ 통장·카드'!$A7) | C27: =IF('교육원 ③ 통장·카드'!$A7="","",'교육원 ③ 통장·카드'!$B7) | D27: =IF('교육원 ③ 통장·카드'!$A7="","",'교육원 ③ 통장·카드'!$G7)
A28: =IF('교육원 ③ 통장·카드'!$A8="","","교육원") | B28: =IF('교육원 ③ 통장·카드'!$A8="","",'교육원 ③ 통장·카드'!$A8) | C28: =IF('교육원 ③ 통장·카드'!$A8="","",'교육원 ③ 통장·카드'!$B8) | D28: =IF('교육원 ③ 통장·카드'!$A8="","",'교육원 ③ 통장·카드'!$G8)
A29: =IF('교육원 ③ 통장·카드'!$A9="","","교육원") | B29: =IF('교육원 ③ 통장·카드'!$A9="","",'교육원 ③ 통장·카드'!$A9) | C29: =IF('교육원 ③ 통장·카드'!$A9="","",'교육원 ③ 통장·카드'!$B9) | D29: =IF('교육원 ③ 통장·카드'!$A9="","",'교육원 ③ 통장·카드'!$G9)
A30: =IF('교육원 ③ 통장·카드'!$A10="","","교육원") | B30: =IF('교육원 ③ 통장·카드'!$A10="","",'교육원 ③ 통장·카드'!$A10) | C30: =IF('교육원 ③ 통장·카드'!$A10="","",'교육원 ③ 통장·카드'!$B10) | D30: =IF('교육원 ③ 통장·카드'!$A10="","",'교육원 ③ 통장·카드'!$G10)
A31: =IF('교육원 ③ 통장·카드'!$A11="","","교육원") | B31: =IF('교육원 ③ 통장·카드'!$A11="","",'교육원 ③ 통장·카드'!$A11) | C31: =IF('교육원 ③ 통장·카드'!$A11="","",'교육원 ③ 통장·카드'!$B11) | D31: =IF('교육원 ③ 통장·카드'!$A11="","",'교육원 ③ 통장·카드'!$G11)
B32: 교육원 통장 합계 | D32: ='교육원 ③ 통장·카드'!$G$12 -> 350000
A35: 월별 손익 (연도는 각 사업자 ② 월별결산의 G1 칸을 따릅니다)
A36: 사업자 | B36: 항목 | C36: 1월 | D36: 2월 | E36: 3월 | F36: 4월 | G36: 5월 | H36: 6월 | I36: 7월 | J36: 8월 | K36: 9월 | L36: 10월 | M36: 11월 | N36: 12월 | O36: 연간 합계
A37: 통합 | B37: 총수입 | C37: ='통합 ② 월별결산'!C44 -> 0 | D37: ='통합 ② 월별결산'!D44 -> 0 | E37: ='통합 ② 월별결산'!E44 -> 0 | F37: ='통합 ② 월별결산'!F44 -> 0 | G37: ='통합 ② 월별결산'!G44 -> 0 | H37: ='통합 ② 월별결산'!H44 -> 0 | I37: ='통합 ② 월별결산'!I44 -> 0 | J37: ='통합 ② 월별결산'!J44 -> 0 | ... O37: ='통합 ② 월별결산'!O44 -> 5120000
B38: 총지출 | C38: ='통합 ② 월별결산'!C45 -> 0 | D38: ='통합 ② 월별결산'!D45 -> 0 | E38: ='통합 ② 월별결산'!E45 -> 0 | F38: ='통합 ② 월별결산'!F45 -> 0 | G38: ='통합 ② 월별결산'!G45 -> 0 | H38: ='통합 ② 월별결산'!H45 -> 0 | I38: ='통합 ② 월별결산'!I45 -> 0 | J38: ='통합 ② 월별결산'!J45 -> 0 | ... O38: ='통합 ② 월별결산'!O45 -> 4278000
B39: 영업이익 | C39: ='통합 ② 월별결산'!C46 -> 0 | D39: ='통합 ② 월별결산'!D46 -> 0 | E39: ='통합 ② 월별결산'!E46 -> 0 | F39: ='통합 ② 월별결산'!F46 -> 0 | G39: ='통합 ② 월별결산'!G46 -> 0 | H39: ='통합 ② 월별결산'!H46 -> 0 | I39: ='통합 ② 월별결산'!I46 -> 0 | J39: ='통합 ② 월별결산'!J46 -> 0 | ... O39: ='통합 ② 월별결산'!O46 -> 842000
A40: 교육원 | B40: 총수입 | C40: ='교육원 ② 월별결산'!C41 -> 0 | D40: ='교육원 ② 월별결산'!D41 -> 0 | E40: ='교육원 ② 월별결산'!E41 -> 0 | F40: ='교육원 ② 월별결산'!F41 -> 0 | G40: ='교육원 ② 월별결산'!G41 -> 0 | H40: ='교육원 ② 월별결산'!H41 -> 0 | I40: ='교육원 ② 월별결산'!I41 -> 0 | J40: ='교육원 ② 월별결산'!J41 -> 0 | ... O40: ='교육원 ② 월별결산'!O41 -> 1260000
B41: 총지출 | C41: ='교육원 ② 월별결산'!C42 -> 0 | D41: ='교육원 ② 월별결산'!D42 -> 0 | E41: ='교육원 ② 월별결산'!E42 -> 0 | F41: ='교육원 ② 월별결산'!F42 -> 0 | G41: ='교육원 ② 월별결산'!G42 -> 0 | H41: ='교육원 ② 월별결산'!H42 -> 0 | I41: ='교육원 ② 월별결산'!I42 -> 0 | J41: ='교육원 ② 월별결산'!J42 -> 0 | ... O41: ='교육원 ② 월별결산'!O42 -> 872400
B42: 영업이익 | C42: ='교육원 ② 월별결산'!C43 -> 0 | D42: ='교육원 ② 월별결산'!D43 -> 0 | E42: ='교육원 ② 월별결산'!E43 -> 0 | F42: ='교육원 ② 월별결산'!F43 -> 0 | G42: ='교육원 ② 월별결산'!G43 -> 0 | H42: ='교육원 ② 월별결산'!H43 -> 0 | I42: ='교육원 ② 월별결산'!I43 -> 0 | J42: ='교육원 ② 월별결산'!J43 -> 0 | ... O42: ='교육원 ② 월별결산'!O43 -> 387600
A43: 합계 | B43: 영업이익 (참고) | C43: =C39+C42 -> 0 | D43: =D39+D42 -> 0 | E43: =E39+E42 -> 0 | F43: =F39+F42 -> 0 | G43: =G39+G42 -> 0 | H43: =H39+H42 -> 0 | I43: =I39+I42 -> 0 | J43: =J39+J42 -> 0 | ... O43: =O39+O42 -> 1229600
A44: ※ 「합계」는 대표가 전체를 볼 때만 참고하십시오. 세무·결산은 사업자별 ② 월별결산으로 각각 합니다.

Sheet 통합 ① 거래입력
A1: 따사로운 통합서비스 회계부 | G1: 통합 ① 거래입력 — 따사로운 통합서비스 통장·카드로 오간 돈만 이 시트에 적습니다. ②③은 자동으로 계산됩니다.
A3: 이번 달 | B3: =TEXT(TODAY(),"yyyy년 m월") -> 2026년 9월 | D3: 점검 | G3: 쓰는 법
A4: 수입 | B4: =SUMIFS($I$15:$I$2014,$O$15:$O$2014,YEAR(TODAY())*100+MONTH(TODAY()),$P$15:$P$2014,1) -> 5120000 | D4: 손볼 줄 | E4: =COUNTIF($L$15:$L$2014,"?*") -> 0 | G4: 1. 따사로운 통합서비스 명의 통장·카드 내역을 내려받아 날짜·거래처·금액을 아래 표에 붙여 넣습니다. 한 줄이 한 거래입니다.
A5: 지출 | B5: =SUMIFS($J$15:$J$2014,$O$15:$O$2014,YEAR(TODAY())*100+MONTH(TODAY()),$P$15:$P$2014,1) -> 4278000 | D5: 증빙 없음 | E5: =COUNTIF($K$15:$K$2014,"없음") -> 0 | G5: 2. 결제수단·계정과목·증빙은 칸을 누르면 목록이 뜹니다. 목록에서 고르십시오 (직접 타이핑하면 ② 결산에서 빠집니다).
A6: 차액 | B6: =B4-B5 -> 842000 | D6: 바우처통장 지출 | E6: =SUMIF($C$15:$C$2014,"바우처통장",$J$15:$J$2014) -> 3000000 | G6: 3. 대분류·고정/변동은 계정과목을 고르면 저절로 채워집니다. 손대지 마십시오.
A7: 누적 수입 | B7: =SUMIF($P$15:$P$2014,1,$I$15:$I$2014) -> 5120000 | G7: 4. 수입이면 수입 칸에, 지출이면 지출 칸에만 금액을 적습니다. 둘 다 적지 않습니다.
A8: 누적 지출 | B8: =SUMIF($P$15:$P$2014,1,$J$15:$J$2014) -> 4278000 | G8: 5. 통장 사이 이체는 계정과목을 「계좌대체」로 하고 두 줄로 적습니다 — 나가는 통장에 지출, 들어오는 통장에 수입. 손익에는 잡히지 않습니다.
A9: 입력 줄수 | B9: =COUNT($B$15:$B$2014) -> 9 | G9: 6. 다른 사업자와 돈이 오가면(임차료 분담 등) 「계좌대체」가 아니라 「타사업자 정산수입/정산지출」로 적고, 상대 사업자 시트에도 같은 금액을 반대로 적습니다.
A10: ※ 수입·지출·누적은 「계좌대체」를 뺀 손익 기준입니다. | G10: 7. 「점검」 칸에 글자가 뜨면 그 줄에 빠진 것이 있다는 뜻입니다. 비어 있어야 정상입니다.
G12: ※ 15행부터 9줄은 형태를 보여드리는 예시입니다. 실제 내역을 넣기 전에 지우십시오.
A14: 번호 | B14: 날짜 | C14: 결제수단 | D14: 계정과목 | E14: 대분류 | F14: 고정/변동 | G14: 거래처 | H14: 적요 (무엇에 썼는지) | I14: 수입 | J14: 지출 | K14: 증빙 | L14: 점검 | M14: 비고 | O14: 년월 | P14: 손익
A15: =IF($B15="","",COUNT($B$15:$B15)) -> 1 | B15: 46266 | C15: 바우처통장 | D15: 바우처수입-산모신생아 | E15: =IF($D15="","",IFERROR(INDEX('통합 ④ 설정'!$A$6:$A$40,MATCH($D15,'통합 ④ 설정'!$B$6:$B$40,0)),"※없는 과목")) -> 수입 | F15: =IF($D15="","",IFERROR(INDEX('통합 ④ 설정'!$C$6:$C$40,MATCH($D15,'통합 ④ 설정'!$B$6:$B$40,0)),"")) -> 0 | G15: 사회보장정보원 | H15: 8월분 바우처 정산 입금 | I15: 4820000 | K15: 이체확인증 | L15: =IF($B15="","",IF(AND(N($I15)=0,N($J15)=0),"금액이 없습니다",IF(AND($I15>0,$J15>0),"수입·지출 둘 다 적혔습니다",IF($C15="","결제수단을 고르십시오",IF(ISNA(MATCH($C15,'통합 ③ 통장·카드'!$A$5:$A$11,0)),"③ 통장·카드에 없는 결제수단입니다",IF($D15="","계정과목을 고르십시오",IF($E15="※없는 과목","④ 설정에 없는 과목입니다",IF(AND($E15="수입",$J15>0),"수입 과목인데 지출에 적혔습니다",IF(AND(LEFT($E15,2)<>"수입",$E15<>"대체",$I15>0),"지출 과목인데 수입에 적혔습니다",IF($K15="","증빙을 고르십시오",IF(AND($C15="바우처통장",$J15>0,IFERROR(INDEX('통합 ④ 설정'!$E$6:$E$40,MATCH($D15,'통합 ④ 설정'!$B$6:$B$40,0)),"")<>"○"),"바우처통장 지출 — 목적 확인",IF($H15="","적요를 적으십시오","")))))))))))) | O15: =IF($B15="","",YEAR($B15)*100+MONTH($B15)) -> 202609 | P15: =IF($B15="","",IF($E15="대체",0,1)) -> 1
A16: =IF($B16="","",COUNT($B$15:$B16)) -> 2 | B16: 46266 | C16: 경비통장 | D16: 계좌대체 | E16: =IF($D16="","",IFERROR(INDEX('통합 ④ 설정'!$A$6:$A$40,MATCH($D16,'통합 ④ 설정'!$B$6:$B$40,0)),"※없는 과목")) -> 대체 | F16: =IF($D16="","",IFERROR(INDEX('통합 ④ 설정'!$C$6:$C$40,MATCH($D16,'통합 ④ 설정'!$B$6:$B$40,0)),"")) -> 0 | G16: 자행이체 | H16: 바우처통장 → 경비통장 운영비 이체 | I16: 3000000 | K16: 이체확인증 | L16: =IF($B16="","",IF(AND(N($I16)=0,N($J16)=0),"금액이 없습니다",IF(AND($I16>0,$J16>0),"수입·지출 둘 다 적혔습니다",IF($C16="","결제수단을 고르십시오",IF(ISNA(MATCH($C16,'통합 ③ 통장·카드'!$A$5:$A$11,0)),"③ 통장·카드에 없는 결제수단입니다",IF($D16="","계정과목을 고르십시오",IF($E16="※없는 과목","④ 설정에 없는 과목입니다",IF(AND($E16="수입",$J16>0),"수입 과목인데 지출에 적혔습니다",IF(AND(LEFT($E16,2)<>"수입",$E16<>"대체",$I16>0),"지출 과목인데 수입에 적혔습니다",IF($K16="","증빙을 고르십시오",IF(AND($C16="바우처통장",$J16>0,IFERROR(INDEX('통합 ④ 설정'!$E$6:$E$40,MATCH($D16,'통합 ④ 설정'!$B$6:$B$40,0)),"")<>"○"),"바우처통장 지출 — 목적 확인",IF($H16="","적요를 적으십시오","")))))))))))) | O16: =IF($B16="","",YEAR($B16)*100+MONTH($B16)) -> 202609 | P16: =IF($B16="","",IF($E16="대체",0,1)) -> 0
A17: =IF($B17="","",COUNT($B$15:$B17)) -> 3 | B17: 46266 | C17: 바우처통장 | D17: 계좌대체 | E17: =IF($D17="","",IFERROR(INDEX('통합 ④ 설정'!$A$6:$A$40,MATCH($D17,'통합 ④ 설정'!$B$6:$B$40,0)),"※없는 과목")) -> 대체 | F17: =IF($D17="","",IFERROR(INDEX('통합 ④ 설정'!$C$6:$C$40,MATCH($D17,'통합 ④ 설정'!$B$6:$B$40,0)),"")) -> 0 | G17: 자행이체 | H17: 바우처통장 → 경비통장 운영비 이체 | J17: 3000000 | K17: 이체확인증 | L17: =IF($B17="","",IF(AND(N($I17)=0,N($J17)=0),"금액이 없습니다",IF(AND($I17>0,$J17>0),"수입·지출 둘 다 적혔습니다",IF($C17="","결제수단을 고르십시오",IF(ISNA(MATCH($C17,'통합 ③ 통장·카드'!$A$5:$A$11,0)),"③ 통장·카드에 없는 결제수단입니다",IF($D17="","계정과목을 고르십시오",IF($E17="※없는 과목","④ 설정에 없는 과목입니다",IF(AND($E17="수입",$J17>0),"수입 과목인데 지출에 적혔습니다",IF(AND(LEFT($E17,2)<>"수입",$E17<>"대체",$I17>0),"지출 과목인데 수입에 적혔습니다",IF($K17="","증빙을 고르십시오",IF(AND($C17="바우처통장",$J17>0,IFERROR(INDEX('통합 ④ 설정'!$E$6:$E$40,MATCH($D17,'통합 ④ 설정'!$B$6:$B$40,0)),"")<>"○"),"바우처통장 지출 — 목적 확인",IF($H17="","적요를 적으십시오","")))))))))))) | O17: =IF($B17="","",YEAR($B17)*100+MONTH($B17)) -> 202609 | P17: =IF($B17="","",IF($E17="대체",0,1)) -> 0
A18: =IF($B18="","",COUNT($B$15:$B18)) -> 4 | B18: 46267 | C18: 경비통장 | D18: 용역비(관리사) | E18: =IF($D18="","",IFERROR(INDEX('통합 ④ 설정'!$A$6:$A$40,MATCH($D18,'통합 ④ 설정'!$B$6:$B$40,0)),"※없는 과목")) -> 고정지출 | F18: =IF($D18="","",IFERROR(INDEX('통합 ④ 설정'!$C$6:$C$40,MATCH($D18,'통합 ④ 설정'!$B$6:$B$40,0)),"")) -> 고정 | G18: 관리사 8명 | H18: 8월분 용역비 (3.3% 원천징수 후) | J18: 2610000 | K18: 이체확인증 | L18: =IF($B18="","",IF(AND(N($I18)=0,N($J18)=0),"금액이 없습니다",IF(AND($I18>0,$J18>0),"수입·지출 둘 다 적혔습니다",IF($C18="","결제수단을 고르십시오",IF(ISNA(MATCH($C18,'통합 ③ 통장·카드'!$A$5:$A$11,0)),"③ 통장·카드에 없는 결제수단입니다",IF($D18="","계정과목을 고르십시오",IF($E18="※없는 과목","④ 설정에 없는 과목입니다",IF(AND($E18="수입",$J18>0),"수입 과목인데 지출에 적혔습니다",IF(AND(LEFT($E18,2)<>"수입",$E18<>"대체",$I18>0),"지출 과목인데 수입에 적혔습니다",IF($K18="","증빙을 고르십시오",IF(AND($C18="바우처통장",$J18>0,IFERROR(INDEX('통합 ④ 설정'!$E$6:$E$40,MATCH($D18,'통합 ④ 설정'!$B$6:$B$40,0)),"")<>"○"),"바우처통장 지출 — 목적 확인",IF($H18="","적요를 적으십시오","")))))))))))) | O18: =IF($B18="","",YEAR($B18)*100+MONTH($B18)) -> 202609 | P18: =IF($B18="","",IF($E18="대체",0,1)) -> 1
A19: =IF($B19="","",COUNT($B$15:$B19)) -> 5 | B19: 46269 | C19: 삼성카드 | D19: 임차료 | E19: =IF($D19="","",IFERROR(INDEX('통합 ④ 설정'!$A$6:$A$40,MATCH($D19,'통합 ④ 설정'!$B$6:$B$40,0)),"※없는 과목")) -> 고정지출 | F19: =IF($D19="","",IFERROR(INDEX('통합 ④ 설정'!$C$6:$C$40,MATCH($D19,'통합 ④ 설정'!$B$6:$B$40,0)),"")) -> 고정 | G19: ○○빌딩 | H19: 9월 사무실 임차료 | J19: 850000 | K19: 세금계산서 | L19: =IF($B19="","",IF(AND(N($I19)=0,N($J19)=0),"금액이 없습니다",IF(AND($I19>0,$J19>0),"수입·지출 둘 다 적혔습니다",IF($C19="","결제수단을 고르십시오",IF(ISNA(MATCH($C19,'통합 ③ 통장·카드'!$A$5:$A$11,0)),"③ 통장·카드에 없는 결제수단입니다",IF($D19="","계정과목을 고르십시오",IF($E19="※없는 과목","④ 설정에 없는 과목입니다",IF(AND($E19="수입",$J19>0),"수입 과목인데 지출에 적혔습니다",IF(AND(LEFT($E19,2)<>"수입",$E19<>"대체",$I19>0),"지출 과목인데 수입에 적혔습니다",IF($K19="","증빙을 고르십시오",IF(AND($C19="바우처통장",$J19>0,IFERROR(INDEX('통합 ④ 설정'!$E$6:$E$40,MATCH($D19,'통합 ④ 설정'!$B$6:$B$40,0)),"")<>"○"),"바우처통장 지출 — 목적 확인",IF($H19="","적요를 적으십시오","")))))))))))) | O19: =IF($B19="","",YEAR($B19)*100+MONTH($B19)) -> 202609 | P19: =IF($B19="","",IF($E19="대체",0,1)) -> 1
A20: =IF($B20="","",COUNT($B$15:$B20)) -> 6 | B20: 46270 | C20: BC카드 | D20: 물품구입비 | E20: =IF($D20="","",IFERROR(INDEX('통합 ④ 설정'!$A$6:$A$40,MATCH($D20,'통합 ④ 설정'!$B$6:$B$40,0)),"※없는 과목")) -> 변동지출 | F20: =IF($D20="","",IFERROR(INDEX('통합 ④ 설정'!$C$6:$C$40,MATCH($D20,'통합 ④ 설정'!$B$6:$B$40,0)),"")) -> 변동 | G20: ○○유통 | H20: 수건·세제·기저귀 보충 | J20: 318000 | K20: 카드전표 | L20: =IF($B20="","",IF(AND(N($I20)=0,N($J20)=0),"금액이 없습니다",IF(AND($I20>0,$J20>0),"수입·지출 둘 다 적혔습니다",IF($C20="","결제수단을 고르십시오",IF(ISNA(MATCH($C20,'통합 ③ 통장·카드'!$A$5:$A$11,0)),"③ 통장·카드에 없는 결제수단입니다",IF($D20="","계정과목을 고르십시오",IF($E20="※없는 과목","④ 설정에 없는 과목입니다",IF(AND($E20="수입",$J20>0),"수입 과목인데 지출에 적혔습니다",IF(AND(LEFT($E20,2)<>"수입",$E20<>"대체",$I20>0),"지출 과목인데 수입에 적혔습니다",IF($K20="","증빙을 고르십시오",IF(AND($C20="바우처통장",$J20>0,IFERROR(INDEX('통합 ④ 설정'!$E$6:$E$40,MATCH($D20,'통합 ④ 설정'!$B$6:$B$40,0)),"")<>"○"),"바우처통장 지출 — 목적 확인",IF($H20="","적요를 적으십시오","")))))))))))) | O20: =IF($B20="","",YEAR($B20)*100+MONTH($B20)) -> 202609 | P20: =IF($B20="","",IF($E20="대체",0,1)) -> 1
A21: =IF($B21="","",COUNT($B$15:$B21)) -> 7 | B21: 46270 | C21: 경비통장 | D21: 4대보험 사업주부담 | E21: =IF($D21="","",IFERROR(INDEX('통합 ④ 설정'!$A$6:$A$40,MATCH($D21,'통합 ④ 설정'!$B$6:$B$40,0)),"※없는 과목")) -> 고정지출 | F21: =IF($D21="","",IFERROR(INDEX('통합 ④ 설정'!$C$6:$C$40,MATCH($D21,'통합 ④ 설정'!$B$6:$B$40,0)),"")) -> 고정 | G21: 건강보험공단 | H21: 8월분 사업주부담금 | J21: 412000 | K21: 이체확인증 | L21: =IF($B21="","",IF(AND(N($I21)=0,N($J21)=0),"금액이 없습니다",IF(AND($I21>0,$J21>0),"수입·지출 둘 다 적혔습니다",IF($C21="","결제수단을 고르십시오",IF(ISNA(MATCH($C21,'통합 ③ 통장·카드'!$A$5:$A$11,0)),"③ 통장·카드에 없는 결제수단입니다",IF($D21="","계정과목을 고르십시오",IF($E21="※없는 과목","④ 설정에 없는 과목입니다",IF(AND($E21="수입",$J21>0),"수입 과목인데 지출에 적혔습니다",IF(AND(LEFT($E21,2)<>"수입",$E21<>"대체",$I21>0),"지출 과목인데 수입에 적혔습니다",IF($K21="","증빙을 고르십시오",IF(AND($C21="바우처통장",$J21>0,IFERROR(INDEX('통합 ④ 설정'!$E$6:$E$40,MATCH($D21,'통합 ④ 설정'!$B$6:$B$40,0)),"")<>"○"),"바우처통장 지출 — 목적 확인",IF($H21="","적요를 적으십시오","")))))))))))) | O21: =IF($B21="","",YEAR($B21)*100+MONTH($B21)) -> 202609 | P21: =IF($B21="","",IF($E21="대체",0,1)) -> 1
A22: =IF($B22="","",COUNT($B$15:$B22)) -> 8 | B22: 46275 | C22: 경비통장 | D22: 통신비 | E22: =IF($D22="","",IFERROR(INDEX('통합 ④ 설정'!$A$6:$A$40,MATCH($D22,'통합 ④ 설정'!$B$6:$B$40,0)),"※없는 과목")) -> 고정지출 | F22: =IF($D22="","",IFERROR(INDEX('통합 ④ 설정'!$C$6:$C$40,MATCH($D22,'통합 ④ 설정'!$B$6:$B$40,0)),"")) -> 고정 | G22: KT | H22: 9월 인터넷·전화 | J22: 88000 | K22: 세금계산서 | L22: =IF($B22="","",IF(AND(N($I22)=0,N($J22)=0),"금액이 없습니다",IF(AND($I22>0,$J22>0),"수입·지출 둘 다 적혔습니다",IF($C22="","결제수단을 고르십시오",IF(ISNA(MATCH($C22,'통합 ③ 통장·카드'!$A$5:$A$11,0)),"③ 통장·카드에 없는 결제수단입니다",IF($D22="","계정과목을 고르십시오",IF($E22="※없는 과목","④ 설정에 없는 과목입니다",IF(AND($E22="수입",$J22>0),"수입 과목인데 지출에 적혔습니다",IF(AND(LEFT($E22,2)<>"수입",$E22<>"대체",$I22>0),"지출 과목인데 수입에 적혔습니다",IF($K22="","증빙을 고르십시오",IF(AND($C22="바우처통장",$J22>0,IFERROR(INDEX('통합 ④ 설정'!$E$6:$E$40,MATCH($D22,'통합 ④ 설정'!$B$6:$B$40,0)),"")<>"○"),"바우처통장 지출 — 목적 확인",IF($H22="","적요를 적으십시오","")))))))))))) | O22: =IF($B22="","",YEAR($B22)*100+MONTH($B22)) -> 202609 | P22: =IF($B22="","",IF($E22="대체",0,1)) -> 1
A23: =IF($B23="","",COUNT($B$15:$B23)) -> 9 | B23: 46280 | C23: 경비통장 | D23: 타사업자 정산수입 | E23: =IF($D23="","",IFERROR(INDEX('통합 ④ 설정'!$A$6:$A$40,MATCH($D23,'통합 ④ 설정'!$B$6:$B$40,0)),"※없는 과목")) -> 수입 | F23: =IF($D23="","",IFERROR(INDEX('통합 ④ 설정'!$C$6:$C$40,MATCH($D23,'통합 ④ 설정'!$B$6:$B$40,0)),"")) -> 0 | G23: 따사로운 평생교육원 | H23: 9월 교육장 임차료 분담분 입금 | I23: 300000 | K23: 이체확인증 | L23: =IF($B23="","",IF(AND(N($I23)=0,N($J23)=0),"금액이 없습니다",IF(AND($I23>0,$J23>0),"수입·지출 둘 다 적혔습니다",IF($C23="","결제수단을 고르십시오",IF(ISNA(MATCH($C23,'통합 ③ 통장·카드'!$A$5:$A$11,0)),"③ 통장·카드에 없는 결제수단입니다",IF($D23="","계정과목을 고르십시오",IF($E23="※없는 과목","④ 설정에 없는 과목입니다",IF(AND($E23="수입",$J23>0),"수입 과목인데 지출에 적혔습니다",IF(AND(LEFT($E23,2)<>"수입",$E23<>"대체",$I23>0),"지출 과목인데 수입에 적혔습니다",IF($K23="","증빙을 고르십시오",IF(AND($C23="바우처통장",$J23>0,IFERROR(INDEX('통합 ④ 설정'!$E$6:$E$40,MATCH($D23,'통합 ④ 설정'!$B$6:$B$40,0)),"")<>"○"),"바우처통장 지출 — 목적 확인",IF($H23="","적요를 적으십시오","")))))))))))) | M23: 교육원 시트에는 「타사업자 정산지출」로 적혀 있습니다 | O23: =IF($B23="","",YEAR($B23)*100+MONTH($B23)) -> 202609 | P23: =IF($B23="","",IF($E23="대체",0,1)) -> 1
A24: =IF($B24="","",COUNT($B$15:$B24)) | E24: =IF($D24="","",IFERROR(INDEX('통합 ④ 설정'!$A$6:$A$40,MATCH($D24,'통합 ④ 설정'!$B$6:$B$40,0)),"※없는 과목")) | F24: =IF($D24="","",IFERROR(INDEX('통합 ④ 설정'!$C$6:$C$40,MATCH($D24,'통합 ④ 설정'!$B$6:$B$40,0)),"")) | L24: =IF($B24="","",IF(AND(N($I24)=0,N($J24)=0),"금액이 없습니다",IF(AND($I24>0,$J24>0),"수입·지출 둘 다 적혔습니다",IF($C24="","결제수단을 고르십시오",IF(ISNA(MATCH($C24,'통합 ③ 통장·카드'!$A$5:$A$11,0)),"③ 통장·카드에 없는 결제수단입니다",IF($D24="","계정과목을 고르십시오",IF($E24="※없는 과목","④ 설정에 없는 과목입니다",IF(AND($E24="수입",$J24>0),"수입 과목인데 지출에 적혔습니다",IF(AND(LEFT($E24,2)<>"수입",$E24<>"대체",$I24>0),"지출 과목인데 수입에 적혔습니다",IF($K24="","증빙을 고르십시오",IF(AND($C24="바우처통장",$J24>0,IFERROR(INDEX('통합 ④ 설정'!$E$6:$E$40,MATCH($D24,'통합 ④ 설정'!$B$6:$B$40,0)),"")<>"○"),"바우처통장 지출 — 목적 확인",IF($H24="","적요를 적으십시오","")))))))))))) | O24: =IF($B24="","",YEAR($B24)*100+MONTH($B24)) | P24: =IF($B24="","",IF($E24="대체",0,1))
A25: =IF($B25="","",COUNT($B$15:$B25)) | E25: =IF($D25="","",IFERROR(INDEX('통합 ④ 설정'!$A$6:$A$40,MATCH($D25,'통합 ④ 설정'!$B$6:$B$40,0)),"※없는 과목")) | F25: =IF($D25="","",IFERROR(INDEX('통합 ④ 설정'!$C$6:$C$40,MATCH($D25,'통합 ④ 설정'!$B$6:$B$40,0)),"")) | L25: =IF($B25="","",IF(AND(N($I25)=0,N($J25)=0),"금액이 없습니다",IF(AND($I25>0,$J25>0),"수입·지출 둘 다 적혔습니다",IF($C25="","결제수단을 고르십시오",IF(ISNA(MATCH($C25,'통합 ③ 통장·카드'!$A$5:$A$11,0)),"③ 통장·카드에 없는 결제수단입니다",IF($D25="","계정과목을 고르십시오",IF($E25="※없는 과목","④ 설정에 없는 과목입니다",IF(AND($E25="수입",$J25>0),"수입 과목인데 지출에 적혔습니다",IF(AND(LEFT($E25,2)<>"수입",$E25<>"대체",$I25>0),"지출 과목인데 수입에 적혔습니다",IF($K25="","증빙을 고르십시오",IF(AND($C25="바우처통장",$J25>0,IFERROR(INDEX('통합 ④ 설정'!$E$6:$E$40,MATCH($D25,'통합 ④ 설정'!$B$6:$B$40,0)),"")<>"○"),"바우처통장 지출 — 목적 확인",IF($H25="","적요를 적으십시오","")))))))))))) | O25: =IF($B25="","",YEAR($B25)*100+MONTH($B25)) | P25: =IF($B25="","",IF($E25="대체",0,1))
A26: =IF($B26="","",COUNT($B$15:$B26)) | E26: =IF($D26="","",IFERROR(INDEX('통합 ④ 설정'!$A$6:$A$40,MATCH($D26,'통합 ④ 설정'!$B$6:$B$40,0)),"※없는 과목")) | F26: =IF($D26="","",IFERROR(INDEX('통합 ④ 설정'!$C$6:$C$40,MATCH($D26,'통합 ④ 설정'!$B$6:$B$40,0)),"")) | L26: =IF($B26="","",IF(AND(N($I26)=0,N($J26)=0),"금액이 없습니다",IF(AND($I26>0,$J26>0),"수입·지출 둘 다 적혔습니다",IF($C26="","결제수단을 고르십시오",IF(ISNA(MATCH($C26,'통합 ③ 통장·카드'!$A$5:$A$11,0)),"③ 통장·카드에 없는 결제수단입니다",IF($D26="","계정과목을 고르십시오",IF($E26="※없는 과목","④ 설정에 없는 과목입니다",IF(AND($E26="수입",$J26>0),"수입 과목인데 지출에 적혔습니다",IF(AND(LEFT($E26,2)<>"수입",$E26<>"대체",$I26>0),"지출 과목인데 수입에 적혔습니다",IF($K26="","증빙을 고르십시오",IF(AND($C26="바우처통장",$J26>0,IFERROR(INDEX('통합 ④ 설정'!$E$6:$E$40,MATCH($D26,'통합 ④ 설정'!$B$6:$B$40,0)),"")<>"○"),"바우처통장 지출 — 목적 확인",IF($H26="","적요를 적으십시오","")))))))))))) | O26: =IF($B26="","",YEAR($B26)*100+MONTH($B26)) | P26: =IF($B26="","",IF($E26="대체",0,1))
A27: =IF($B27="","",COUNT($B$15:$B27)) | E27: =IF($D27="","",IFERROR(INDEX('통합 ④ 설정'!$A$6:$A$40,MATCH($D27,'통합 ④ 설정'!$B$6:$B$40,0)),"※없는 과목")) | F27: =IF($D27="","",IFERROR(INDEX('통합 ④ 설정'!$C$6:$C$40,MATCH($D27,'통합 ④ 설정'!$B$6:$B$40,0)),"")) | L27: =IF($B27="","",IF(AND(N($I27)=0,N($J27)=0),"금액이 없습니다",IF(AND($I27>0,$J27>0),"수입·지출 둘 다 적혔습니다",IF($C27="","결제수단을 고르십시오",IF(ISNA(MATCH($C27,'통합 ③ 통장·카드'!$A$5:$A$11,0)),"③ 통장·카드에 없는 결제수단입니다",IF($D27="","계정과목을 고르십시오",IF($E27="※없는 과목","④ 설정에 없는 과목입니다",IF(AND($E27="수입",$J27>0),"수입 과목인데 지출에 적혔습니다",IF(AND(LEFT($E27,2)<>"수입",$E27<>"대체",$I27>0),"지출 과목인데 수입에 적혔습니다",IF($K27="","증빙을 고르십시오",IF(AND($C27="바우처통장",$J27>0,IFERROR(INDEX('통합 ④ 설정'!$E$6:$E$40,MATCH($D27,'통합 ④ 설정'!$B$6:$B$40,0)),"")<>"○"),"바우처통장 지출 — 목적 확인",IF($H27="","적요를 적으십시오","")))))))))))) | O27: =IF($B27="","",YEAR($B27)*100+MONTH($B27)) | P27: =IF($B27="","",IF($E27="대체",0,1))
A28: =IF($B28="","",COUNT($B$15:$B28)) | E28: =IF($D28="","",IFERROR(INDEX('통합 ④ 설정'!$A$6:$A$40,MATCH($D28,'통합 ④ 설정'!$B$6:$B$40,0)),"※없는 과목")) | F28: =IF($D28="","",IFERROR(INDEX('통합 ④ 설정'!$C$6:$C$40,MATCH($D28,'통합 ④ 설정'!$B$6:$B$40,0)),"")) | L28: =IF($B28="","",IF(AND(N($I28)=0,N($J28)=0),"금액이 없습니다",IF(AND($I28>0,$J28>0),"수입·지출 둘 다 적혔습니다",IF($C28="","결제수단을 고르십시오",IF(ISNA(MATCH($C28,'통합 ③ 통장·카드'!$A$5:$A$11,0)),"③ 통장·카드에 없는 결제수단입니다",IF($D28="","계정과목을 고르십시오",IF($E28="※없는 과목","④ 설정에 없는 과목입니다",IF(AND($E28="수입",$J28>0),"수입 과목인데 지출에 적혔습니다",IF(AND(LEFT($E28,2)<>"수입",$E28<>"대체",$I28>0),"지출 과목인데 수입에 적혔습니다",IF($K28="","증빙을 고르십시오",IF(AND($C28="바우처통장",$J28>0,IFERROR(INDEX('통합 ④ 설정'!$E$6:$E$40,MATCH($D28,'통합 ④ 설정'!$B$6:$B$40,0)),"")<>"○"),"바우처통장 지출 — 목적 확인",IF($H28="","적요를 적으십시오","")))))))))))) | O28: =IF($B28="","",YEAR($B28)*100+MONTH($B28)) | P28: =IF($B28="","",IF($E28="대체",0,1))
A29: =IF($B29="","",COUNT($B$15:$B29)) | E29: =IF($D29="","",IFERROR(INDEX('통합 ④ 설정'!$A$6:$A$40,MATCH($D29,'통합 ④ 설정'!$B$6:$B$40,0)),"※없는 과목")) | F29: =IF($D29="","",IFERROR(INDEX('통합 ④ 설정'!$C$6:$C$40,MATCH($D29,'통합 ④ 설정'!$B$6:$B$40,0)),"")) | L29: =IF($B29="","",IF(AND(N($I29)=0,N($J29)=0),"금액이 없습니다",IF(AND($I29>0,$J29>0),"수입·지출 둘 다 적혔습니다",IF($C29="","결제수단을 고르십시오",IF(ISNA(MATCH($C29,'통합 ③ 통장·카드'!$A$5:$A$11,0)),"③ 통장·카드에 없는 결제수단입니다",IF($D29="","계정과목을 고르십시오",IF($E29="※없는 과목","④ 설정에 없는 과목입니다",IF(AND($E29="수입",$J29>0),"수입 과목인데 지출에 적혔습니다",IF(AND(LEFT($E29,2)<>"수입",$E29<>"대체",$I29>0),"지출 과목인데 수입에 적혔습니다",IF($K29="","증빙을 고르십시오",IF(AND($C29="바우처통장",$J29>0,IFERROR(INDEX('통합 ④ 설정'!$E$6:$E$40,MATCH($D29,'통합 ④ 설정'!$B$6:$B$40,0)),"")<>"○"),"바우처통장 지출 — 목적 확인",IF($H29="","적요를 적으십시오","")))))))))))) | O29: =IF($B29="","",YEAR($B29)*100+MONTH($B29)) | P29: =IF($B29="","",IF($E29="대체",0,1))
A30: =IF($B30="","",COUNT($B$15:$B30)) | E30: =IF($D30="","",IFERROR(INDEX('통합 ④ 설정'!$A$6:$A$40,MATCH($D30,'통합 ④ 설정'!$B$6:$B$40,0)),"※없는 과목")) | F30: =IF($D30="","",IFERROR(INDEX('통합 ④ 설정'!$C$6:$C$40,MATCH($D30,'통합 ④ 설정'!$B$6:$B$40,0)),"")) | L30: =IF($B30="","",IF(AND(N($I30)=0,N($J30)=0),"금액이 없습니다",IF(AND($I30>0,$J30>0),"수입·지출 둘 다 적혔습니다",IF($C30="","결제수단을 고르십시오",IF(ISNA(MATCH($C30,'통합 ③ 통장·카드'!$A$5:$A$11,0)),"③ 통장·카드에 없는 결제수단입니다",IF($D30="","계정과목을 고르십시오",IF($E30="※없는 과목","④ 설정에 없는 과목입니다",IF(AND($E30="수입",$J30>0),"수입 과목인데 지출에 적혔습니다",IF(AND(LEFT($E30,2)<>"수입",$E30<>"대체",$I30>0),"지출 과목인데 수입에 적혔습니다",IF($K30="","증빙을 고르십시오",IF(AND($C30="바우처통장",$J30>0,IFERROR(INDEX('통합 ④ 설정'!$E$6:$E$40,MATCH($D30,'통합 ④ 설정'!$B$6:$B$40,0)),"")<>"○"),"바우처통장 지출 — 목적 확인",IF($H30="","적요를 적으십시오","")))))))))))) | O30: =IF($B30="","",YEAR($B30)*100+MONTH($B30)) | P30: =IF($B30="","",IF($E30="대체",0,1))
A31: =IF($B31="","",COUNT($B$15:$B31)) | E31: =IF($D31="","",IFERROR(INDEX('통합 ④ 설정'!$A$6:$A$40,MATCH($D31,'통합 ④ 설정'!$B$6:$B$40,0)),"※없는 과목")) | F31: =IF($D31="","",IFERROR(INDEX('통합 ④ 설정'!$C$6:$C$40,MATCH($D31,'통합 ④ 설정'!$B$6:$B$40,0)),"")) | L31: =IF($B31="","",IF(AND(N($I31)=0,N($J31)=0),"금액이 없습니다",IF(AND($I31>0,$J31>0),"수입·지출 둘 다 적혔습니다",IF($C31="","결제수단을 고르십시오",IF(ISNA(MATCH($C31,'통합 ③ 통장·카드'!$A$5:$A$11,0)),"③ 통장·카드에 없는 결제수단입니다",IF($D31="","계정과목을 고르십시오",IF($E31="※없는 과목","④ 설정에 없는 과목입니다",IF(AND($E31="수입",$J31>0),"수입 과목인데 지출에 적혔습니다",IF(AND(LEFT($E31,2)<>"수입",$E31<>"대체",$I31>0),"지출 과목인데 수입에 적혔습니다",IF($K31="","증빙을 고르십시오",IF(AND($C31="바우처통장",$J31>0,IFERROR(INDEX('통합 ④ 설정'!$E$6:$E$40,MATCH($D31,'통합 ④ 설정'!$B$6:$B$40,0)),"")<>"○"),"바우처통장 지출 — 목적 확인",IF($H31="","적요를 적으십시오","")))))))))))) | O31: =IF($B31="","",YEAR($B31)*100+MONTH($B31)) | P31: =IF($B31="","",IF($E31="대체",0,1))
A32: =IF($B32="","",COUNT($B$15:$B32)) | E32: =IF($D32="","",IFERROR(INDEX('통합 ④ 설정'!$A$6:$A$40,MATCH($D32,'통합 ④ 설정'!$B$6:$B$40,0)),"※없는 과목")) | F32: =IF($D32="","",IFERROR(INDEX('통합 ④ 설정'!$C$6:$C$40,MATCH($D32,'통합 ④ 설정'!$B$6:$B$40,0)),"")) | L32: =IF($B32="","",IF(AND(N($I32)=0,N($J32)=0),"금액이 없습니다",IF(AND($I32>0,$J32>0),"수입·지출 둘 다 적혔습니다",IF($C32="","결제수단을 고르십시오",IF(ISNA(MATCH($C32,'통합 ③ 통장·카드'!$A$5:$A$11,0)),"③ 통장·카드에 없는 결제수단입니다",IF($D32="","계정과목을 고르십시오",IF($E32="※없는 과목","④ 설정에 없는 과목입니다",IF(AND($E32="수입",$J32>0),"수입 과목인데 지출에 적혔습니다",IF(AND(LEFT($E32,2)<>"수입",$E32<>"대체",$I32>0),"지출 과목인데 수입에 적혔습니다",IF($K32="","증빙을 고르십시오",IF(AND($C32="바우처통장",$J32>0,IFERROR(INDEX('통합 ④ 설정'!$E$6:$E$40,MATCH($D32,'통합 ④ 설정'!$B$6:$B$40,0)),"")<>"○"),"바우처통장 지출 — 목적 확인",IF($H32="","적요를 적으십시오","")))))))))))) | O32: =IF($B32="","",YEAR($B32)*100+MONTH($B32)) | P32: =IF($B32="","",IF($E32="대체",0,1))
A33: =IF($B33="","",COUNT($B$15:$B33)) | E33: =IF($D33="","",IFERROR(INDEX('통합 ④ 설정'!$A$6:$A$40,MATCH($D33,'통합 ④ 설정'!$B$6:$B$40,0)),"※없는 과목")) | F33: =IF($D33="","",IFERROR(INDEX('통합 ④ 설정'!$C$6:$C$40,MATCH($D33,'통합 ④ 설정'!$B$6:$B$40,0)),"")) | L33: =IF($B33="","",IF(AND(N($I33)=0,N($J33)=0),"금액이 없습니다",IF(AND($I33>0,$J33>0),"수입·지출 둘 다 적혔습니다",IF($C33="","결제수단을 고르십시오",IF(ISNA(MATCH($C33,'통합 ③ 통장·카드'!$A$5:$A$11,0)),"③ 통장·카드에 없는 결제수단입니다",IF($D33="","계정과목을 고르십시오",IF($E33="※없는 과목","④ 설정에 없는 과목입니다",IF(AND($E33="수입",$J33>0),"수입 과목인데 지출에 적혔습니다",IF(AND(LEFT($E33,2)<>"수입",$E33<>"대체",$I33>0),"지출 과목인데 수입에 적혔습니다",IF($K33="","증빙을 고르십시오",IF(AND($C33="바우처통장",$J33>0,IFERROR(INDEX('통합 ④ 설정'!$E$6:$E$40,MATCH($D33,'통합 ④ 설정'!$B$6:$B$40,0)),"")<>"○"),"바우처통장 지출 — 목적 확인",IF($H33="","적요를 적으십시오","")))))))))))) | O33: =IF($B33="","",YEAR($B33)*100+MONTH($B33)) | P33: =IF($B33="","",IF($E33="대체",0,1))
A34: =IF($B34="","",COUNT($B$15:$B34)) | E34: =IF($D34="","",IFERROR(INDEX('통합 ④ 설정'!$A$6:$A$40,MATCH($D34,'통합 ④ 설정'!$B$6:$B$40,0)),"※없는 과목")) | F34: =IF($D34="","",IFERROR(INDEX('통합 ④ 설정'!$C$6:$C$40,MATCH($D34,'통합 ④ 설정'!$B$6:$B$40,0)),"")) | L34: =IF($B34="","",IF(AND(N($I34)=0,N($J34)=0),"금액이 없습니다",IF(AND($I34>0,$J34>0),"수입·지출 둘 다 적혔습니다",IF($C34="","결제수단을 고르십시오",IF(ISNA(MATCH($C34,'통합 ③ 통장·카드'!$A$5:$A$11,0)),"③ 통장·카드에 없는 결제수단입니다",IF($D34="","계정과목을 고르십시오",IF($E34="※없는 과목","④ 설정에 없는 과목입니다",IF(AND($E34="수입",$J34>0),"수입 과목인데 지출에 적혔습니다",IF(AND(LEFT($E34,2)<>"수입",$E34<>"대체",$I34>0),"지출 과목인데 수입에 적혔습니다",IF($K34="","증빙을 고르십시오",IF(AND($C34="바우처통장",$J34>0,IFERROR(INDEX('통합 ④ 설정'!$E$6:$E$40,MATCH($D34,'통합 ④ 설정'!$B$6:$B$40,0)),"")<>"○"),"바우처통장 지출 — 목적 확인",IF($H34="","적요를 적으십시오","")))))))))))) | O34: =IF($B34="","",YEAR($B34)*100+MONTH($B34)) | P34: =IF($B34="","",IF($E34="대체",0,1))
A35: =IF($B35="","",COUNT($B$15:$B35)) | E35: =IF($D35="","",IFERROR(INDEX('통합 ④ 설정'!$A$6:$A$40,MATCH($D35,'통합 ④ 설정'!$B$6:$B$40,0)),"※없는 과목")) | F35: =IF($D35="","",IFERROR(INDEX('통합 ④ 설정'!$C$6:$C$40,MATCH($D35,'통합 ④ 설정'!$B$6:$B$40,0)),"")) | L35: =IF($B35="","",IF(AND(N($I35)=0,N($J35)=0),"금액이 없습니다",IF(AND($I35>0,$J35>0),"수입·지출 둘 다 적혔습니다",IF($C35="","결제수단을 고르십시오",IF(ISNA(MATCH($C35,'통합 ③ 통장·카드'!$A$5:$A$11,0)),"③ 통장·카드에 없는 결제수단입니다",IF($D35="","계정과목을 고르십시오",IF($E35="※없는 과목","④ 설정에 없는 과목입니다",IF(AND($E35="수입",$J35>0),"수입 과목인데 지출에 적혔습니다",IF(AND(LEFT($E35,2)<>"수입",$E35<>"대체",$I35>0),"지출 과목인데 수입에 적혔습니다",IF($K35="","증빙을 고르십시오",IF(AND($C35="바우처통장",$J35>0,IFERROR(INDEX('통합 ④ 설정'!$E$6:$E$40,MATCH($D35,'통합 ④ 설정'!$B$6:$B$40,0)),"")<>"○"),"바우처통장 지출 — 목적 확인",IF($H35="","적요를 적으십시오","")))))))))))) | O35: =IF($B35="","",YEAR($B35)*100+MONTH($B35)) | P35: =IF($B35="","",IF($E35="대체",0,1))
... A2014: =IF($B2014="","",COUNT($B$15:$B2014)) | E2014: =IF($D2014="","",IFERROR(INDEX('통합 ④ 설정'!$A$6:$A$40,MATCH($D2014,'통합 ④ 설정'!$B$6:$B$40,0)),"※없는 과목")) | F2014: =IF($D2014="","",IFERROR(INDEX('통합 ④ 설정'!$C$6:$C$40,MATCH($D2014,'통합 ④ 설정'!$B$6:$B$40,0)),"")) | L2014: =IF($B2014="","",IF(AND(N($I2014)=0,N($J2014)=0),"금액이 없습니다",IF(AND($I2014>0,$J2014>0),"수입·지출 둘 다 적혔습니다",IF($C2014="","결제수단을 고르십시오",IF(ISNA(MATCH($C2014,'통합 ③ 통장·카드'!$A$5:$A$11,0)),"③ 통장·카드에 없는 결제수단입니다",IF($D2014="","계정과목을 고르십시오",IF($E2014="※없는 과목","④ 설정에 없는 과목입니다",IF(AND($E2014="수입",$J2014>0),"수입 과목인데 지출에 적혔습니다",IF(AND(LEFT($E2014,2)<>"수입",$E2014<>"대체",$I2014>0),"지출 과목인데 수입에 적혔습니다",IF($K2014="","증빙을 고르십시오",IF(AND($C2014="바우처통장",$J2014>0,IFERROR(INDEX('통합 ④ 설정'!$E$6:$E$40,MATCH($D2014,'통합 ④ 설정'!$B$6:$B$40,0)),"")<>"○"),"바우처통장 지출 — 목적 확인",IF($H2014="","적요를 적으십시오","")))))))))))) | O2014: =IF($B2014="","",YEAR($B2014)*100+MONTH($B2014)) | P2014: =IF($B2014="","",IF($E2014="대체",0,1))

Sheet 통합 ② 월별결산
A1: 통합 ② 월별 결산 (따사로운 통합서비스) | F1: 연도 | G1: 2026 | H1: ← 이 칸의 연도만 바꾸면 그 해 숫자가 나옵니다
A2: 「통합 ① 거래입력」에서 자동으로 계산됩니다. 손으로 고치지 마십시오. 이 표에는 따사로운 통합서비스의 돈만 들어 있습니다.
A4: 구분 | B4: 계정과목 | C4: 1월 | D4: 2월 | E4: 3월 | F4: 4월 | G4: 5월 | H4: 6월 | I4: 7월 | J4: 8월 | K4: 9월 | L4: 10월 | M4: 11월 | N4: 12월 | O4: 연간 합계 | P4: 월평균
A5: 수입 | B5: 바우처수입-산모신생아 | C5: =SUMIFS('통합 ① 거래입력'!$I$15:$I$2014,'통합 ① 거래입력'!$O$15:$O$2014,$G$1*100+1,'통합 ① 거래입력'!$D$15:$D$2014,$B5) -> 0 | D5: =SUMIFS('통합 ① 거래입력'!$I$15:$I$2014,'통합 ① 거래입력'!$O$15:$O$2014,$G$1*100+2,'통합 ① 거래입력'!$D$15:$D$2014,$B5) -> 0 | E5: =SUMIFS('통합 ① 거래입력'!$I$15:$I$2014,'통합 ① 거래입력'!$O$15:$O$2014,$G$1*100+3,'통합 ① 거래입력'!$D$15:$D$2014,$B5) -> 0 | F5: =SUMIFS('통합 ① 거래입력'!$I$15:$I$2014,'통합 ① 거래입력'!$O$15:$O$2014,$G$1*100+4,'통합 ① 거래입력'!$D$15:$D$2014,$B5) -> 0 | G5: =SUMIFS('통합 ① 거래입력'!$I$15:$I$2014,'통합 ① 거래입력'!$O$15:$O$2014,$G$1*100+5,'통합 ① 거래입력'!$D$15:$D$2014,$B5) -> 0 | H5: =SUMIFS('통합 ① 거래입력'!$I$15:$I$2014,'통합 ① 거래입력'!$O$15:$O$2014,$G$1*100+6,'통합 ① 거래입력'!$D$15:$D$2014,$B5) -> 0 | I5: =SUMIFS('통합 ① 거래입력'!$I$15:$I$2014,'통합 ① 거래입력'!$O$15:$O$2014,$G$1*100+7,'통합 ① 거래입력'!$D$15:$D$2014,$B5) -> 0 | J5: =SUMIFS('통합 ① 거래입력'!$I$15:$I$2014,'통합 ① 거래입력'!$O$15:$O$2014,$G$1*100+8,'통합 ① 거래입력'!$D$15:$D$2014,$B5) -> 0 | K5: =SUMIFS('통합 ① 거래입력'!$I$15:$I$2014,'통합 ① 거래입력'!$O$15:$O$2014,$G$1*100+9,'통합 ① 거래입력'!$D$15:$D$2014,$B5) -> 4820000 | L5: =SUMIFS('통합 ① 거래입력'!$I$15:$I$2014,'통합 ① 거래입력'!$O$15:$O$2014,$G$1*100+10,'통합 ① 거래입력'!$D$15:$D$2014,$B5) -> 0 | M5: =SUMIFS('통합 ① 거래입력'!$I$15:$I$2014,'통합 ① 거래입력'!$O$15:$O$2014,$G$1*100+11,'통합 ① 거래입력'!$D$15:$D$2014,$B5) -> 0 | N5: =SUMIFS('통합 ① 거래입력'!$I$15:$I$2014,'통합 ① 거래입력'!$O$15:$O$2014,$G$1*100+12,'통합 ① 거래입력'!$D$15:$D$2014,$B5) -> 0 | O5: =SUM($C5:$N5) -> 4820000 | P5: =IFERROR(AVERAGEIF($C5:$N5,"<>0"),0) -> 4820000
B6: 바우처수입-가사서비스 | C6: =SUMIFS('통합 ① 거래입력'!$I$15:$I$2014,'통합 ① 거래입력'!$O$15:$O$2014,$G$1*100+1,'통합 ① 거래입력'!$D$15:$D$2014,$B6) -> 0 | D6: =SUMIFS('통합 ① 거래입력'!$I$15:$I$2014,'통합 ① 거래입력'!$O$15:$O$2014,$G$1*100+2,'통합 ① 거래입력'!$D$15:$D$2014,$B6) -> 0 | E6: =SUMIFS('통합 ① 거래입력'!$I$15:$I$2014,'통합 ① 거래입력'!$O$15:$O$2014,$G$1*100+3,'통합 ① 거래입력'!$D$15:$D$2014,$B6) -> 0 | F6: =SUMIFS('통합 ① 거래입력'!$I$15:$I$2014,'통합 ① 거래입력'!$O$15:$O$2014,$G$1*100+4,'통합 ① 거래입력'!$D$15:$D$2014,$B6) -> 0 | G6: =SUMIFS('통합 ① 거래입력'!$I$15:$I$2014,'통합 ① 거래입력'!$O$15:$O$2014,$G$1*100+5,'통합 ① 거래입력'!$D$15:$D$2014,$B6) -> 0 | H6: =SUMIFS('통합 ① 거래입력'!$I$15:$I$2014,'통합 ① 거래입력'!$O$15:$O$2014,$G$1*100+6,'통합 ① 거래입력'!$D$15:$D$2014,$B6) -> 0 | I6: =SUMIFS('통합 ① 거래입력'!$I$15:$I$2014,'통합 ① 거래입력'!$O$15:$O$2014,$G$1*100+7,'통합 ① 거래입력'!$D$15:$D$2014,$B6) -> 0 | J6: =SUMIFS('통합 ① 거래입력'!$I$15:$I$2014,'통합 ① 거래입력'!$O$15:$O$2014,$G$1*100+8,'통합 ① 거래입력'!$D$15:$D$2014,$B6) -> 0 | K6: =SUMIFS('통합 ① 거래입력'!$I$15:$I$2014,'통합 ① 거래입력'!$O$15:$O$2014,$G$1*100+9,'통합 ① 거래입력'!$D$15:$D$2014,$B6) -> 0 | L6: =SUMIFS('통합 ① 거래입력'!$I$15:$I$2014,'통합 ① 거래입력'!$O$15:$O$2014,$G$1*100+10,'통합 ① 거래입력'!$D$15:$D$2014,$B6) -> 0 | M6: =SUMIFS('통합 ① 거래입력'!$I$15:$I$2014,'통합 ① 거래입력'!$O$15:$O$2014,$G$1*100+11,'통합 ① 거래입력'!$D$15:$D$2014,$B6) -> 0 | N6: =SUMIFS('통합 ① 거래입력'!$I$15:$I$2014,'통합 ① 거래입력'!$O$15:$O$2014,$G$1*100+12,'통합 ① 거래입력'!$D$15:$D$2014,$B6) -> 0 | O6: =SUM($C6:$N6) -> 0 | P6: =IFERROR(AVERAGEIF($C6:$N6,"<>0"),0) -> 0
B7: 바우처수입-영유아 | C7: =SUMIFS('통합 ① 거래입력'!$I$15:$I$2014,'통합 ① 거래입력'!$O$15:$O$2014,$G$1*100+1,'통합 ① 거래입력'!$D$15:$D$2014,$B7) -> 0 | D7: =SUMIFS('통합 ① 거래입력'!$I$15:$I$2014,'통합 ① 거래입력'!$O$15:$O$2014,$G$1*100+2,'통합 ① 거래입력'!$D$15:$D$2014,$B7) -> 0 | E7: =SUMIFS('통합 ① 거래입력'!$I$15:$I$2014,'통합 ① 거래입력'!$O$15:$O$2014,$G$1*100+3,'통합 ① 거래입력'!$D$15:$D$2014,$B7) -> 0 | F7: =SUMIFS('통합 ① 거래입력'!$I$15:$I$2014,'통합 ① 거래입력'!$O$15:$O$2014,$G$1*100+4,'통합 ① 거래입력'!$D$15:$D$2014,$B7) -> 0 | G7: =SUMIFS('통합 ① 거래입력'!$I$15:$I$2014,'통합 ① 거래입력'!$O$15:$O$2014,$G$1*100+5,'통합 ① 거래입력'!$D$15:$D$2014,$B7) -> 0 | H7: =SUMIFS('통합 ① 거래입력'!$I$15:$I$2014,'통합 ① 거래입력'!$O$15:$O$2014,$G$1*100+6,'통합 ① 거래입력'!$D$15:$D$2014,$B7) -> 0 | I7: =SUMIFS('통합 ① 거래입력'!$I$15:$I$2014,'통합 ① 거래입력'!$O$15:$O$2014,$G$1*100+7,'통합 ① 거래입력'!$D$15:$D$2014,$B7) -> 0 | J7: =SUMIFS('통합 ① 거래입력'!$I$15:$I$2014,'통합 ① 거래입력'!$O$15:$O$2014,$G$1*100+8,'통합 ① 거래입력'!$D$15:$D$2014,$B7) -> 0 | K7: =SUMIFS('통합 ① 거래입력'!$I$15:$I$2014,'통합 ① 거래입력'!$O$15:$O$2014,$G$1*100+9,'통합 ① 거래입력'!$D$15:$D$2014,$B7) -> 0 | L7: =SUMIFS('통합 ① 거래입력'!$I$15:$I$2014,'통합 ① 거래입력'!$O$15:$O$2014,$G$1*100+10,'통합 ① 거래입력'!$D$15:$D$2014,$B7) -> 0 | M7: =SUMIFS('통합 ① 거래입력'!$I$15:$I$2014,'통합 ① 거래입력'!$O$15:$O$2014,$G$1*100+11,'통합 ① 거래입력'!$D$15:$D$2014,$B7) -> 0 | N7: =SUMIFS('통합 ① 거래입력'!$I$15:$I$2014,'통합 ① 거래입력'!$O$15:$O$2014,$G$1*100+12,'통합 ① 거래입력'!$D$15:$D$2014,$B7) -> 0 | O7: =SUM($C7:$N7) -> 0 | P7: =IFERROR(AVERAGEIF($C7:$N7,"<>0"),0) -> 0
B8: 바우처수입-정리수납 | C8: =SUMIFS('통합 ① 거래입력'!$I$15:$I$2014,'통합 ① 거래입력'!$O$15:$O$2014,$G$1*100+1,'통합 ① 거래입력'!$D$15:$D$2014,$B8) -> 0 | D8: =SUMIFS('통합 ① 거래입력'!$I$15:$I$2014,'통합 ① 거래입력'!$O$15:$O$2014,$G$1*100+2,'통합 ① 거래입력'!$D$15:$D$2014,$B8) -> 0 | E8: =SUMIFS('통합 ① 거래입력'!$I$15:$I$2014,'통합 ① 거래입력'!$O$15:$O$2014,$G$1*100+3,'통합 ① 거래입력'!$D$15:$D$2014,$B8) -> 0 | F8: =SUMIFS('통합 ① 거래입력'!$I$15:$I$2014,'통합 ① 거래입력'!$O$15:$O$2014,$G$1*100+4,'통합 ① 거래입력'!$D$15:$D$2014,$B8) -> 0 | G8: =SUMIFS('통합 ① 거래입력'!$I$15:$I$2014,'통합 ① 거래입력'!$O$15:$O$2014,$G$1*100+5,'통합 ① 거래입력'!$D$15:$D$2014,$B8) -> 0 | H8: =SUMIFS('통합 ① 거래입력'!$I$15:$I$2014,'통합 ① 거래입력'!$O$15:$O$2014,$G$1*100+6,'통합 ① 거래입력'!$D$15:$D$2014,$B8) -> 0 | I8: =SUMIFS('통합 ① 거래입력'!$I$15:$I$2014,'통합 ① 거래입력'!$O$15:$O$2014,$G$1*100+7,'통합 ① 거래입력'!$D$15:$D$2014,$B8) -> 0 | J8: =SUMIFS('통합 ① 거래입력'!$I$15:$I$2014,'통합 ① 거래입력'!$O$15:$O$2014,$G$1*100+8,'통합 ① 거래입력'!$D$15:$D$2014,$B8) -> 0 | K8: =SUMIFS('통합 ① 거래입력'!$I$15:$I$2014,'통합 ① 거래입력'!$O$15:$O$2014,$G$1*100+9,'통합 ① 거래입력'!$D$15:$D$2014,$B8) -> 0 | L8: =SUMIFS('통합 ① 거래입력'!$I$15:$I$2014,'통합 ① 거래입력'!$O$15:$O$2014,$G$1*100+10,'통합 ① 거래입력'!$D$15:$D$2014,$B8) -> 0 | M8: =SUMIFS('통합 ① 거래입력'!$I$15:$I$2014,'통합 ① 거래입력'!$O$15:$O$2014,$G$1*100+11,'통합 ① 거래입력'!$D$15:$D$2014,$B8) -> 0 | N8: =SUMIFS('통합 ① 거래입력'!$I$15:$I$2014,'통합 ① 거래입력'!$O$15:$O$2014,$G$1*100+12,'통합 ① 거래입력'!$D$15:$D$2014,$B8) -> 0 | O8: =SUM($C8:$N8) -> 0 | P8: =IFERROR(AVERAGEIF($C8:$N8,"<>0"),0) -> 0
B9: 본인부담금 | C9: =SUMIFS('통합 ① 거래입력'!$I$15:$I$2014,'통합 ① 거래입력'!$O$15:$O$2014,$G$1*100+1,'통합 ① 거래입력'!$D$15:$D$2014,$B9) -> 0 | D9: =SUMIFS('통합 ① 거래입력'!$I$15:$I$2014,'통합 ① 거래입력'!$O$15:$O$2014,$G$1*100+2,'통합 ① 거래입력'!$D$15:$D$2014,$B9) -> 0 | E9: =SUMIFS('통합 ① 거래입력'!$I$15:$I$2014,'통합 ① 거래입력'!$O$15:$O$2014,$G$1*100+3,'통합 ① 거래입력'!$D$15:$D$2014,$B9) -> 0 | F9: =SUMIFS('통합 ① 거래입력'!$I$15:$I$2014,'통합 ① 거래입력'!$O$15:$O$2014,$G$1*100+4,'통합 ① 거래입력'!$D$15:$D$2014,$B9) -> 0 | G9: =SUMIFS('통합 ① 거래입력'!$I$15:$I$2014,'통합 ① 거래입력'!$O$15:$O$2014,$G$1*100+5,'통합 ① 거래입력'!$D$15:$D$2014,$B9) -> 0 | H9: =SUMIFS('통합 ① 거래입력'!$I$15:$I$2014,'통합 ① 거래입력'!$O$15:$O$2014,$G$1*100+6,'통합 ① 거래입력'!$D$15:$D$2014,$B9) -> 0 | I9: =SUMIFS('통합 ① 거래입력'!$I$15:$I$2014,'통합 ① 거래입력'!$O$15:$O$2014,$G$1*100+7,'통합 ① 거래입력'!$D$15:$D$2014,$B9) -> 0 | J9: =SUMIFS('통합 ① 거래입력'!$I$15:$I$2014,'통합 ① 거래입력'!$O$15:$O$2014,$G$1*100+8,'통합 ① 거래입력'!$D$15:$D$2014,$B9) -> 0 | K9: =SUMIFS('통합 ① 거래입력'!$I$15:$I$2014,'통합 ① 거래입력'!$O$15:$O$2014,$G$1*100+9,'통합 ① 거래입력'!$D$15:$D$2014,$B9) -> 0 | L9: =SUMIFS('통합 ① 거래입력'!$I$15:$I$2014,'통합 ① 거래입력'!$O$15:$O$2014,$G$1*100+10,'통합 ① 거래입력'!$D$15:$D$2014,$B9) -> 0 | M9: =SUMIFS('통합 ① 거래입력'!$I$15:$I$2014,'통합 ① 거래입력'!$O$15:$O$2014,$G$1*100+11,'통합 ① 거래입력'!$D$15:$D$2014,$B9) -> 0 | N9: =SUMIFS('통합 ① 거래입력'!$I$15:$I$2014,'통합 ① 거래입력'!$O$15:$O$2014,$G$1*100+12,'통합 ① 거래입력'!$D$15:$D$2014,$B9) -> 0 | O9: =SUM($C9:$N9) -> 0 | P9: =IFERROR(AVERAGEIF($C9:$N9,"<>0"),0) -> 0
B10: 보조금·지원금 | C10: =SUMIFS('통합 ① 거래입력'!$I$15:$I$2014,'통합 ① 거래입력'!$O$15:$O$2014,$G$1*100+1,'통합 ① 거래입력'!$D$15:$D$2014,$B10) -> 0 | D10: =SUMIFS('통합 ① 거래입력'!$I$15:$I$2014,'통합 ① 거래입력'!$O$15:$O$2014,$G$1*100+2,'통합 ① 거래입력'!$D$15:$D$2014,$B10) -> 0 | E10: =SUMIFS('통합 ① 거래입력'!$I$15:$I$2014,'통합 ① 거래입력'!$O$15:$O$2014,$G$1*100+3,'통합 ① 거래입력'!$D$15:$D$2014,$B10) -> 0 | F10: =SUMIFS('통합 ① 거래입력'!$I$15:$I$2014,'통합 ① 거래입력'!$O$15:$O$2014,$G$1*100+4,'통합 ① 거래입력'!$D$15:$D$2014,$B10) -> 0 | G10: =SUMIFS('통합 ① 거래입력'!$I$15:$I$2014,'통합 ① 거래입력'!$O$15:$O$2014,$G$1*100+5,'통합 ① 거래입력'!$D$15:$D$2014,$B10) -> 0 | H10: =SUMIFS('통합 ① 거래입력'!$I$15:$I$2014,'통합 ① 거래입력'!$O$15:$O$2014,$G$1*100+6,'통합 ① 거래입력'!$D$15:$D$2014,$B10) -> 0 | I10: =SUMIFS('통합 ① 거래입력'!$I$15:$I$2014,'통합 ① 거래입력'!$O$15:$O$2014,$G$1*100+7,'통합 ① 거래입력'!$D$15:$D$2014,$B10) -> 0 | J10: =SUMIFS('통합 ① 거래입력'!$I$15:$I$2014,'통합 ① 거래입력'!$O$15:$O$2014,$G$1*100+8,'통합 ① 거래입력'!$D$15:$D$2014,$B10) -> 0 | K10: =SUMIFS('통합 ① 거래입력'!$I$15:$I$2014,'통합 ① 거래입력'!$O$15:$O$2014,$G$1*100+9,'통합 ① 거래입력'!$D$15:$D$2014,$B10) -> 0 | L10: =SUMIFS('통합 ① 거래입력'!$I$15:$I$2014,'통합 ① 거래입력'!$O$15:$O$2014,$G$1*100+10,'통합 ① 거래입력'!$D$15:$D$2014,$B10) -> 0 | M10: =SUMIFS('통합 ① 거래입력'!$I$15:$I$2014,'통합 ① 거래입력'!$O$15:$O$2014,$G$1*100+11,'통합 ① 거래입력'!$D$15:$D$2014,$B10) -> 0 | N10: =SUMIFS('통합 ① 거래입력'!$I$15:$I$2014,'통합 ① 거래입력'!$O$15:$O$2014,$G$1*100+12,'통합 ① 거래입력'!$D$15:$D$2014,$B10) -> 0 | O10: =SUM($C10:$N10) -> 0 | P10: =IFERROR(AVERAGEIF($C10:$N10,"<>0"),0) -> 0
B11: 타사업자 정산수입 | C11: =SUMIFS('통합 ① 거래입력'!$I$15:$I$2014,'통합 ① 거래입력'!$O$15:$O$2014,$G$1*100+1,'통합 ① 거래입력'!$D$15:$D$2014,$B11) -> 0 | D11: =SUMIFS('통합 ① 거래입력'!$I$15:$I$2014,'통합 ① 거래입력'!$O$15:$O$2014,$G$1*100+2,'통합 ① 거래입력'!$D$15:$D$2014,$B11) -> 0 | E11: =SUMIFS('통합 ① 거래입력'!$I$15:$I$2014,'통합 ① 거래입력'!$O$15:$O$2014,$G$1*100+3,'통합 ① 거래입력'!$D$15:$D$2014,$B11) -> 0 | F11: =SUMIFS('통합 ① 거래입력'!$I$15:$I$2014,'통합 ① 거래입력'!$O$15:$O$2014,$G$1*100+4,'통합 ① 거래입력'!$D$15:$D$2014,$B11) -> 0 | G11: =SUMIFS('통합 ① 거래입력'!$I$15:$I$2014,'통합 ① 거래입력'!$O$15:$O$2014,$G$1*100+5,'통합 ① 거래입력'!$D$15:$D$2014,$B11) -> 0 | H11: =SUMIFS('통합 ① 거래입력'!$I$15:$I$2014,'통합 ① 거래입력'!$O$15:$O$2014,$G$1*100+6,'통합 ① 거래입력'!$D$15:$D$2014,$B11) -> 0 | I11: =SUMIFS('통합 ① 거래입력'!$I$15:$I$2014,'통합 ① 거래입력'!$O$15:$O$2014,$G$1*100+7,'통합 ① 거래입력'!$D$15:$D$2014,$B11) -> 0 | J11: =SUMIFS('통합 ① 거래입력'!$I$15:$I$2014,'통합 ① 거래입력'!$O$15:$O$2014,$G$1*100+8,'통합 ① 거래입력'!$D$15:$D$2014,$B11) -> 0 | K11: =SUMIFS('통합 ① 거래입력'!$I$15:$I$2014,'통합 ① 거래입력'!$O$15:$O$2014,$G$1*100+9,'통합 ① 거래입력'!$D$15:$D$2014,$B11) -> 300000 | L11: =SUMIFS('통합 ① 거래입력'!$I$15:$I$2014,'통합 ① 거래입력'!$O$15:$O$2014,$G$1*100+10,'통합 ① 거래입력'!$D$15:$D$2014,$B11) -> 0 | M11: =SUMIFS('통합 ① 거래입력'!$I$15:$I$2014,'통합 ① 거래입력'!$O$15:$O$2014,$G$1*100+11,'통합 ① 거래입력'!$D$15:$D$2014,$B11) -> 0 | N11: =SUMIFS('통합 ① 거래입력'!$I$15:$I$2014,'통합 ① 거래입력'!$O$15:$O$2014,$G$1*100+12,'통합 ① 거래입력'!$D$15:$D$2014,$B11) -> 0 | O11: =SUM($C11:$N11) -> 300000 | P11: =IFERROR(AVERAGEIF($C11:$N11,"<>0"),0) -> 300000
B12: 이자수입 | C12: =SUMIFS('통합 ① 거래입력'!$I$15:$I$2014,'통합 ① 거래입력'!$O$15:$O$2014,$G$1*100+1,'통합 ① 거래입력'!$D$15:$D$2014,$B12) -> 0 | D12: =SUMIFS('통합 ① 거래입력'!$I$15:$I$2014,'통합 ① 거래입력'!$O$15:$O$2014,$G$1*100+2,'통합 ① 거래입력'!$D$15:$D$2014,$B12) -> 0 | E12: =SUMIFS('통합 ① 거래입력'!$I$15:$I$2014,'통합 ① 거래입력'!$O$15:$O$2014,$G$1*100+3,'통합 ① 거래입력'!$D$15:$D$2014,$B12) -> 0 | F12: =SUMIFS('통합 ① 거래입력'!$I$15:$I$2014,'통합 ① 거래입력'!$O$15:$O$2014,$G$1*100+4,'통합 ① 거래입력'!$D$15:$D$2014,$B12) -> 0 | G12: =SUMIFS('통합 ① 거래입력'!$I$15:$I$2014,'통합 ① 거래입력'!$O$15:$O$2014,$G$1*100+5,'통합 ① 거래입력'!$D$15:$D$2014,$B12) -> 0 | H12: =SUMIFS('통합 ① 거래입력'!$I$15:$I$2014,'통합 ① 거래입력'!$O$15:$O$2014,$G$1*100+6,'통합 ① 거래입력'!$D$15:$D$2014,$B12) -> 0 | I12: =SUMIFS('통합 ① 거래입력'!$I$15:$I$2014,'통합 ① 거래입력'!$O$15:$O$2014,$G$1*100+7,'통합 ① 거래입력'!$D$15:$D$2014,$B12) -> 0 | J12: =SUMIFS('통합 ① 거래입력'!$I$15:$I$2014,'통합 ① 거래입력'!$O$15:$O$2014,$G$1*100+8,'통합 ① 거래입력'!$D$15:$D$2014,$B12) -> 0 | K12: =SUMIFS('통합 ① 거래입력'!$I$15:$I$2014,'통합 ① 거래입력'!$O$15:$O$2014,$G$1*100+9,'통합 ① 거래입력'!$D$15:$D$2014,$B12) -> 0 | L12: =SUMIFS('통합 ① 거래입력'!$I$15:$I$2014,'통합 ① 거래입력'!$O$15:$O$2014,$G$1*100+10,'통합 ① 거래입력'!$D$15:$D$2014,$B12) -> 0 | M12: =SUMIFS('통합 ① 거래입력'!$I$15:$I$2014,'통합 ① 거래입력'!$O$15:$O$2014,$G$1*100+11,'통합 ① 거래입력'!$D$15:$D$2014,$B12) -> 0 | N12: =SUMIFS('통합 ① 거래입력'!$I$15:$I$2014,'통합 ① 거래입력'!$O$15:$O$2014,$G$1*100+12,'통합 ① 거래입력'!$D$15:$D$2014,$B12) -> 0 | O12: =SUM($C12:$N12) -> 0 | P12: =IFERROR(AVERAGEIF($C12:$N12,"<>0"),0) -> 0
B13: 기타수입 | C13: =SUMIFS('통합 ① 거래입력'!$I$15:$I$2014,'통합 ① 거래입력'!$O$15:$O$2014,$G$1*100+1,'통합 ① 거래입력'!$D$15:$D$2014,$B13) -> 0 | D13: =SUMIFS('통합 ① 거래입력'!$I$15:$I$2014,'통합 ① 거래입력'!$O$15:$O$2014,$G$1*100+2,'통합 ① 거래입력'!$D$15:$D$2014,$B13) -> 0 | E13: =SUMIFS('통합 ① 거래입력'!$I$15:$I$2014,'통합 ① 거래입력'!$O$15:$O$2014,$G$1*100+3,'통합 ① 거래입력'!$D$15:$D$2014,$B13) -> 0 | F13: =SUMIFS('통합 ① 거래입력'!$I$15:$I$2014,'통합 ① 거래입력'!$O$15:$O$2014,$G$1*100+4,'통합 ① 거래입력'!$D$15:$D$2014,$B13) -> 0 | G13: =SUMIFS('통합 ① 거래입력'!$I$15:$I$2014,'통합 ① 거래입력'!$O$15:$O$2014,$G$1*100+5,'통합 ① 거래입력'!$D$15:$D$2014,$B13) -> 0 | H13: =SUMIFS('통합 ① 거래입력'!$I$15:$I$2014,'통합 ① 거래입력'!$O$15:$O$2014,$G$1*100+6,'통합 ① 거래입력'!$D$15:$D$2014,$B13) -> 0 | I13: =SUMIFS('통합 ① 거래입력'!$I$15:$I$2014,'통합 ① 거래입력'!$O$15:$O$2014,$G$1*100+7,'통합 ① 거래입력'!$D$15:$D$2014,$B13) -> 0 | J13: =SUMIFS('통합 ① 거래입력'!$I$15:$I$2014,'통합 ① 거래입력'!$O$15:$O$2014,$G$1*100+8,'통합 ① 거래입력'!$D$15:$D$2014,$B13) -> 0 | K13: =SUMIFS('통합 ① 거래입력'!$I$15:$I$2014,'통합 ① 거래입력'!$O$15:$O$2014,$G$1*100+9,'통합 ① 거래입력'!$D$15:$D$2014,$B13) -> 0 | L13: =SUMIFS('통합 ① 거래입력'!$I$15:$I$2014,'통합 ① 거래입력'!$O$15:$O$2014,$G$1*100+10,'통합 ① 거래입력'!$D$15:$D$2014,$B13) -> 0 | M13: =SUMIFS('통합 ① 거래입력'!$I$15:$I$2014,'통합 ① 거래입력'!$O$15:$O$2014,$G$1*100+11,'통합 ① 거래입력'!$D$15:$D$2014,$B13) -> 0 | N13: =SUMIFS('통합 ① 거래입력'!$I$15:$I$2014,'통합 ① 거래입력'!$O$15:$O$2014,$G$1*100+12,'통합 ① 거래입력'!$D$15:$D$2014,$B13) -> 0 | O13: =SUM($C13:$N13) -> 0 | P13: =IFERROR(AVERAGEIF($C13:$N13,"<>0"),0) -> 0
B14: 수입 소계 | C14: =SUM(C5:C13) -> 0 | D14: =SUM(D5:D13) -> 0 | E14: =SUM(E5:E13) -> 0 | F14: =SUM(F5:F13) -> 0 | G14: =SUM(G5:G13) -> 0 | H14: =SUM(H5:H13) -> 0 | I14: =SUM(I5:I13) -> 0 | J14: =SUM(J5:J13) -> 0 | ... P14: =SUM(P5:P13) -> 5120000
A16: 고정지출 | B16: 급여(직원) | C16: =SUMIFS('통합 ① 거래입력'!$J$15:$J$2014,'통합 ① 거래입력'!$O$15:$O$2014,$G$1*100+1,'통합 ① 거래입력'!$D$15:$D$2014,$B16) -> 0 | D16: =SUMIFS('통합 ① 거래입력'!$J$15:$J$2014,'통합 ① 거래입력'!$O$15:$O$2014,$G$1*100+2,'통합 ① 거래입력'!$D$15:$D$2014,$B16) -> 0 | E16: =SUMIFS('통합 ① 거래입력'!$J$15:$J$2014,'통합 ① 거래입력'!$O$15:$O$2014,$G$1*100+3,'통합 ① 거래입력'!$D$15:$D$2014,$B16) -> 0 | F16: =SUMIFS('통합 ① 거래입력'!$J$15:$J$2014,'통합 ① 거래입력'!$O$15:$O$2014,$G$1*100+4,'통합 ① 거래입력'!$D$15:$D$2014,$B16) -> 0 | G16: =SUMIFS('통합 ① 거래입력'!$J$15:$J$2014,'통합 ① 거래입력'!$O$15:$O$2014,$G$1*100+5,'통합 ① 거래입력'!$D$15:$D$2014,$B16) -> 0 | H16: =SUMIFS('통합 ① 거래입력'!$J$15:$J$2014,'통합 ① 거래입력'!$O$15:$O$2014,$G$1*100+6,'통합 ① 거래입력'!$D$15:$D$2014,$B16) -> 0 | I16: =SUMIFS('통합 ① 거래입력'!$J$15:$J$2014,'통합 ① 거래입력'!$O$15:$O$2014,$G$1*100+7,'통합 ① 거래입력'!$D$15:$D$2014,$B16) -> 0 | J16: =SUMIFS('통합 ① 거래입력'!$J$15:$J$2014,'통합 ① 거래입력'!$O$15:$O$2014,$G$1*100+8,'통합 ① 거래입력'!$D$15:$D$2014,$B16) -> 0 | K16: =SUMIFS('통합 ① 거래입력'!$J$15:$J$2014,'통합 ① 거래입력'!$O$15:$O$2014,$G$1*100+9,'통합 ① 거래입력'!$D$15:$D$2014,$B16) -> 0 | L16: =SUMIFS('통합 ① 거래입력'!$J$15:$J$2014,'통합 ① 거래입력'!$O$15:$O$2014,$G$1*100+10,'통합 ① 거래입력'!$D$15:$D$2014,$B16) -> 0 | M16: =SUMIFS('통합 ① 거래입력'!$J$15:$J$2014,'통합 ① 거래입력'!$O$15:$O$2014,$G$1*100+11,'통합 ① 거래입력'!$D$15:$D$2014,$B16) -> 0 | N16: =SUMIFS('통합 ① 거래입력'!$J$15:$J$2014,'통합 ① 거래입력'!$O$15:$O$2014,$G$1*100+12,'통합 ① 거래입력'!$D$15:$D$2014,$B16) -> 0 | O16: =SUM($C16:$N16) -> 0 | P16: =IFERROR(AVERAGEIF($C16:$N16,"<>0"),0) -> 0
B17: 용역비(관리사) | C17: =SUMIFS('통합 ① 거래입력'!$J$15:$J$2014,'통합 ① 거래입력'!$O$15:$O$2014,$G$1*100+1,'통합 ① 거래입력'!$D$15:$D$2014,$B17) -> 0 | D17: =SUMIFS('통합 ① 거래입력'!$J$15:$J$2014,'통합 ① 거래입력'!$O$15:$O$2014,$G$1*100+2,'통합 ① 거래입력'!$D$15:$D$2014,$B17) -> 0 | E17: =SUMIFS('통합 ① 거래입력'!$J$15:$J$2014,'통합 ① 거래입력'!$O$15:$O$2014,$G$1*100+3,'통합 ① 거래입력'!$D$15:$D$2014,$B17) -> 0 | F17: =SUMIFS('통합 ① 거래입력'!$J$15:$J$2014,'통합 ① 거래입력'!$O$15:$O$2014,$G$1*100+4,'통합 ① 거래입력'!$D$15:$D$2014,$B17) -> 0 | G17: =SUMIFS('통합 ① 거래입력'!$J$15:$J$2014,'통합 ① 거래입력'!$O$15:$O$2014,$G$1*100+5,'통합 ① 거래입력'!$D$15:$D$2014,$B17) -> 0 | H17: =SUMIFS('통합 ① 거래입력'!$J$15:$J$2014,'통합 ① 거래입력'!$O$15:$O$2014,$G$1*100+6,'통합 ① 거래입력'!$D$15:$D$2014,$B17) -> 0 | I17: =SUMIFS('통합 ① 거래입력'!$J$15:$J$2014,'통합 ① 거래입력'!$O$15:$O$2014,$G$1*100+7,'통합 ① 거래입력'!$D$15:$D$2014,$B17) -> 0 | J17: =SUMIFS('통합 ① 거래입력'!$J$15:$J$2014,'통합 ① 거래입력'!$O$15:$O$2014,$G$1*100+8,'통합 ① 거래입력'!$D$15:$D$2014,$B17) -> 0 | K17: =SUMIFS('통합 ① 거래입력'!$J$15:$J$2014,'통합 ① 거래입력'!$O$15:$O$2014,$G$1*100+9,'통합 ① 거래입력'!$D$15:$D$2014,$B17) -> 2610000 | L17: =SUMIFS('통합 ① 거래입력'!$J$15:$J$2014,'통합 ① 거래입력'!$O$15:$O$2014,$G$1*100+10,'통합 ① 거래입력'!$D$15:$D$2014,$B17) -> 0 | M17: =SUMIFS('통합 ① 거래입력'!$J$15:$J$2014,'통합 ① 거래입력'!$O$15:$O$2014,$G$1*100+11,'통합 ① 거래입력'!$D$15:$D$2014,$B17) -> 0 | N17: =SUMIFS('통합 ① 거래입력'!$J$15:$J$2014,'통합 ① 거래입력'!$O$15:$O$2014,$G$1*100+12,'통합 ① 거래입력'!$D$15:$D$2014,$B17) -> 0 | O17: =SUM($C17:$N17) -> 2610000 | P17: =IFERROR(AVERAGEIF($C17:$N17,"<>0"),0) -> 2610000
B18: 4대보험 사업주부담 | C18: =SUMIFS('통합 ① 거래입력'!$J$15:$J$2014,'통합 ① 거래입력'!$O$15:$O$2014,$G$1*100+1,'통합 ① 거래입력'!$D$15:$D$2014,$B18) -> 0 | D18: =SUMIFS('통합 ① 거래입력'!$J$15:$J$2014,'통합 ① 거래입력'!$O$15:$O$2014,$G$1*100+2,'통합 ① 거래입력'!$D$15:$D$2014,$B18) -> 0 | E18: =SUMIFS('통합 ① 거래입력'!$J$15:$J$2014,'통합 ① 거래입력'!$O$15:$O$2014,$G$1*100+3,'통합 ① 거래입력'!$D$15:$D$2014,$B18) -> 0 | F18: =SUMIFS('통합 ① 거래입력'!$J$15:$J$2014,'통합 ① 거래입력'!$O$15:$O$2014,$G$1*100+4,'통합 ① 거래입력'!$D$15:$D$2014,$B18) -> 0 | G18: =SUMIFS('통합 ① 거래입력'!$J$15:$J$2014,'통합 ① 거래입력'!$O$15:$O$2014,$G$1*100+5,'통합 ① 거래입력'!$D$15:$D$2014,$B18) -> 0 | H18: =SUMIFS('통합 ① 거래입력'!$J$15:$J$2014,'통합 ① 거래입력'!$O$15:$O$2014,$G$1*100+6,'통합 ① 거래입력'!$D$15:$D$2014,$B18) -> 0 | I18: =SUMIFS('통합 ① 거래입력'!$J$15:$J$2014,'통합 ① 거래입력'!$O$15:$O$2014,$G$1*100+7,'통합 ① 거래입력'!$D$15:$D$2014,$B18) -> 0 | J18: =SUMIFS('통합 ① 거래입력'!$J$15:$J$2014,'통합 ① 거래입력'!$O$15:$O$2014,$G$1*100+8,'통합 ① 거래입력'!$D$15:$D$2014,$B18) -> 0 | K18: =SUMIFS('통합 ① 거래입력'!$J$15:$J$2014,'통합 ① 거래입력'!$O$15:$O$2014,$G$1*100+9,'통합 ① 거래입력'!$D$15:$D$2014,$B18) -> 412000 | L18: =SUMIFS('통합 ① 거래입력'!$J$15:$J$2014,'통합 ① 거래입력'!$O$15:$O$2014,$G$1*100+10,'통합 ① 거래입력'!$D$15:$D$2014,$B18) -> 0 | M18: =SUMIFS('통합 ① 거래입력'!$J$15:$J$2014,'통합 ① 거래입력'!$O$15:$O$2014,$G$1*100+11,'통합 ① 거래입력'!$D$15:$D$2014,$B18) -> 0 | N18: =SUMIFS('통합 ① 거래입력'!$J$15:$J$2014,'통합 ① 거래입력'!$O$15:$O$2014,$G$1*100+12,'통합 ① 거래입력'!$D$15:$D$2014,$B18) -> 0 | O18: =SUM($C18:$N18) -> 412000 | P18: =IFERROR(AVERAGEIF($C18:$N18,"<>0"),0) -> 412000
B19: 퇴직급여 | C19: =SUMIFS('통합 ① 거래입력'!$J$15:$J$2014,'통합 ① 거래입력'!$O$15:$O$2014,$G$1*100+1,'통합 ① 거래입력'!$D$15:$D$2014,$B19) -> 0 | D19: =SUMIFS('통합 ① 거래입력'!$J$15:$J$2014,'통합 ① 거래입력'!$O$15:$O$2014,$G$1*100+2,'통합 ① 거래입력'!$D$15:$D$2014,$B19) -> 0 | E19: =SUMIFS('통합 ① 거래입력'!$J$15:$J$2014,'통합 ① 거래입력'!$O$15:$O$2014,$G$1*100+3,'통합 ① 거래입력'!$D$15:$D$2014,$B19) -> 0 | F19: =SUMIFS('통합 ① 거래입력'!$J$15:$J$2014,'통합 ① 거래입력'!$O$15:$O$2014,$G$1*100+4,'통합 ① 거래입력'!$D$15:$D$2014,$B19) -> 0 | G19: =SUMIFS('통합 ① 거래입력'!$J$15:$J$2014,'통합 ① 거래입력'!$O$15:$O$2014,$G$1*100+5,'통합 ① 거래입력'!$D$15:$D$2014,$B19) -> 0 | H19: =SUMIFS('통합 ① 거래입력'!$J$15:$J$2014,'통합 ① 거래입력'!$O$15:$O$2014,$G$1*100+6,'통합 ① 거래입력'!$D$15:$D$2014,$B19) -> 0 | I19: =SUMIFS('통합 ① 거래입력'!$J$15:$J$2014,'통합 ① 거래입력'!$O$15:$O$2014,$G$1*100+7,'통합 ① 거래입력'!$D$15:$D$2014,$B19) -> 0 | J19: =SUMIFS('통합 ① 거래입력'!$J$15:$J$2014,'통합 ① 거래입력'!$O$15:$O$2014,$G$1*100+8,'통합 ① 거래입력'!$D$15:$D$2014,$B19) -> 0 | K19: =SUMIFS('통합 ① 거래입력'!$J$15:$J$2014,'통합 ① 거래입력'!$O$15:$O$2014,$G$1*100+9,'통합 ① 거래입력'!$D$15:$D$2014,$B19) -> 0 | L19: =SUMIFS('통합 ① 거래입력'!$J$15:$J$2014,'통합 ① 거래입력'!$O$15:$O$2014,$G$1*100+10,'통합 ① 거래입력'!$D$15:$D$2014,$B19) -> 0 | M19: =SUMIFS('통합 ① 거래입력'!$J$15:$J$2014,'통합 ① 거래입력'!$O$15:$O$2014,$G$1*100+11,'통합 ① 거래입력'!$D$15:$D$2014,$B19) -> 0 | N19: =SUMIFS('통합 ① 거래입력'!$J$15:$J$2014,'통합 ① 거래입력'!$O$15:$O$2014,$G$1*100+12,'통합 ① 거래입력'!$D$15:$D$2014,$B19) -> 0 | O19: =SUM($C19:$N19) -> 0 | P19: =IFERROR(AVERAGEIF($C19:$N19,"<>0"),0) -> 0
B20: 임차료 | C20: =SUMIFS('통합 ① 거래입력'!$J$15:$J$2014,'통합 ① 거래입력'!$O$15:$O$2014,$G$1*100+1,'통합 ① 거래입력'!$D$15:$D$2014,$B20) -> 0 | D20: =SUMIFS('통합 ① 거래입력'!$J$15:$J$2014,'통합 ① 거래입력'!$O$15:$O$2014,$G$1*100+2,'통합 ① 거래입력'!$D$15:$D$2014,$B20) -> 0 | E20: =SUMIFS('통합 ① 거래입력'!$J$15:$J$2014,'통합 ① 거래입력'!$O$15:$O$2014,$G$1*100+3,'통합 ① 거래입력'!$D$15:$D$2014,$B20) -> 0 | F20: =SUMIFS('통합 ① 거래입력'!$J$15:$J$2014,'통합 ① 거래입력'!$O$15:$O$2014,$G$1*100+4,'통합 ① 거래입력'!$D$15:$D$2014,$B20) -> 0 | G20: =SUMIFS('통합 ① 거래입력'!$J$15:$J$2014,'통합 ① 거래입력'!$O$15:$O$2014,$G$1*100+5,'통합 ① 거래입력'!$D$15:$D$2014,$B20) -> 0 | H20: =SUMIFS('통합 ① 거래입력'!$J$15:$J$2014,'통합 ① 거래입력'!$O$15:$O$2014,$G$1*100+6,'통합 ① 거래입력'!$D$15:$D$2014,$B20) -> 0 | I20: =SUMIFS('통합 ① 거래입력'!$J$15:$J$2014,'통합 ① 거래입력'!$O$15:$O$2014,$G$1*100+7,'통합 ① 거래입력'!$D$15:$D$2014,$B20) -> 0 | J20: =SUMIFS('통합 ① 거래입력'!$J$15:$J$2014,'통합 ① 거래입력'!$O$15:$O$2014,$G$1*100+8,'통합 ① 거래입력'!$D$15:$D$2014,$B20) -> 0 | K20: =SUMIFS('통합 ① 거래입력'!$J$15:$J$2014,'통합 ① 거래입력'!$O$15:$O$2014,$G$1*100+9,'통합 ① 거래입력'!$D$15:$D$2014,$B20) -> 850000 | L20: =SUMIFS('통합 ① 거래입력'!$J$15:$J$2014,'통합 ① 거래입력'!$O$15:$O$2014,$G$1*100+10,'통합 ① 거래입력'!$D$15:$D$2014,$B20) -> 0 | M20: =SUMIFS('통합 ① 거래입력'!$J$15:$J$2014,'통합 ① 거래입력'!$O$15:$O$2014,$G$1*100+11,'통합 ① 거래입력'!$D$15:$D$2014,$B20) -> 0 | N20: =SUMIFS('통합 ① 거래입력'!$J$15:$J$2014,'통합 ① 거래입력'!$O$15:$O$2014,$G$1*100+12,'통합 ① 거래입력'!$D$15:$D$2014,$B20) -> 0 | O20: =SUM($C20:$N20) -> 850000 | P20: =IFERROR(AVERAGEIF($C20:$N20,"<>0"),0) -> 850000
B21: 관리비 | C21: =SUMIFS('통합 ① 거래입력'!$J$15:$J$2014,'통합 ① 거래입력'!$O$15:$O$2014,$G$1*100+1,'통합 ① 거래입력'!$D$15:$D$2014,$B21) -> 0 | D21: =SUMIFS('통합 ① 거래입력'!$J$15:$J$2014,'통합 ① 거래입력'!$O$15:$O$2014,$G$1*100+2,'통합 ① 거래입력'!$D$15:$D$2014,$B21) -> 0 | E21: =SUMIFS('통합 ① 거래입력'!$J$15:$J$2014,'통합 ① 거래입력'!$O$15:$O$2014,$G$1*100+3,'통합 ① 거래입력'!$D$15:$D$2014,$B21) -> 0 | F21: =SUMIFS('통합 ① 거래입력'!$J$15:$J$2014,'통합 ① 거래입력'!$O$15:$O$2014,$G$1*100+4,'통합 ① 거래입력'!$D$15:$D$2014,$B21) -> 0 | G21: =SUMIFS('통합 ① 거래입력'!$J$15:$J$2014,'통합 ① 거래입력'!$O$15:$O$2014,$G$1*100+5,'통합 ① 거래입력'!$D$15:$D$2014,$B21) -> 0 | H21: =SUMIFS('통합 ① 거래입력'!$J$15:$J$2014,'통합 ① 거래입력'!$O$15:$O$2014,$G$1*100+6,'통합 ① 거래입력'!$D$15:$D$2014,$B21) -> 0 | I21: =SUMIFS('통합 ① 거래입력'!$J$15:$J$2014,'통합 ① 거래입력'!$O$15:$O$2014,$G$1*100+7,'통합 ① 거래입력'!$D$15:$D$2014,$B21) -> 0 | J21: =SUMIFS('통합 ① 거래입력'!$J$15:$J$2014,'통합 ① 거래입력'!$O$15:$O$2014,$G$1*100+8,'통합 ① 거래입력'!$D$15:$D$2014,$B21) -> 0 | K21: =SUMIFS('통합 ① 거래입력'!$J$15:$J$2014,'통합 ① 거래입력'!$O$15:$O$2014,$G$1*100+9,'통합 ① 거래입력'!$D$15:$D$2014,$B21) -> 0 | L21: =SUMIFS('통합 ① 거래입력'!$J$15:$J$2014,'통합 ① 거래입력'!$O$15:$O$2014,$G$1*100+10,'통합 ① 거래입력'!$D$15:$D$2014,$B21) -> 0 | M21: =SUMIFS('통합 ① 거래입력'!$J$15:$J$2014,'통합 ① 거래입력'!$O$15:$O$2014,$G$1*100+11,'통합 ① 거래입력'!$D$15:$D$2014,$B21) -> 0 | N21: =SUMIFS('통합 ① 거래입력'!$J$15:$J$2014,'통합 ① 거래입력'!$O$15:$O$2014,$G$1*100+12,'통합 ① 거래입력'!$D$15:$D$2014,$B21) -> 0 | O21: =SUM($C21:$N21) -> 0 | P21: =IFERROR(AVERAGEIF($C21:$N21,"<>0"),0) -> 0
B22: 통신비 | C22: =SUMIFS('통합 ① 거래입력'!$J$15:$J$2014,'통합 ① 거래입력'!$O$15:$O$2014,$G$1*100+1,'통합 ① 거래입력'!$D$15:$D$2014,$B22) -> 0 | D22: =SUMIFS('통합 ① 거래입력'!$J$15:$J$2014,'통합 ① 거래입력'!$O$15:$O$2014,$G$1*100+2,'통합 ① 거래입력'!$D$15:$D$2014,$B22) -> 0 | E22: =SUMIFS('통합 ① 거래입력'!$J$15:$J$2014,'통합 ① 거래입력'!$O$15:$O$2014,$G$1*100+3,'통합 ① 거래입력'!$D$15:$D$2014,$B22) -> 0 | F22: =SUMIFS('통합 ① 거래입력'!$J$15:$J$2014,'통합 ① 거래입력'!$O$15:$O$2014,$G$1*100+4,'통합 ① 거래입력'!$D$15:$D$2014,$B22) -> 0 | G22: =SUMIFS('통합 ① 거래입력'!$J$15:$J$2014,'통합 ① 거래입력'!$O$15:$O$2014,$G$1*100+5,'통합 ① 거래입력'!$D$15:$D$2014,$B22) -> 0 | H22: =SUMIFS('통합 ① 거래입력'!$J$15:$J$2014,'통합 ① 거래입력'!$O$15:$O$2014,$G$1*100+6,'통합 ① 거래입력'!$D$15:$D$2014,$B22) -> 0 | I22: =SUMIFS('통합 ① 거래입력'!$J$15:$J$2014,'통합 ① 거래입력'!$O$15:$O$2014,$G$1*100+7,'통합 ① 거래입력'!$D$15:$D$2014,$B22) -> 0 | J22: =SUMIFS('통합 ① 거래입력'!$J$15:$J$2014,'통합 ① 거래입력'!$O$15:$O$2014,$G$1*100+8,'통합 ① 거래입력'!$D$15:$D$2014,$B22) -> 0 | K22: =SUMIFS('통합 ① 거래입력'!$J$15:$J$2014,'통합 ① 거래입력'!$O$15:$O$2014,$G$1*100+9,'통합 ① 거래입력'!$D$15:$D$2014,$B22) -> 88000 | L22: =SUMIFS('통합 ① 거래입력'!$J$15:$J$2014,'통합 ① 거래입력'!$O$15:$O$2014,$G$1*100+10,'통합 ① 거래입력'!$D$15:$D$2014,$B22) -> 0 | M22: =SUMIFS('통합 ① 거래입력'!$J$15:$J$2014,'통합 ① 거래입력'!$O$15:$O$2014,$G$1*100+11,'통합 ① 거래입력'!$D$15:$D$2014,$B22) -> 0 | N22: =SUMIFS('통합 ① 거래입력'!$J$15:$J$2014,'통합 ① 거래입력'!$O$15:$O$2014,$G$1*100+12,'통합 ① 거래입력'!$D$15:$D$2014,$B22) -> 0 | O22: =SUM($C22:$N22) -> 88000 | P22: =IFERROR(AVERAGEIF($C22:$N22,"<>0"),0) -> 88000
B23: 보험료 | C23: =SUMIFS('통합 ① 거래입력'!$J$15:$J$2014,'통합 ① 거래입력'!$O$15:$O$2014,$G$1*100+1,'통합 ① 거래입력'!$D$15:$D$2014,$B23) -> 0 | D23: =SUMIFS('통합 ① 거래입력'!$J$15:$J$2014,'통합 ① 거래입력'!$O$15:$O$2014,$G$1*100+2,'통합 ① 거래입력'!$D$15:$D$2014,$B23) -> 0 | E23: =SUMIFS('통합 ① 거래입력'!$J$15:$J$2014,'통합 ① 거래입력'!$O$15:$O$2014,$G$1*100+3,'통합 ① 거래입력'!$D$15:$D$2014,$B23) -> 0 | F23: =SUMIFS('통합 ① 거래입력'!$J$15:$J$2014,'통합 ① 거래입력'!$O$15:$O$2014,$G$1*100+4,'통합 ① 거래입력'!$D$15:$D$2014,$B23) -> 0 | G23: =SUMIFS('통합 ① 거래입력'!$J$15:$J$2014,'통합 ① 거래입력'!$O$15:$O$2014,$G$1*100+5,'통합 ① 거래입력'!$D$15:$D$2014,$B23) -> 0 | H23: =SUMIFS('통합 ① 거래입력'!$J$15:$J$2014,'통합 ① 거래입력'!$O$15:$O$2014,$G$1*100+6,'통합 ① 거래입력'!$D$15:$D$2014,$B23) -> 0 | I23: =SUMIFS('통합 ① 거래입력'!$J$15:$J$2014,'통합 ① 거래입력'!$O$15:$O$2014,$G$1*100+7,'통합 ① 거래입력'!$D$15:$D$2014,$B23) -> 0 | J23: =SUMIFS('통합 ① 거래입력'!$J$15:$J$2014,'통합 ① 거래입력'!$O$15:$O$2014,$G$1*100+8,'통합 ① 거래입력'!$D$15:$D$2014,$B23) -> 0 | K23: =SUMIFS('통합 ① 거래입력'!$J$15:$J$2014,'통합 ① 거래입력'!$O$15:$O$2014,$G$1*100+9,'통합 ① 거래입력'!$D$15:$D$2014,$B23) -> 0 | L23: =SUMIFS('통합 ① 거래입력'!$J$15:$J$2014,'통합 ① 거래입력'!$O$15:$O$2014,$G$1*100+10,'통합 ① 거래입력'!$D$15:$D$2014,$B23) -> 0 | M23: =SUMIFS('통합 ① 거래입력'!$J$15:$J$2014,'통합 ① 거래입력'!$O$15:$O$2014,$G$1*100+11,'통합 ① 거래입력'!$D$15:$D$2014,$B23) -> 0 | N23: =SUMIFS('통합 ① 거래입력'!$J$15:$J$2014,'통합 ① 거래입력'!$O$15:$O$2014,$G$1*100+12,'통합 ① 거래입력'!$D$15:$D$2014,$B23) -> 0 | O23: =SUM($C23:$N23) -> 0 | P23: =IFERROR(AVERAGEIF($C23:$N23,"<>0"),0) -> 0
B24: 세무기장료 | C24: =SUMIFS('통합 ① 거래입력'!$J$15:$J$2014,'통합 ① 거래입력'!$O$15:$O$2014,$G$1*100+1,'통합 ① 거래입력'!$D$15:$D$2014,$B24) -> 0 | D24: =SUMIFS('통합 ① 거래입력'!$J$15:$J$2014,'통합 ① 거래입력'!$O$15:$O$2014,$G$1*100+2,'통합 ① 거래입력'!$D$15:$D$2014,$B24) -> 0 | E24: =SUMIFS('통합 ① 거래입력'!$J$15:$J$2014,'통합 ① 거래입력'!$O$15:$O$2014,$G$1*100+3,'통합 ① 거래입력'!$D$15:$D$2014,$B24) -> 0 | F24: =SUMIFS('통합 ① 거래입력'!$J$15:$J$2014,'통합 ① 거래입력'!$O$15:$O$2014,$G$1*100+4,'통합 ① 거래입력'!$D$15:$D$2014,$B24) -> 0 | G24: =SUMIFS('통합 ① 거래입력'!$J$15:$J$2014,'통합 ① 거래입력'!$O$15:$O$2014,$G$1*100+5,'통합 ① 거래입력'!$D$15:$D$2014,$B24) -> 0 | H24: =SUMIFS('통합 ① 거래입력'!$J$15:$J$2014,'통합 ① 거래입력'!$O$15:$O$2014,$G$1*100+6,'통합 ① 거래입력'!$D$15:$D$2014,$B24) -> 0 | I24: =SUMIFS('통합 ① 거래입력'!$J$15:$J$2014,'통합 ① 거래입력'!$O$15:$O$2014,$G$1*100+7,'통합 ① 거래입력'!$D$15:$D$2014,$B24) -> 0 | J24: =SUMIFS('통합 ① 거래입력'!$J$15:$J$2014,'통합 ① 거래입력'!$O$15:$O$2014,$G$1*100+8,'통합 ① 거래입력'!$D$15:$D$2014,$B24) -> 0 | K24: =SUMIFS('통합 ① 거래입력'!$J$15:$J$2014,'통합 ① 거래입력'!$O$15:$O$2014,$G$1*100+9,'통합 ① 거래입력'!$D$15:$D$2014,$B24) -> 0 | L24: =SUMIFS('통합 ① 거래입력'!$J$15:$J$2014,'통합 ① 거래입력'!$O$15:$O$2014,$G$1*100+10,'통합 ① 거래입력'!$D$15:$D$2014,$B24) -> 0 | M24: =SUMIFS('통합 ① 거래입력'!$J$15:$J$2014,'통합 ① 거래입력'!$O$15:$O$2014,$G$1*100+11,'통합 ① 거래입력'!$D$15:$D$2014,$B24) -> 0 | N24: =SUMIFS('통합 ① 거래입력'!$J$15:$J$2014,'통합 ① 거래입력'!$O$15:$O$2014,$G$1*100+12,'통합 ① 거래입력'!$D$15:$D$2014,$B24) -> 0 | O24: =SUM($C24:$N24) -> 0 | P24: =IFERROR(AVERAGEIF($C24:$N24,"<>0"),0) -> 0
B25: 소프트웨어·구독료 | C25: =SUMIFS('통합 ① 거래입력'!$J$15:$J$2014,'통합 ① 거래입력'!$O$15:$O$2014,$G$1*100+1,'통합 ① 거래입력'!$D$15:$D$2014,$B25) -> 0 | D25: =SUMIFS('통합 ① 거래입력'!$J$15:$J$2014,'통합 ① 거래입력'!$O$15:$O$2014,$G$1*100+2,'통합 ① 거래입력'!$D$15:$D$2014,$B25) -> 0 | E25: =SUMIFS('통합 ① 거래입력'!$J$15:$J$2014,'통합 ① 거래입력'!$O$15:$O$2014,$G$1*100+3,'통합 ① 거래입력'!$D$15:$D$2014,$B25) -> 0 | F25: =SUMIFS('통합 ① 거래입력'!$J$15:$J$2014,'통합 ① 거래입력'!$O$15:$O$2014,$G$1*100+4,'통합 ① 거래입력'!$D$15:$D$2014,$B25) -> 0 | G25: =SUMIFS('통합 ① 거래입력'!$J$15:$J$2014,'통합 ① 거래입력'!$O$15:$O$2014,$G$1*100+5,'통합 ① 거래입력'!$D$15:$D$2014,$B25) -> 0 | H25: =SUMIFS('통합 ① 거래입력'!$J$15:$J$2014,'통합 ① 거래입력'!$O$15:$O$2014,$G$1*100+6,'통합 ① 거래입력'!$D$15:$D$2014,$B25) -> 0 | I25: =SUMIFS('통합 ① 거래입력'!$J$15:$J$2014,'통합 ① 거래입력'!$O$15:$O$2014,$G$1*100+7,'통합 ① 거래입력'!$D$15:$D$2014,$B25) -> 0 | J25: =SUMIFS('통합 ① 거래입력'!$J$15:$J$2014,'통합 ① 거래입력'!$O$15:$O$2014,$G$1*100+8,'통합 ① 거래입력'!$D$15:$D$2014,$B25) -> 0 | K25: =SUMIFS('통합 ① 거래입력'!$J$15:$J$2014,'통합 ① 거래입력'!$O$15:$O$2014,$G$1*100+9,'통합 ① 거래입력'!$D$15:$D$2014,$B25) -> 0 | L25: =SUMIFS('통합 ① 거래입력'!$J$15:$J$2014,'통합 ① 거래입력'!$O$15:$O$2014,$G$1*100+10,'통합 ① 거래입력'!$D$15:$D$2014,$B25) -> 0 | M25: =SUMIFS('통합 ① 거래입력'!$J$15:$J$2014,'통합 ① 거래입력'!$O$15:$O$2014,$G$1*100+11,'통합 ① 거래입력'!$D$15:$D$2014,$B25) -> 0 | N25: =SUMIFS('통합 ① 거래입력'!$J$15:$J$2014,'통합 ① 거래입력'!$O$15:$O$2014,$G$1*100+12,'통합 ① 거래입력'!$D$15:$D$2014,$B25) -> 0 | O25: =SUM($C25:$N25) -> 0 | P25: =IFERROR(AVERAGEIF($C25:$N25,"<>0"),0) -> 0
B26: 차량유지비 | C26: =SUMIFS('통합 ① 거래입력'!$J$15:$J$2014,'통합 ① 거래입력'!$O$15:$O$2014,$G$1*100+1,'통합 ① 거래입력'!$D$15:$D$2014,$B26) -> 0 | D26: =SUMIFS('통합 ① 거래입력'!$J$15:$J$2014,'통합 ① 거래입력'!$O$15:$O$2014,$G$1*100+2,'통합 ① 거래입력'!$D$15:$D$2014,$B26) -> 0 | E26: =SUMIFS('통합 ① 거래입력'!$J$15:$J$2014,'통합 ① 거래입력'!$O$15:$O$2014,$G$1*100+3,'통합 ① 거래입력'!$D$15:$D$2014,$B26) -> 0 | F26: =SUMIFS('통합 ① 거래입력'!$J$15:$J$2014,'통합 ① 거래입력'!$O$15:$O$2014,$G$1*100+4,'통합 ① 거래입력'!$D$15:$D$2014,$B26) -> 0 | G26: =SUMIFS('통합 ① 거래입력'!$J$15:$J$2014,'통합 ① 거래입력'!$O$15:$O$2014,$G$1*100+5,'통합 ① 거래입력'!$D$15:$D$2014,$B26) -> 0 | H26: =SUMIFS('통합 ① 거래입력'!$J$15:$J$2014,'통합 ① 거래입력'!$O$15:$O$2014,$G$1*100+6,'통합 ① 거래입력'!$D$15:$D$2014,$B26) -> 0 | I26: =SUMIFS('통합 ① 거래입력'!$J$15:$J$2014,'통합 ① 거래입력'!$O$15:$O$2014,$G$1*100+7,'통합 ① 거래입력'!$D$15:$D$2014,$B26) -> 0 | J26: =SUMIFS('통합 ① 거래입력'!$J$15:$J$2014,'통합 ① 거래입력'!$O$15:$O$2014,$G$1*100+8,'통합 ① 거래입력'!$D$15:$D$2014,$B26) -> 0 | K26: =SUMIFS('통합 ① 거래입력'!$J$15:$J$2014,'통합 ① 거래입력'!$O$15:$O$2014,$G$1*100+9,'통합 ① 거래입력'!$D$15:$D$2014,$B26) -> 0 | L26: =SUMIFS('통합 ① 거래입력'!$J$15:$J$2014,'통합 ① 거래입력'!$O$15:$O$2014,$G$1*100+10,'통합 ① 거래입력'!$D$15:$D$2014,$B26) -> 0 | M26: =SUMIFS('통합 ① 거래입력'!$J$15:$J$2014,'통합 ① 거래입력'!$O$15:$O$2014,$G$1*100+11,'통합 ① 거래입력'!$D$15:$D$2014,$B26) -> 0 | N26: =SUMIFS('통합 ① 거래입력'!$J$15:$J$2014,'통합 ① 거래입력'!$O$15:$O$2014,$G$1*100+12,'통합 ① 거래입력'!$D$15:$D$2014,$B26) -> 0 | O26: =SUM($C26:$N26) -> 0 | P26: =IFERROR(AVERAGEIF($C26:$N26,"<>0"),0) -> 0
B27: 고정지출 소계 | C27: =SUM(C16:C26) -> 0 | D27: =SUM(D16:D26) -> 0 | E27: =SUM(E16:E26) -> 0 | F27: =SUM(F16:F26) -> 0 | G27: =SUM(G16:G26) -> 0 | H27: =SUM(H16:H26) -> 0 | I27: =SUM(I16:I26) -> 0 | J27: =SUM(J16:J26) -> 0 | ... P27: =SUM(P16:P26) -> 3960000
